Workbook

Sheet 체중별_손익표
A1: 비육돈 출하 손익 시뮬레이션 (평균체중 105~125kg)
A2: ※ 돈가·지육율·지급율·생산원가·편도거리·두수 등은 [기준값] 시트의 파란 글씨 셀에서 조정하면 이 표 전체가 자동 재계산됩니다.
B4: ="시나리오 A · 두수 "&기준값!$B$18&"두 (30~59두 구간 예시)" -> 시나리오 A · 두수 30두 (30~59두 구간 예시) | J4: ="시나리오 B · 두수 "&기준값!$B$19&"두 (60두 이상 구간 예시)" -> 시나리오 B · 두수 65두 (60두 이상 구간 예시)
A5: 평균체중 | B5: 두당 출하대금 | C5: 지급조건 | D5: 지급률 | E5: 두당 운반비 | F5: 총 운반비 | G5: 두당 총원가 | H5: 두당 순수익 | I5: 전체 손익 | J5: 지급조건 | K5: 지급률 | L5: 두당 운반비 | M5: 총 운반비 | N5: 두당 총원가 | O5: 두당 순수익 | P5: 전체 손익
A6: 105 | B6: =A6*기준값!$B$7 -> 407281.88 | C6: =IF(기준값!$B$18<기준값!$B$11,"두수기준미달",IF(기준값!$B$18>=기준값!$B$12,IF(A6>=기준값!$B$13,"인센티브","기본(두수만 충족)"),IF(A6>=기준값!$B$13,"기본","패널티"))) -> 패널티 | D6: =IF(기준값!$B$18<기준값!$B$11,"-",IF(기준값!$B$18>=기준값!$B$12,IF(A6>=기준값!$B$13,기준값!$B$14,기준값!$B$16),IF(A6>=기준값!$B$13,기준값!$B$16,기준값!$B$15))) -> 1 | E6: =IFERROR(IF(ISNUMBER(D6),기준값!$B$10*D6/기준값!$B$18,"-"),"-") -> 13333.333 | F6: =IF(ISNUMBER(E6),E6*기준값!$B$18,"-") -> 400000 | G6: =IF(ISNUMBER(E6),기준값!$B$8+E6,"-") -> 443333.33 | H6: =IF(ISNUMBER(G6),B6-G6,"-") -> -36051.458 | I6: =IF(ISNUMBER(H6),H6*기준값!$B$18,"-") -> -1081543.7 | J6: =IF(기준값!$B$19<기준값!$B$11,"두수기준미달",IF(기준값!$B$19>=기준값!$B$12,IF(A6>=기준값!$B$13,"인센티브","기본(두수만 충족)"),IF(A6>=기준값!$B$13,"기본","패널티"))) -> 기본(두수만 충족) | K6: =IF(기준값!$B$19<기준값!$B$11,"-",IF(기준값!$B$19>=기준값!$B$12,IF(A6>=기준값!$B$13,기준값!$B$14,기준값!$B$16),IF(A6>=기준값!$B$13,기준값!$B$16,기준값!$B$15))) -> 1 | L6: =IFERROR(IF(ISNUMBER(K6),기준값!$B$10*K6/기준값!$B$19,"-"),"-") -> 6153.8462 | M6: =IF(ISNUMBER(L6),L6*기준값!$B$19,"-") -> 400000 | N6: =IF(ISNUMBER(L6),기준값!$B$8+L6,"-") -> 436153.85 | O6: =IF(ISNUMBER(N6),B6-N6,"-") -> -28871.971 | P6: =IF(ISNUMBER(O6),O6*기준값!$B$19,"-") -> -1876678.1
A7: 106 | B7: =A7*기준값!$B$7 -> 411160.75 | C7: =IF(기준값!$B$18<기준값!$B$11,"두수기준미달",IF(기준값!$B$18>=기준값!$B$12,IF(A7>=기준값!$B$13,"인센티브","기본(두수만 충족)"),IF(A7>=기준값!$B$13,"기본","패널티"))) -> 패널티 | D7: =IF(기준값!$B$18<기준값!$B$11,"-",IF(기준값!$B$18>=기준값!$B$12,IF(A7>=기준값!$B$13,기준값!$B$14,기준값!$B$16),IF(A7>=기준값!$B$13,기준값!$B$16,기준값!$B$15))) -> 1 | E7: =IFERROR(IF(ISNUMBER(D7),기준값!$B$10*D7/기준값!$B$18,"-"),"-") -> 13333.333 | F7: =IF(ISNUMBER(E7),E7*기준값!$B$18,"-") -> 400000 | G7: =IF(ISNUMBER(E7),기준값!$B$8+E7,"-") -> 443333.33 | H7: =IF(ISNUMBER(G7),B7-G7,"-") -> -32172.583 | I7: =IF(ISNUMBER(H7),H7*기준값!$B$18,"-") -> -965177.5 | J7: =IF(기준값!$B$19<기준값!$B$11,"두수기준미달",IF(기준값!$B$19>=기준값!$B$12,IF(A7>=기준값!$B$13,"인센티브","기본(두수만 충족)"),IF(A7>=기준값!$B$13,"기본","패널티"))) -> 기본(두수만 충족) | K7: =IF(기준값!$B$19<기준값!$B$11,"-",IF(기준값!$B$19>=기준값!$B$12,IF(A7>=기준값!$B$13,기준값!$B$14,기준값!$B$16),IF(A7>=기준값!$B$13,기준값!$B$16,기준값!$B$15))) -> 1 | L7: =IFERROR(IF(ISNUMBER(K7),기준값!$B$10*K7/기준값!$B$19,"-"),"-") -> 6153.8462 | M7: =IF(ISNUMBER(L7),L7*기준값!$B$19,"-") -> 400000 | N7: =IF(ISNUMBER(L7),기준값!$B$8+L7,"-") -> 436153.85 | O7: =IF(ISNUMBER(N7),B7-N7,"-") -> -24993.096 | P7: =IF(ISNUMBER(O7),O7*기준값!$B$19,"-") -> -1624551.2
A8: 107 | B8: =A8*기준값!$B$7 -> 415039.62 | C8: =IF(기준값!$B$18<기준값!$B$11,"두수기준미달",IF(기준값!$B$18>=기준값!$B$12,IF(A8>=기준값!$B$13,"인센티브","기본(두수만 충족)"),IF(A8>=기준값!$B$13,"기본","패널티"))) -> 패널티 | D8: =IF(기준값!$B$18<기준값!$B$11,"-",IF(기준값!$B$18>=기준값!$B$12,IF(A8>=기준값!$B$13,기준값!$B$14,기준값!$B$16),IF(A8>=기준값!$B$13,기준값!$B$16,기준값!$B$15))) -> 1 | E8: =IFERROR(IF(ISNUMBER(D8),기준값!$B$10*D8/기준값!$B$18,"-"),"-") -> 13333.333 | F8: =IF(ISNUMBER(E8),E8*기준값!$B$18,"-") -> 400000 | G8: =IF(ISNUMBER(E8),기준값!$B$8+E8,"-") -> 443333.33 | H8: =IF(ISNUMBER(G8),B8-G8,"-") -> -28293.708 | I8: =IF(ISNUMBER(H8),H8*기준값!$B$18,"-") -> -848811.25 | J8: =IF(기준값!$B$19<기준값!$B$11,"두수기준미달",IF(기준값!$B$19>=기준값!$B$12,IF(A8>=기준값!$B$13,"인센티브","기본(두수만 충족)"),IF(A8>=기준값!$B$13,"기본","패널티"))) -> 기본(두수만 충족) | K8: =IF(기준값!$B$19<기준값!$B$11,"-",IF(기준값!$B$19>=기준값!$B$12,IF(A8>=기준값!$B$13,기준값!$B$14,기준값!$B$16),IF(A8>=기준값!$B$13,기준값!$B$16,기준값!$B$15))) -> 1 | L8: =IFERROR(IF(ISNUMBER(K8),기준값!$B$10*K8/기준값!$B$19,"-"),"-") -> 6153.8462 | M8: =IF(ISNUMBER(L8),L8*기준값!$B$19,"-") -> 400000 | N8: =IF(ISNUMBER(L8),기준값!$B$8+L8,"-") -> 436153.85 | O8: =IF(ISNUMBER(N8),B8-N8,"-") -> -21114.221 | P8: =IF(ISNUMBER(O8),O8*기준값!$B$19,"-") -> -1372424.4
A9: 108 | B9: =A9*기준값!$B$7 -> 418918.5 | C9: =IF(기준값!$B$18<기준값!$B$11,"두수기준미달",IF(기준값!$B$18>=기준값!$B$12,IF(A9>=기준값!$B$13,"인센티브","기본(두수만 충족)"),IF(A9>=기준값!$B$13,"기본","패널티"))) -> 패널티 | D9: =IF(기준값!$B$18<기준값!$B$11,"-",IF(기준값!$B$18>=기준값!$B$12,IF(A9>=기준값!$B$13,기준값!$B$14,기준값!$B$16),IF(A9>=기준값!$B$13,기준값!$B$16,기준값!$B$15))) -> 1 | E9: =IFERROR(IF(ISNUMBER(D9),기준값!$B$10*D9/기준값!$B$18,"-"),"-") -> 13333.333 | F9: =IF(ISNUMBER(E9),E9*기준값!$B$18,"-") -> 400000 | G9: =IF(ISNUMBER(E9),기준값!$B$8+E9,"-") -> 443333.33 | H9: =IF(ISNUMBER(G9),B9-G9,"-") -> -24414.833 | I9: =IF(ISNUMBER(H9),H9*기준값!$B$18,"-") -> -732445 | J9: =IF(기준값!$B$19<기준값!$B$11,"두수기준미달",IF(기준값!$B$19>=기준값!$B$12,IF(A9>=기준값!$B$13,"인센티브","기본(두수만 충족)"),IF(A9>=기준값!$B$13,"기본","패널티"))) -> 기본(두수만 충족) | K9: =IF(기준값!$B$19<기준값!$B$11,"-",IF(기준값!$B$19>=기준값!$B$12,IF(A9>=기준값!$B$13,기준값!$B$14,기준값!$B$16),IF(A9>=기준값!$B$13,기준값!$B$16,기준값!$B$15))) -> 1 | L9: =IFERROR(IF(ISNUMBER(K9),기준값!$B$10*K9/기준값!$B$19,"-"),"-") -> 6153.8462 | M9: =IF(ISNUMBER(L9),L9*기준값!$B$19,"-") -> 400000 | N9: =IF(ISNUMBER(L9),기준값!$B$8+L9,"-") -> 436153.85 | O9: =IF(ISNUMBER(N9),B9-N9,"-") -> -17235.346 | P9: =IF(ISNUMBER(O9),O9*기준값!$B$19,"-") -> -1120297.5
A10: 109 | B10: =A10*기준값!$B$7 -> 422797.38 | C10: =IF(기준값!$B$18<기준값!$B$11,"두수기준미달",IF(기준값!$B$18>=기준값!$B$12,IF(A10>=기준값!$B$13,"인센티브","기본(두수만 충족)"),IF(A10>=기준값!$B$13,"기본","패널티"))) -> 패널티 | D10: =IF(기준값!$B$18<기준값!$B$11,"-",IF(기준값!$B$18>=기준값!$B$12,IF(A10>=기준값!$B$13,기준값!$B$14,기준값!$B$16),IF(A10>=기준값!$B$13,기준값!$B$16,기준값!$B$15))) -> 1 | E10: =IFERROR(IF(ISNUMBER(D10),기준값!$B$10*D10/기준값!$B$18,"-"),"-") -> 13333.333 | F10: =IF(ISNUMBER(E10),E10*기준값!$B$18,"-") -> 400000 | G10: =IF(ISNUMBER(E10),기준값!$B$8+E10,"-") -> 443333.33 | H10: =IF(ISNUMBER(G10),B10-G10,"-") -> -20535.958 | I10: =IF(ISNUMBER(H10),H10*기준값!$B$18,"-") -> -616078.75 | J10: =IF(기준값!$B$19<기준값!$B$11,"두수기준미달",IF(기준값!$B$19>=기준값!$B$12,IF(A10>=기준값!$B$13,"인센티브","기본(두수만 충족)"),IF(A10>=기준값!$B$13,"기본","패널티"))) -> 기본(두수만 충족) | K10: =IF(기준값!$B$19<기준값!$B$11,"-",IF(기준값!$B$19>=기준값!$B$12,IF(A10>=기준값!$B$13,기준값!$B$14,기준값!$B$16),IF(A10>=기준값!$B$13,기준값!$B$16,기준값!$B$15))) -> 1 | L10: =IFERROR(IF(ISNUMBER(K10),기준값!$B$10*K10/기준값!$B$19,"-"),"-") -> 6153.8462 | M10: =IF(ISNUMBER(L10),L10*기준값!$B$19,"-") -> 400000 | N10: =IF(ISNUMBER(L10),기준값!$B$8+L10,"-") -> 436153.85 | O10: =IF(ISNUMBER(N10),B10-N10,"-") -> -13356.471 | P10: =IF(ISNUMBER(O10),O10*기준값!$B$19,"-") -> -868170.62
A11: 110 | B11: =A11*기준값!$B$7 -> 426676.25 | C11: =IF(기준값!$B$18<기준값!$B$11,"두수기준미달",IF(기준값!$B$18>=기준값!$B$12,IF(A11>=기준값!$B$13,"인센티브","기본(두수만 충족)"),IF(A11>=기준값!$B$13,"기본","패널티"))) -> 패널티 | D11: =IF(기준값!$B$18<기준값!$B$11,"-",IF(기준값!$B$18>=기준값!$B$12,IF(A11>=기준값!$B$13,기준값!$B$14,기준값!$B$16),IF(A11>=기준값!$B$13,기준값!$B$16,기준값!$B$15))) -> 1 | E11: =IFERROR(IF(ISNUMBER(D11),기준값!$B$10*D11/기준값!$B$18,"-"),"-") -> 13333.333 | F11: =IF(ISNUMBER(E11),E11*기준값!$B$18,"-") -> 400000 | G11: =IF(ISNUMBER(E11),기준값!$B$8+E11,"-") -> 443333.33 | H11: =IF(ISNUMBER(G11),B11-G11,"-") -> -16657.083 | I11: =IF(ISNUMBER(H11),H11*기준값!$B$18,"-") -> -499712.5 | J11: =IF(기준값!$B$19<기준값!$B$11,"두수기준미달",IF(기준값!$B$19>=기준값!$B$12,IF(A11>=기준값!$B$13,"인센티브","기본(두수만 충족)"),IF(A11>=기준값!$B$13,"기본","패널티"))) -> 기본(두수만 충족) | K11: =IF(기준값!$B$19<기준값!$B$11,"-",IF(기준값!$B$19>=기준값!$B$12,IF(A11>=기준값!$B$13,기준값!$B$14,기준값!$B$16),IF(A11>=기준값!$B$13,기준값!$B$16,기준값!$B$15))) -> 1 | L11: =IFERROR(IF(ISNUMBER(K11),기준값!$B$10*K11/기준값!$B$19,"-"),"-") -> 6153.8462 | M11: =IF(ISNUMBER(L11),L11*기준값!$B$19,"-") -> 400000 | N11: =IF(ISNUMBER(L11),기준값!$B$8+L11,"-") -> 436153.85 | O11: =IF(ISNUMBER(N11),B11-N11,"-") -> -9477.5962 | P11: =IF(ISNUMBER(O11),O11*기준값!$B$19,"-") -> -616043.75
A12: 111 | B12: =A12*기준값!$B$7 -> 430555.12 | C12: =IF(기준값!$B$18<기준값!$B$11,"두수기준미달",IF(기준값!$B$18>=기준값!$B$12,IF(A12>=기준값!$B$13,"인센티브","기본(두수만 충족)"),IF(A12>=기준값!$B$13,"기본","패널티"))) -> 패널티 | D12: =IF(기준값!$B$18<기준값!$B$11,"-",IF(기준값!$B$18>=기준값!$B$12,IF(A12>=기준값!$B$13,기준값!$B$14,기준값!$B$16),IF(A12>=기준값!$B$13,기준값!$B$16,기준값!$B$15))) -> 1 | E12: =IFERROR(IF(ISNUMBER(D12),기준값!$B$10*D12/기준값!$B$18,"-"),"-") -> 13333.333 | F12: =IF(ISNUMBER(E12),E12*기준값!$B$18,"-") -> 400000 | G12: =IF(ISNUMBER(E12),기준값!$B$8+E12,"-") -> 443333.33 | H12: =IF(ISNUMBER(G12),B12-G12,"-") -> -12778.208 | I12: =IF(ISNUMBER(H12),H12*기준값!$B$18,"-") -> -383346.25 | J12: =IF(기준값!$B$19<기준값!$B$11,"두수기준미달",IF(기준값!$B$19>=기준값!$B$12,IF(A12>=기준값!$B$13,"인센티브","기본(두수만 충족)"),IF(A12>=기준값!$B$13,"기본","패널티"))) -> 기본(두수만 충족) | K12: =IF(기준값!$B$19<기준값!$B$11,"-",IF(기준값!$B$19>=기준값!$B$12,IF(A12>=기준값!$B$13,기준값!$B$14,기준값!$B$16),IF(A12>=기준값!$B$13,기준값!$B$16,기준값!$B$15))) -> 1 | L12: =IFERROR(IF(ISNUMBER(K12),기준값!$B$10*K12/기준값!$B$19,"-"),"-") -> 6153.8462 | M12: =IF(ISNUMBER(L12),L12*기준값!$B$19,"-") -> 400000 | N12: =IF(ISNUMBER(L12),기준값!$B$8+L12,"-") -> 436153.85 | O12: =IF(ISNUMBER(N12),B12-N12,"-") -> -5598.7212 | P12: =IF(ISNUMBER(O12),O12*기준값!$B$19,"-") -> -363916.87
A13: 112 | B13: =A13*기준값!$B$7 -> 434434 | C13: =IF(기준값!$B$18<기준값!$B$11,"두수기준미달",IF(기준값!$B$18>=기준값!$B$12,IF(A13>=기준값!$B$13,"인센티브","기본(두수만 충족)"),IF(A13>=기준값!$B$13,"기본","패널티"))) -> 패널티 | D13: =IF(기준값!$B$18<기준값!$B$11,"-",IF(기준값!$B$18>=기준값!$B$12,IF(A13>=기준값!$B$13,기준값!$B$14,기준값!$B$16),IF(A13>=기준값!$B$13,기준값!$B$16,기준값!$B$15))) -> 1 | E13: =IFERROR(IF(ISNUMBER(D13),기준값!$B$10*D13/기준값!$B$18,"-"),"-") -> 13333.333 | F13: =IF(ISNUMBER(E13),E13*기준값!$B$18,"-") -> 400000 | G13: =IF(ISNUMBER(E13),기준값!$B$8+E13,"-") -> 443333.33 | H13: =IF(ISNUMBER(G13),B13-G13,"-") -> -8899.3333 | I13: =IF(ISNUMBER(H13),H13*기준값!$B$18,"-") -> -266980 | J13: =IF(기준값!$B$19<기준값!$B$11,"두수기준미달",IF(기준값!$B$19>=기준값!$B$12,IF(A13>=기준값!$B$13,"인센티브","기본(두수만 충족)"),IF(A13>=기준값!$B$13,"기본","패널티"))) -> 기본(두수만 충족) | K13: =IF(기준값!$B$19<기준값!$B$11,"-",IF(기준값!$B$19>=기준값!$B$12,IF(A13>=기준값!$B$13,기준값!$B$14,기준값!$B$16),IF(A13>=기준값!$B$13,기준값!$B$16,기준값!$B$15))) -> 1 | L13: =IFERROR(IF(ISNUMBER(K13),기준값!$B$10*K13/기준값!$B$19,"-"),"-") -> 6153.8462 | M13: =IF(ISNUMBER(L13),L13*기준값!$B$19,"-") -> 400000 | N13: =IF(ISNUMBER(L13),기준값!$B$8+L13,"-") -> 436153.85 | O13: =IF(ISNUMBER(N13),B13-N13,"-") -> -1719.8462 | P13: =IF(ISNUMBER(O13),O13*기준값!$B$19,"-") -> -111790
A14: 113 | B14: =A14*기준값!$B$7 -> 438312.88 | C14: =IF(기준값!$B$18<기준값!$B$11,"두수기준미달",IF(기준값!$B$18>=기준값!$B$12,IF(A14>=기준값!$B$13,"인센티브","기본(두수만 충족)"),IF(A14>=기준값!$B$13,"기본","패널티"))) -> 기본 | D14: =IF(기준값!$B$18<기준값!$B$11,"-",IF(기준값!$B$18>=기준값!$B$12,IF(A14>=기준값!$B$13,기준값!$B$14,기준값!$B$16),IF(A14>=기준값!$B$13,기준값!$B$16,기준값!$B$15))) -> 1 | E14: =IFERROR(IF(ISNUMBER(D14),기준값!$B$10*D14/기준값!$B$18,"-"),"-") -> 13333.333 | F14: =IF(ISNUMBER(E14),E14*기준값!$B$18,"-") -> 400000 | G14: =IF(ISNUMBER(E14),기준값!$B$8+E14,"-") -> 443333.33 | H14: =IF(ISNUMBER(G14),B14-G14,"-") -> -5020.4583 | I14: =IF(ISNUMBER(H14),H14*기준값!$B$18,"-") -> -150613.75 | J14: =IF(기준값!$B$19<기준값!$B$11,"두수기준미달",IF(기준값!$B$19>=기준값!$B$12,IF(A14>=기준값!$B$13,"인센티브","기본(두수만 충족)"),IF(A14>=기준값!$B$13,"기본","패널티"))) -> 인센티브 | K14: =IF(기준값!$B$19<기준값!$B$11,"-",IF(기준값!$B$19>=기준값!$B$12,IF(A14>=기준값!$B$13,기준값!$B$14,기준값!$B$16),IF(A14>=기준값!$B$13,기준값!$B$16,기준값!$B$15))) -> 1 | L14: =IFERROR(IF(ISNUMBER(K14),기준값!$B$10*K14/기준값!$B$19,"-"),"-") -> 6153.8462 | M14: =IF(ISNUMBER(L14),L14*기준값!$B$19,"-") -> 400000 | N14: =IF(ISNUMBER(L14),기준값!$B$8+L14,"-") -> 436153.85 | O14: =IF(ISNUMBER(N14),B14-N14,"-") -> 2159.0288 | P14: =IF(ISNUMBER(O14),O14*기준값!$B$19,"-") -> 140336.88
A15: 114 | B15: =A15*기준값!$B$7 -> 442191.75 | C15: =IF(기준값!$B$18<기준값!$B$11,"두수기준미달",IF(기준값!$B$18>=기준값!$B$12,IF(A15>=기준값!$B$13,"인센티브","기본(두수만 충족)"),IF(A15>=기준값!$B$13,"기본","패널티"))) -> 기본 | D15: =IF(기준값!$B$18<기준값!$B$11,"-",IF(기준값!$B$18>=기준값!$B$12,IF(A15>=기준값!$B$13,기준값!$B$14,기준값!$B$16),IF(A15>=기준값!$B$13,기준값!$B$16,기준값!$B$15))) -> 1 | E15: =IFERROR(IF(ISNUMBER(D15),기준값!$B$10*D15/기준값!$B$18,"-"),"-") -> 13333.333 | F15: =IF(ISNUMBER(E15),E15*기준값!$B$18,"-") -> 400000 | G15: =IF(ISNUMBER(E15),기준값!$B$8+E15,"-") -> 443333.33 | H15: =IF(ISNUMBER(G15),B15-G15,"-") -> -1141.5833 | I15: =IF(ISNUMBER(H15),H15*기준값!$B$18,"-") -> -34247.5 | J15: =IF(기준값!$B$19<기준값!$B$11,"두수기준미달",IF(기준값!$B$19>=기준값!$B$12,IF(A15>=기준값!$B$13,"인센티브","기본(두수만 충족)"),IF(A15>=기준값!$B$13,"기본","패널티"))) -> 인센티브 | K15: =IF(기준값!$B$19<기준값!$B$11,"-",IF(기준값!$B$19>=기준값!$B$12,IF(A15>=기준값!$B$13,기준값!$B$14,기준값!$B$16),IF(A15>=기준값!$B$13,기준값!$B$16,기준값!$B$15))) -> 1 | L15: =IFERROR(IF(ISNUMBER(K15),기준값!$B$10*K15/기준값!$B$19,"-"),"-") -> 6153.8462 | M15: =IF(ISNUMBER(L15),L15*기준값!$B$19,"-") -> 400000 | N15: =IF(ISNUMBER(L15),기준값!$B$8+L15,"-") -> 436153.85 | O15: =IF(ISNUMBER(N15),B15-N15,"-") -> 6037.9038 | P15: =IF(ISNUMBER(O15),O15*기준값!$B$19,"-") -> 392463.75
A16: 115 | B16: =A16*기준값!$B$7 -> 446070.62 | C16: =IF(기준값!$B$18<기준값!$B$11,"두수기준미달",IF(기준값!$B$18>=기준값!$B$12,IF(A16>=기준값!$B$13,"인센티브","기본(두수만 충족)"),IF(A16>=기준값!$B$13,"기본","패널티"))) -> 기본 | D16: =IF(기준값!$B$18<기준값!$B$11,"-",IF(기준값!$B$18>=기준값!$B$12,IF(A16>=기준값!$B$13,기준값!$B$14,기준값!$B$16),IF(A16>=기준값!$B$13,기준값!$B$16,기준값!$B$15))) -> 1 | E16: =IFERROR(IF(ISNUMBER(D16),기준값!$B$10*D16/기준값!$B$18,"-"),"-") -> 13333.333 | F16: =IF(ISNUMBER(E16),E16*기준값!$B$18,"-") -> 400000 | G16: =IF(ISNUMBER(E16),기준값!$B$8+E16,"-") -> 443333.33 | H16: =IF(ISNUMBER(G16),B16-G16,"-") -> 2737.2917 | I16: =IF(ISNUMBER(H16),H16*기준값!$B$18,"-") -> 82118.75 | J16: =IF(기준값!$B$19<기준값!$B$11,"두수기준미달",IF(기준값!$B$19>=기준값!$B$12,IF(A16>=기준값!$B$13,"인센티브","기본(두수만 충족)"),IF(A16>=기준값!$B$13,"기본","패널티"))) -> 인센티브 | K16: =IF(기준값!$B$19<기준값!$B$11,"-",IF(기준값!$B$19>=기준값!$B$12,IF(A16>=기준값!$B$13,기준값!$B$14,기준값!$B$16),IF(A16>=기준값!$B$13,기준값!$B$16,기준값!$B$15))) -> 1 | L16: =IFERROR(IF(ISNUMBER(K16),기준값!$B$10*K16/기준값!$B$19,"-"),"-") -> 6153.8462 | M16: =IF(ISNUMBER(L16),L16*기준값!$B$19,"-") -> 400000 | N16: =IF(ISNUMBER(L16),기준값!$B$8+L16,"-") -> 436153.85 | O16: =IF(ISNUMBER(N16),B16-N16,"-") -> 9916.7788 | P16: =IF(ISNUMBER(O16),O16*기준값!$B$19,"-") -> 644590.63
A17: 116 | B17: =A17*기준값!$B$7 -> 449949.5 | C17: =IF(기준값!$B$18<기준값!$B$11,"두수기준미달",IF(기준값!$B$18>=기준값!$B$12,IF(A17>=기준값!$B$13,"인센티브","기본(두수만 충족)"),IF(A17>=기준값!$B$13,"기본","패널티"))) -> 기본 | D17: =IF(기준값!$B$18<기준값!$B$11,"-",IF(기준값!$B$18>=기준값!$B$12,IF(A17>=기준값!$B$13,기준값!$B$14,기준값!$B$16),IF(A17>=기준값!$B$13,기준값!$B$16,기준값!$B$15))) -> 1 | E17: =IFERROR(IF(ISNUMBER(D17),기준값!$B$10*D17/기준값!$B$18,"-"),"-") -> 13333.333 | F17: =IF(ISNUMBER(E17),E17*기준값!$B$18,"-") -> 400000 | G17: =IF(ISNUMBER(E17),기준값!$B$8+E17,"-") -> 443333.33 | H17: =IF(ISNUMBER(G17),B17-G17,"-") -> 6616.1667 | I17: =IF(ISNUMBER(H17),H17*기준값!$B$18,"-") -> 198485 | J17: =IF(기준값!$B$19<기준값!$B$11,"두수기준미달",IF(기준값!$B$19>=기준값!$B$12,IF(A17>=기준값!$B$13,"인센티브","기본(두수만 충족)"),IF(A17>=기준값!$B$13,"기본","패널티"))) -> 인센티브 | K17: =IF(기준값!$B$19<기준값!$B$11,"-",IF(기준값!$B$19>=기준값!$B$12,IF(A17>=기준값!$B$13,기준값!$B$14,기준값!$B$16),IF(A17>=기준값!$B$13,기준값!$B$16,기준값!$B$15))) -> 1 | L17: =IFERROR(IF(ISNUMBER(K17),기준값!$B$10*K17/기준값!$B$19,"-"),"-") -> 6153.8462 | M17: =IF(ISNUMBER(L17),L17*기준값!$B$19,"-") -> 400000 | N17: =IF(ISNUMBER(L17),기준값!$B$8+L17,"-") -> 436153.85 | O17: =IF(ISNUMBER(N17),B17-N17,"-") -> 13795.654 | P17: =IF(ISNUMBER(O17),O17*기준값!$B$19,"-") -> 896717.5
... A26: 125 | B26: =A26*기준값!$B$7 -> 484859.38 | C26: =IF(기준값!$B$18<기준값!$B$11,"두수기준미달",IF(기준값!$B$18>=기준값!$B$12,IF(A26>=기준값!$B$13,"인센티브","기본(두수만 충족)"),IF(A26>=기준값!$B$13,"기본","패널티"))) -> 기본 | D26: =IF(기준값!$B$18<기준값!$B$11,"-",IF(기준값!$B$18>=기준값!$B$12,IF(A26>=기준값!$B$13,기준값!$B$14,기준값!$B$16),IF(A26>=기준값!$B$13,기준값!$B$16,기준값!$B$15))) -> 1 | E26: =IFERROR(IF(ISNUMBER(D26),기준값!$B$10*D26/기준값!$B$18,"-"),"-") -> 13333.333 | F26: =IF(ISNUMBER(E26),E26*기준값!$B$18,"-") -> 400000 | G26: =IF(ISNUMBER(E26),기준값!$B$8+E26,"-") -> 443333.33 | H26: =IF(ISNUMBER(G26),B26-G26,"-") -> 41526.042 | I26: =IF(ISNUMBER(H26),H26*기준값!$B$18,"-") -> 1245781.3 | J26: =IF(기준값!$B$19<기준값!$B$11,"두수기준미달",IF(기준값!$B$19>=기준값!$B$12,IF(A26>=기준값!$B$13,"인센티브","기본(두수만 충족)"),IF(A26>=기준값!$B$13,"기본","패널티"))) -> 인센티브 | K26: =IF(기준값!$B$19<기준값!$B$11,"-",IF(기준값!$B$19>=기준값!$B$12,IF(A26>=기준값!$B$13,기준값!$B$14,기준값!$B$16),IF(A26>=기준값!$B$13,기준값!$B$16,기준값!$B$15))) -> 1 | L26: =IFERROR(IF(ISNUMBER(K26),기준값!$B$10*K26/기준값!$B$19,"-"),"-") -> 6153.8462 | M26: =IF(ISNUMBER(L26),L26*기준값!$B$19,"-") -> 400000 | N26: =IF(ISNUMBER(L26),기준값!$B$8+L26,"-") -> 436153.85 | O26: =IF(ISNUMBER(N26),B26-N26,"-") -> 48705.529 | P26: =IF(ISNUMBER(O26),O26*기준값!$B$19,"-") -> 3165859.4
A28: ※ 음영 처리된 행(113kg)은 정책 기준체중입니다. 순수익이 음수(적자)인 셀은 빨간색으로 표시됩니다.

Sheet 거리구간표
A1: 거리구간별 운반비 (기존 vs 개정)
A2: ※ [기준값] 시트의 편도거리 입력값은 이 표의 '개정 지급액'(D열)을 자동 조회합니다. 신설 구간은 음영 표시했습니다.
A4: 구간 | B4: 하한거리(km) | C4: 기존 지급액(원) | D4: 개정 지급액(원) | E4: 증감 | F4: 비고
A5: ~40km | B5: 0 | C5: 300000 | D5: 300000 | E5: =IF(C5="","신설","유지") -> 유지 | F5: 유지
A6: 41~80km | B6: 41 | C6: 350000 | D6: 350000 | E6: =IF(C6="","신설","유지") -> 유지 | F6: 유지
A7: 81~120km | B7: 81 | C7: 400000 | D7: 400000 | E7: =IF(C7="","신설","유지") -> 유지 | F7: 유지
A8: 121~150km | B8: 121 | C8: 500000 | D8: 500000 | E8: =IF(C8="","신설","유지") -> 유지 | F8: 유지
A9: 151~180km | B9: 151 | C9: 550000 | D9: 550000 | E9: =IF(C9="","신설","유지") -> 유지 | F9: 유지
A10: 181~220km | B10: 181 | D10: 600000 | E10: =IF(C10="","신설","유지") -> 신설
A11: 221~260km | B11: 221 | D11: 650000 | E11: =IF(C11="","신설","유지") -> 신설
A12: 261~300km | B12: 261 | D12: 700000 | E12: =IF(C12="","신설","유지") -> 신설
A13: 301~340km | B13: 301 | D13: 750000 | E13: =IF(C13="","신설","유지") -> 신설 | F13: 301km~ 규칙: 40km마다 +50,000
A14: 341~380km | B14: 341 | D14: 800000 | E14: =IF(C14="","신설","유지") -> 신설 | F14: 상동
A15: 381~420km | B15: 381 | D15: 850000 | E15: =IF(C15="","신설","유지") -> 신설 | F15: 상동
A16: 421~460km | B16: 421 | D16: 900000 | E16: =IF(C16="","신설","유지") -> 신설 | F16: 상동
A17: 461~500km | B17: 461 | D17: 950000 | E17: =IF(C17="","신설","유지") -> 신설 | F17: 상동 (500km 초과 시 동일 규칙 계속 적용)
A19: 가정 및 참고사항
A20: • 이전 대화에서 산정한 운반비 개편안을 그대로 옮긴 표입니다: 151km 이상 구간을 4단계로 세분화하고, 301km 이상은 40km마다 +50,000원을 가산하는 규칙을 적용했습니다.
A21: • 가산폭(40km당 +50,000원)의 근거: 대형 가축운반차 평균연비 약 3.0km/L, 최근 1년 평균 경유가 약 1,730원/L 추정 시 편도 40km 확장에 따른 왕복 유류비 증가분이 약 46,000원입니다.

Sheet 기준값
A1: 산정 기준값
A2: ※ 파란 글씨 셀만 수정하세요. 검은 글씨(수식)·녹색 글씨(다른 시트 참조)는 건드리지 않아도 자동 계산됩니다.
A3: 항목 | B3: 값 | C3: 비고
A4: 돈가 (원/kg, 지육 기준) | B4: 6500 | C4: 사용자 제공값
A5: 지육율 | B5: 0.775 | C5: 사용자 제공값 (77.5%)
A6: 지급율 | B6: 0.77 | C6: 사용자 제공값 (77%)
A7: 두당 정산단가 (원/kg, 생체중 환산) | B7: =B4*B5*B6 -> 3878.875 | C7: 돈가 × 지육율 × 지급율
A8: 두당 생산원가 (원/두, 운반비 제외) | B8: 430000 | C8: 사용자 제공값
A9: 편도거리 (km) | B9: 100 | C9: 예시값 — 실제 거리로 수정
A10: 기본운반비 (원) | B10: =INDEX(거리구간표!$D$5:$D$17,MATCH(B9,거리구간표!$B$5:$B$17,1)) -> 400000 | C10: [거리구간표] 시트의 '개정 지급액'을 자동 조회
A11: 최소 상차두수 (기준) | B11: 30 | C11: 이전 대화에서 정한 정책기준
A12: 인센티브 두수기준 (이상) | B12: 60 | C12: 이전 대화에서 정한 정책기준
A13: 기준 체중 (kg) | B13: 113 | C13: 이전 대화에서 정한 정책기준
A14: 인센티브 지급률 | B14: 1 | C14: 기본운반비 대비 +10%
A15: 패널티 지급률 | B15: 1 | C15: 기본운반비 대비 -10%
A16: 기본 지급률 | B16: 1 | C16: 조건 미해당 시 100% 유지
A18: 두수 시나리오 A (30~59두 구간 예시) | B18: 30 | C18: [체중별_손익표] 블록① 두수
A19: 두수 시나리오 B (60두 이상 구간 예시) | B19: 65 | C19: [체중별_손익표] 블록② 두수
A21: 가정 및 참고사항
A22: • 경유가·거리구간 기본운반비는 이전 대화에서 산출한 값을 그대로 사용했습니다 (최근 1년 평균 경유가 약 1,730원/L 추정 기준, 오피넷 주간자료 기반).
A23: • 두당 정산단가 공식(돈가×지육율×지급율)은 지육 기준 돈가를 생체중 기준으로 환산하는 일반적 방식을 가정한 것으로, 실제 계열화 업체 정산 방식과 다를 수 있습니다.
A24: • 두당 생산원가 410,000원은 체중과 무관한 고정값으로 가정했고, 여기에 두당 운반비를 더해 '두당 총원가'로 손익을 계산합니다.
A25: • 301km 이상 구간은 40km마다 +50,000원을 가산하는 규칙을 500km까지 표로 확장했습니다 ([거리구간표] 시트 참고). 그 이상 거리는 동일 규칙을 계속 적용하면 됩니다.

Sheet 거리구간별_체중별_손익표
A1: 거리구간별 × 체중별 두당 순수익 매트릭스
A2: ※ 값 = 두당 순수익(원) = 체중×정산단가 − 생산원가 − 두당운반비. 거리구간·기준값을 바꾸면 자동 재계산됩니다. 구간은 [거리구간표] 시트의 ~40km부터 301~340km까지 9개(그 이상은 동일 규칙 적용).
A4: ="시나리오 A · 두수 "&기준값!$B$18&"두" -> 시나리오 A · 두수 30두
A5: 평균체중\거리구간 | B5: =거리구간표!$A$5 -> ~40km | C5: =거리구간표!$A$6 -> 41~80km | D5: =거리구간표!$A$7 -> 81~120km | E5: =거리구간표!$A$8 -> 121~150km | F5: =거리구간표!$A$9 -> 151~180km | G5: =거리구간표!$A$10 -> 181~220km | H5: =거리구간표!$A$11 -> 221~260km | I5: =거리구간표!$A$12 -> 261~300km | J5: =거리구간표!$A$13 -> 301~340km
A6: 105 | B6: =$A6*기준값!$B$7-기준값!$B$8-(거리구간표!$D$5*(IF(기준값!$B$18<기준값!$B$11,기준값!$B$16,IF(기준값!$B$18>=기준값!$B$12,IF($A6>=기준값!$B$13,기준값!$B$14,기준값!$B$16),IF($A6>=기준값!$B$13,기준값!$B$16,기준값!$B$15)))))/기준값!$B$18 -> -32718.125 | C6: =$A6*기준값!$B$7-기준값!$B$8-(거리구간표!$D$6*(IF(기준값!$B$18<기준값!$B$11,기준값!$B$16,IF(기준값!$B$18>=기준값!$B$12,IF($A6>=기준값!$B$13,기준값!$B$14,기준값!$B$16),IF($A6>=기준값!$B$13,기준값!$B$16,기준값!$B$15)))))/기준값!$B$18 -> -34384.792 | D6: =$A6*기준값!$B$7-기준값!$B$8-(거리구간표!$D$7*(IF(기준값!$B$18<기준값!$B$11,기준값!$B$16,IF(기준값!$B$18>=기준값!$B$12,IF($A6>=기준값!$B$13,기준값!$B$14,기준값!$B$16),IF($A6>=기준값!$B$13,기준값!$B$16,기준값!$B$15)))))/기준값!$B$18 -> -36051.458 | E6: =$A6*기준값!$B$7-기준값!$B$8-(거리구간표!$D$8*(IF(기준값!$B$18<기준값!$B$11,기준값!$B$16,IF(기준값!$B$18>=기준값!$B$12,IF($A6>=기준값!$B$13,기준값!$B$14,기준값!$B$16),IF($A6>=기준값!$B$13,기준값!$B$16,기준값!$B$15)))))/기준값!$B$18 -> -39384.792 | F6: =$A6*기준값!$B$7-기준값!$B$8-(거리구간표!$D$9*(IF(기준값!$B$18<기준값!$B$11,기준값!$B$16,IF(기준값!$B$18>=기준값!$B$12,IF($A6>=기준값!$B$13,기준값!$B$14,기준값!$B$16),IF($A6>=기준값!$B$13,기준값!$B$16,기준값!$B$15)))))/기준값!$B$18 -> -41051.458 | G6: =$A6*기준값!$B$7-기준값!$B$8-(거리구간표!$D$10*(IF(기준값!$B$18<기준값!$B$11,기준값!$B$16,IF(기준값!$B$18>=기준값!$B$12,IF($A6>=기준값!$B$13,기준값!$B$14,기준값!$B$16),IF($A6>=기준값!$B$13,기준값!$B$16,기준값!$B$15)))))/기준값!$B$18 -> -42718.125 | H6: =$A6*기준값!$B$7-기준값!$B$8-(거리구간표!$D$11*(IF(기준값!$B$18<기준값!$B$11,기준값!$B$16,IF(기준값!$B$18>=기준값!$B$12,IF($A6>=기준값!$B$13,기준값!$B$14,기준값!$B$16),IF($A6>=기준값!$B$13,기준값!$B$16,기준값!$B$15)))))/기준값!$B$18 -> -44384.792 | I6: =$A6*기준값!$B$7-기준값!$B$8-(거리구간표!$D$12*(IF(기준값!$B$18<기준값!$B$11,기준값!$B$16,IF(기준값!$B$18>=기준값!$B$12,IF($A6>=기준값!$B$13,기준값!$B$14,기준값!$B$16),IF($A6>=기준값!$B$13,기준값!$B$16,기준값!$B$15)))))/기준값!$B$18 -> -46051.458 | J6: =$A6*기준값!$B$7-기준값!$B$8-(거리구간표!$D$13*(IF(기준값!$B$18<기준값!$B$11,기준값!$B$16,IF(기준값!$B$18>=기준값!$B$12,IF($A6>=기준값!$B$13,기준값!$B$14,기준값!$B$16),IF($A6>=기준값!$B$13,기준값!$B$16,기준값!$B$15)))))/기준값!$B$18 -> -47718.125
A7: 106 | B7: =$A7*기준값!$B$7-기준값!$B$8-(거리구간표!$D$5*(IF(기준값!$B$18<기준값!$B$11,기준값!$B$16,IF(기준값!$B$18>=기준값!$B$12,IF($A7>=기준값!$B$13,기준값!$B$14,기준값!$B$16),IF($A7>=기준값!$B$13,기준값!$B$16,기준값!$B$15)))))/기준값!$B$18 -> -28839.25 | C7: =$A7*기준값!$B$7-기준값!$B$8-(거리구간표!$D$6*(IF(기준값!$B$18<기준값!$B$11,기준값!$B$16,IF(기준값!$B$18>=기준값!$B$12,IF($A7>=기준값!$B$13,기준값!$B$14,기준값!$B$16),IF($A7>=기준값!$B$13,기준값!$B$16,기준값!$B$15)))))/기준값!$B$18 -> -30505.917 | D7: =$A7*기준값!$B$7-기준값!$B$8-(거리구간표!$D$7*(IF(기준값!$B$18<기준값!$B$11,기준값!$B$16,IF(기준값!$B$18>=기준값!$B$12,IF($A7>=기준값!$B$13,기준값!$B$14,기준값!$B$16),IF($A7>=기준값!$B$13,기준값!$B$16,기준값!$B$15)))))/기준값!$B$18 -> -32172.583 | E7: =$A7*기준값!$B$7-기준값!$B$8-(거리구간표!$D$8*(IF(기준값!$B$18<기준값!$B$11,기준값!$B$16,IF(기준값!$B$18>=기준값!$B$12,IF($A7>=기준값!$B$13,기준값!$B$14,기준값!$B$16),IF($A7>=기준값!$B$13,기준값!$B$16,기준값!$B$15)))))/기준값!$B$18 -> -35505.917 | F7: =$A7*기준값!$B$7-기준값!$B$8-(거리구간표!$D$9*(IF(기준값!$B$18<기준값!$B$11,기준값!$B$16,IF(기준값!$B$18>=기준값!$B$12,IF($A7>=기준값!$B$13,기준값!$B$14,기준값!$B$16),IF($A7>=기준값!$B$13,기준값!$B$16,기준값!$B$15)))))/기준값!$B$18 -> -37172.583 | G7: =$A7*기준값!$B$7-기준값!$B$8-(거리구간표!$D$10*(IF(기준값!$B$18<기준값!$B$11,기준값!$B$16,IF(기준값!$B$18>=기준값!$B$12,IF($A7>=기준값!$B$13,기준값!$B$14,기준값!$B$16),IF($A7>=기준값!$B$13,기준값!$B$16,기준값!$B$15)))))/기준값!$B$18 -> -38839.25 | H7: =$A7*기준값!$B$7-기준값!$B$8-(거리구간표!$D$11*(IF(기준값!$B$18<기준값!$B$11,기준값!$B$16,IF(기준값!$B$18>=기준값!$B$12,IF($A7>=기준값!$B$13,기준값!$B$14,기준값!$B$16),IF($A7>=기준값!$B$13,기준값!$B$16,기준값!$B$15)))))/기준값!$B$18 -> -40505.917 | I7: =$A7*기준값!$B$7-기준값!$B$8-(거리구간표!$D$12*(IF(기준값!$B$18<기준값!$B$11,기준값!$B$16,IF(기준값!$B$18>=기준값!$B$12,IF($A7>=기준값!$B$13,기준값!$B$14,기준값!$B$16),IF($A7>=기준값!$B$13,기준값!$B$16,기준값!$B$15)))))/기준값!$B$18 -> -42172.583 | J7: =$A7*기준값!$B$7-기준값!$B$8-(거리구간표!$D$13*(IF(기준값!$B$18<기준값!$B$11,기준값!$B$16,IF(기준값!$B$18>=기준값!$B$12,IF($A7>=기준값!$B$13,기준값!$B$14,기준값!$B$16),IF($A7>=기준값!$B$13,기준값!$B$16,기준값!$B$15)))))/기준값!$B$18 -> -43839.25
A8: 107 | B8: =$A8*기준값!$B$7-기준값!$B$8-(거리구간표!$D$5*(IF(기준값!$B$18<기준값!$B$11,기준값!$B$16,IF(기준값!$B$18>=기준값!$B$12,IF($A8>=기준값!$B$13,기준값!$B$14,기준값!$B$16),IF($A8>=기준값!$B$13,기준값!$B$16,기준값!$B$15)))))/기준값!$B$18 -> -24960.375 | C8: =$A8*기준값!$B$7-기준값!$B$8-(거리구간표!$D$6*(IF(기준값!$B$18<기준값!$B$11,기준값!$B$16,IF(기준값!$B$18>=기준값!$B$12,IF($A8>=기준값!$B$13,기준값!$B$14,기준값!$B$16),IF($A8>=기준값!$B$13,기준값!$B$16,기준값!$B$15)))))/기준값!$B$18 -> -26627.042 | D8: =$A8*기준값!$B$7-기준값!$B$8-(거리구간표!$D$7*(IF(기준값!$B$18<기준값!$B$11,기준값!$B$16,IF(기준값!$B$18>=기준값!$B$12,IF($A8>=기준값!$B$13,기준값!$B$14,기준값!$B$16),IF($A8>=기준값!$B$13,기준값!$B$16,기준값!$B$15)))))/기준값!$B$18 -> -28293.708 | E8: =$A8*기준값!$B$7-기준값!$B$8-(거리구간표!$D$8*(IF(기준값!$B$18<기준값!$B$11,기준값!$B$16,IF(기준값!$B$18>=기준값!$B$12,IF($A8>=기준값!$B$13,기준값!$B$14,기준값!$B$16),IF($A8>=기준값!$B$13,기준값!$B$16,기준값!$B$15)))))/기준값!$B$18 -> -31627.042 | F8: =$A8*기준값!$B$7-기준값!$B$8-(거리구간표!$D$9*(IF(기준값!$B$18<기준값!$B$11,기준값!$B$16,IF(기준값!$B$18>=기준값!$B$12,IF($A8>=기준값!$B$13,기준값!$B$14,기준값!$B$16),IF($A8>=기준값!$B$13,기준값!$B$16,기준값!$B$15)))))/기준값!$B$18 -> -33293.708 | G8: =$A8*기준값!$B$7-기준값!$B$8-(거리구간표!$D$10*(IF(기준값!$B$18<기준값!$B$11,기준값!$B$16,IF(기준값!$B$18>=기준값!$B$12,IF($A8>=기준값!$B$13,기준값!$B$14,기준값!$B$16),IF($A8>=기준값!$B$13,기준값!$B$16,기준값!$B$15)))))/기준값!$B$18 -> -34960.375 | H8: =$A8*기준값!$B$7-기준값!$B$8-(거리구간표!$D$11*(IF(기준값!$B$18<기준값!$B$11,기준값!$B$16,IF(기준값!$B$18>=기준값!$B$12,IF($A8>=기준값!$B$13,기준값!$B$14,기준값!$B$16),IF($A8>=기준값!$B$13,기준값!$B$16,기준값!$B$15)))))/기준값!$B$18 -> -36627.042 | I8: =$A8*기준값!$B$7-기준값!$B$8-(거리구간표!$D$12*(IF(기준값!$B$18<기준값!$B$11,기준값!$B$16,IF(기준값!$B$18>=기준값!$B$12,IF($A8>=기준값!$B$13,기준값!$B$14,기준값!$B$16),IF($A8>=기준값!$B$13,기준값!$B$16,기준값!$B$15)))))/기준값!$B$18 -> -38293.708 | J8: =$A8*기준값!$B$7-기준값!$B$8-(거리구간표!$D$13*(IF(기준값!$B$18<기준값!$B$11,기준값!$B$16,IF(기준값!$B$18>=기준값!$B$12,IF($A8>=기준값!$B$13,기준값!$B$14,기준값!$B$16),IF($A8>=기준값!$B$13,기준값!$B$16,기준값!$B$15)))))/기준값!$B$18 -> -39960.375
A9: 108 | B9: =$A9*기준값!$B$7-기준값!$B$8-(거리구간표!$D$5*(IF(기준값!$B$18<기준값!$B$11,기준값!$B$16,IF(기준값!$B$18>=기준값!$B$12,IF($A9>=기준값!$B$13,기준값!$B$14,기준값!$B$16),IF($A9>=기준값!$B$13,기준값!$B$16,기준값!$B$15)))))/기준값!$B$18 -> -21081.5 | C9: =$A9*기준값!$B$7-기준값!$B$8-(거리구간표!$D$6*(IF(기준값!$B$18<기준값!$B$11,기준값!$B$16,IF(기준값!$B$18>=기준값!$B$12,IF($A9>=기준값!$B$13,기준값!$B$14,기준값!$B$16),IF($A9>=기준값!$B$13,기준값!$B$16,기준값!$B$15)))))/기준값!$B$18 -> -22748.167 | D9: =$A9*기준값!$B$7-기준값!$B$8-(거리구간표!$D$7*(IF(기준값!$B$18<기준값!$B$11,기준값!$B$16,IF(기준값!$B$18>=기준값!$B$12,IF($A9>=기준값!$B$13,기준값!$B$14,기준값!$B$16),IF($A9>=기준값!$B$13,기준값!$B$16,기준값!$B$15)))))/기준값!$B$18 -> -24414.833 | E9: =$A9*기준값!$B$7-기준값!$B$8-(거리구간표!$D$8*(IF(기준값!$B$18<기준값!$B$11,기준값!$B$16,IF(기준값!$B$18>=기준값!$B$12,IF($A9>=기준값!$B$13,기준값!$B$14,기준값!$B$16),IF($A9>=기준값!$B$13,기준값!$B$16,기준값!$B$15)))))/기준값!$B$18 -> -27748.167 | F9: =$A9*기준값!$B$7-기준값!$B$8-(거리구간표!$D$9*(IF(기준값!$B$18<기준값!$B$11,기준값!$B$16,IF(기준값!$B$18>=기준값!$B$12,IF($A9>=기준값!$B$13,기준값!$B$14,기준값!$B$16),IF($A9>=기준값!$B$13,기준값!$B$16,기준값!$B$15)))))/기준값!$B$18 -> -29414.833 | G9: =$A9*기준값!$B$7-기준값!$B$8-(거리구간표!$D$10*(IF(기준값!$B$18<기준값!$B$11,기준값!$B$16,IF(기준값!$B$18>=기준값!$B$12,IF($A9>=기준값!$B$13,기준값!$B$14,기준값!$B$16),IF($A9>=기준값!$B$13,기준값!$B$16,기준값!$B$15)))))/기준값!$B$18 -> -31081.5 | H9: =$A9*기준값!$B$7-기준값!$B$8-(거리구간표!$D$11*(IF(기준값!$B$18<기준값!$B$11,기준값!$B$16,IF(기준값!$B$18>=기준값!$B$12,IF($A9>=기준값!$B$13,기준값!$B$14,기준값!$B$16),IF($A9>=기준값!$B$13,기준값!$B$16,기준값!$B$15)))))/기준값!$B$18 -> -32748.167 | I9: =$A9*기준값!$B$7-기준값!$B$8-(거리구간표!$D$12*(IF(기준값!$B$18<기준값!$B$11,기준값!$B$16,IF(기준값!$B$18>=기준값!$B$12,IF($A9>=기준값!$B$13,기준값!$B$14,기준값!$B$16),IF($A9>=기준값!$B$13,기준값!$B$16,기준값!$B$15)))))/기준값!$B$18 -> -34414.833 | J9: =$A9*기준값!$B$7-기준값!$B$8-(거리구간표!$D$13*(IF(기준값!$B$18<기준값!$B$11,기준값!$B$16,IF(기준값!$B$18>=기준값!$B$12,IF($A9>=기준값!$B$13,기준값!$B$14,기준값!$B$16),IF($A9>=기준값!$B$13,기준값!$B$16,기준값!$B$15)))))/기준값!$B$18 -> -36081.5
A10: 109 | B10: =$A10*기준값!$B$7-기준값!$B$8-(거리구간표!$D$5*(IF(기준값!$B$18<기준값!$B$11,기준값!$B$16,IF(기준값!$B$18>=기준값!$B$12,IF($A10>=기준값!$B$13,기준값!$B$14,기준값!$B$16),IF($A10>=기준값!$B$13,기준값!$B$16,기준값!$B$15)))))/기준값!$B$18 -> -17202.625 | C10: =$A10*기준값!$B$7-기준값!$B$8-(거리구간표!$D$6*(IF(기준값!$B$18<기준값!$B$11,기준값!$B$16,IF(기준값!$B$18>=기준값!$B$12,IF($A10>=기준값!$B$13,기준값!$B$14,기준값!$B$16),IF($A10>=기준값!$B$13,기준값!$B$16,기준값!$B$15)))))/기준값!$B$18 -> -18869.292 | D10: =$A10*기준값!$B$7-기준값!$B$8-(거리구간표!$D$7*(IF(기준값!$B$18<기준값!$B$11,기준값!$B$16,IF(기준값!$B$18>=기준값!$B$12,IF($A10>=기준값!$B$13,기준값!$B$14,기준값!$B$16),IF($A10>=기준값!$B$13,기준값!$B$16,기준값!$B$15)))))/기준값!$B$18 -> -20535.958 | E10: =$A10*기준값!$B$7-기준값!$B$8-(거리구간표!$D$8*(IF(기준값!$B$18<기준값!$B$11,기준값!$B$16,IF(기준값!$B$18>=기준값!$B$12,IF($A10>=기준값!$B$13,기준값!$B$14,기준값!$B$16),IF($A10>=기준값!$B$13,기준값!$B$16,기준값!$B$15)))))/기준값!$B$18 -> -23869.292 | F10: =$A10*기준값!$B$7-기준값!$B$8-(거리구간표!$D$9*(IF(기준값!$B$18<기준값!$B$11,기준값!$B$16,IF(기준값!$B$18>=기준값!$B$12,IF($A10>=기준값!$B$13,기준값!$B$14,기준값!$B$16),IF($A10>=기준값!$B$13,기준값!$B$16,기준값!$B$15)))))/기준값!$B$18 -> -25535.958 | G10: =$A10*기준값!$B$7-기준값!$B$8-(거리구간표!$D$10*(IF(기준값!$B$18<기준값!$B$11,기준값!$B$16,IF(기준값!$B$18>=기준값!$B$12,IF($A10>=기준값!$B$13,기준값!$B$14,기준값!$B$16),IF($A10>=기준값!$B$13,기준값!$B$16,기준값!$B$15)))))/기준값!$B$18 -> -27202.625 | H10: =$A10*기준값!$B$7-기준값!$B$8-(거리구간표!$D$11*(IF(기준값!$B$18<기준값!$B$11,기준값!$B$16,IF(기준값!$B$18>=기준값!$B$12,IF($A10>=기준값!$B$13,기준값!$B$14,기준값!$B$16),IF($A10>=기준값!$B$13,기준값!$B$16,기준값!$B$15)))))/기준값!$B$18 -> -28869.292 | I10: =$A10*기준값!$B$7-기준값!$B$8-(거리구간표!$D$12*(IF(기준값!$B$18<기준값!$B$11,기준값!$B$16,IF(기준값!$B$18>=기준값!$B$12,IF($A10>=기준값!$B$13,기준값!$B$14,기준값!$B$16),IF($A10>=기준값!$B$13,기준값!$B$16,기준값!$B$15)))))/기준값!$B$18 -> -30535.958 | J10: =$A10*기준값!$B$7-기준값!$B$8-(거리구간표!$D$13*(IF(기준값!$B$18<기준값!$B$11,기준값!$B$16,IF(기준값!$B$18>=기준값!$B$12,IF($A10>=기준값!$B$13,기준값!$B$14,기준값!$B$16),IF($A10>=기준값!$B$13,기준값!$B$16,기준값!$B$15)))))/기준값!$B$18 -> -32202.625
A11: 110 | B11: =$A11*기준값!$B$7-기준값!$B$8-(거리구간표!$D$5*(IF(기준값!$B$18<기준값!$B$11,기준값!$B$16,IF(기준값!$B$18>=기준값!$B$12,IF($A11>=기준값!$B$13,기준값!$B$14,기준값!$B$16),IF($A11>=기준값!$B$13,기준값!$B$16,기준값!$B$15)))))/기준값!$B$18 -> -13323.75 | C11: =$A11*기준값!$B$7-기준값!$B$8-(거리구간표!$D$6*(IF(기준값!$B$18<기준값!$B$11,기준값!$B$16,IF(기준값!$B$18>=기준값!$B$12,IF($A11>=기준값!$B$13,기준값!$B$14,기준값!$B$16),IF($A11>=기준값!$B$13,기준값!$B$16,기준값!$B$15)))))/기준값!$B$18 -> -14990.417 | D11: =$A11*기준값!$B$7-기준값!$B$8-(거리구간표!$D$7*(IF(기준값!$B$18<기준값!$B$11,기준값!$B$16,IF(기준값!$B$18>=기준값!$B$12,IF($A11>=기준값!$B$13,기준값!$B$14,기준값!$B$16),IF($A11>=기준값!$B$13,기준값!$B$16,기준값!$B$15)))))/기준값!$B$18 -> -16657.083 | E11: =$A11*기준값!$B$7-기준값!$B$8-(거리구간표!$D$8*(IF(기준값!$B$18<기준값!$B$11,기준값!$B$16,IF(기준값!$B$18>=기준값!$B$12,IF($A11>=기준값!$B$13,기준값!$B$14,기준값!$B$16),IF($A11>=기준값!$B$13,기준값!$B$16,기준값!$B$15)))))/기준값!$B$18 -> -19990.417 | F11: =$A11*기준값!$B$7-기준값!$B$8-(거리구간표!$D$9*(IF(기준값!$B$18<기준값!$B$11,기준값!$B$16,IF(기준값!$B$18>=기준값!$B$12,IF($A11>=기준값!$B$13,기준값!$B$14,기준값!$B$16),IF($A11>=기준값!$B$13,기준값!$B$16,기준값!$B$15)))))/기준값!$B$18 -> -21657.083 | G11: =$A11*기준값!$B$7-기준값!$B$8-(거리구간표!$D$10*(IF(기준값!$B$18<기준값!$B$11,기준값!$B$16,IF(기준값!$B$18>=기준값!$B$12,IF($A11>=기준값!$B$13,기준값!$B$14,기준값!$B$16),IF($A11>=기준값!$B$13,기준값!$B$16,기준값!$B$15)))))/기준값!$B$18 -> -23323.75 | H11: =$A11*기준값!$B$7-기준값!$B$8-(거리구간표!$D$11*(IF(기준값!$B$18<기준값!$B$11,기준값!$B$16,IF(기준값!$B$18>=기준값!$B$12,IF($A11>=기준값!$B$13,기준값!$B$14,기준값!$B$16),IF($A11>=기준값!$B$13,기준값!$B$16,기준값!$B$15)))))/기준값!$B$18 -> -24990.417 | I11: =$A11*기준값!$B$7-기준값!$B$8-(거리구간표!$D$12*(IF(기준값!$B$18<기준값!$B$11,기준값!$B$16,IF(기준값!$B$18>=기준값!$B$12,IF($A11>=기준값!$B$13,기준값!$B$14,기준값!$B$16),IF($A11>=기준값!$B$13,기준값!$B$16,기준값!$B$15)))))/기준값!$B$18 -> -26657.083 | J11: =$A11*기준값!$B$7-기준값!$B$8-(거리구간표!$D$13*(IF(기준값!$B$18<기준값!$B$11,기준값!$B$16,IF(기준값!$B$18>=기준값!$B$12,IF($A11>=기준값!$B$13,기준값!$B$14,기준값!$B$16),IF($A11>=기준값!$B$13,기준값!$B$16,기준값!$B$15)))))/기준값!$B$18 -> -28323.75
A12: 111 | B12: =$A12*기준값!$B$7-기준값!$B$8-(거리구간표!$D$5*(IF(기준값!$B$18<기준값!$B$11,기준값!$B$16,IF(기준값!$B$18>=기준값!$B$12,IF($A12>=기준값!$B$13,기준값!$B$14,기준값!$B$16),IF($A12>=기준값!$B$13,기준값!$B$16,기준값!$B$15)))))/기준값!$B$18 -> -9444.875 | C12: =$A12*기준값!$B$7-기준값!$B$8-(거리구간표!$D$6*(IF(기준값!$B$18<기준값!$B$11,기준값!$B$16,IF(기준값!$B$18>=기준값!$B$12,IF($A12>=기준값!$B$13,기준값!$B$14,기준값!$B$16),IF($A12>=기준값!$B$13,기준값!$B$16,기준값!$B$15)))))/기준값!$B$18 -> -11111.542 | D12: =$A12*기준값!$B$7-기준값!$B$8-(거리구간표!$D$7*(IF(기준값!$B$18<기준값!$B$11,기준값!$B$16,IF(기준값!$B$18>=기준값!$B$12,IF($A12>=기준값!$B$13,기준값!$B$14,기준값!$B$16),IF($A12>=기준값!$B$13,기준값!$B$16,기준값!$B$15)))))/기준값!$B$18 -> -12778.208 | E12: =$A12*기준값!$B$7-기준값!$B$8-(거리구간표!$D$8*(IF(기준값!$B$18<기준값!$B$11,기준값!$B$16,IF(기준값!$B$18>=기준값!$B$12,IF($A12>=기준값!$B$13,기준값!$B$14,기준값!$B$16),IF($A12>=기준값!$B$13,기준값!$B$16,기준값!$B$15)))))/기준값!$B$18 -> -16111.542 | F12: =$A12*기준값!$B$7-기준값!$B$8-(거리구간표!$D$9*(IF(기준값!$B$18<기준값!$B$11,기준값!$B$16,IF(기준값!$B$18>=기준값!$B$12,IF($A12>=기준값!$B$13,기준값!$B$14,기준값!$B$16),IF($A12>=기준값!$B$13,기준값!$B$16,기준값!$B$15)))))/기준값!$B$18 -> -17778.208 | G12: =$A12*기준값!$B$7-기준값!$B$8-(거리구간표!$D$10*(IF(기준값!$B$18<기준값!$B$11,기준값!$B$16,IF(기준값!$B$18>=기준값!$B$12,IF($A12>=기준값!$B$13,기준값!$B$14,기준값!$B$16),IF($A12>=기준값!$B$13,기준값!$B$16,기준값!$B$15)))))/기준값!$B$18 -> -19444.875 | H12: =$A12*기준값!$B$7-기준값!$B$8-(거리구간표!$D$11*(IF(기준값!$B$18<기준값!$B$11,기준값!$B$16,IF(기준값!$B$18>=기준값!$B$12,IF($A12>=기준값!$B$13,기준값!$B$14,기준값!$B$16),IF($A12>=기준값!$B$13,기준값!$B$16,기준값!$B$15)))))/기준값!$B$18 -> -21111.542 | I12: =$A12*기준값!$B$7-기준값!$B$8-(거리구간표!$D$12*(IF(기준값!$B$18<기준값!$B$11,기준값!$B$16,IF(기준값!$B$18>=기준값!$B$12,IF($A12>=기준값!$B$13,기준값!$B$14,기준값!$B$16),IF($A12>=기준값!$B$13,기준값!$B$16,기준값!$B$15)))))/기준값!$B$18 -> -22778.208 | J12: =$A12*기준값!$B$7-기준값!$B$8-(거리구간표!$D$13*(IF(기준값!$B$18<기준값!$B$11,기준값!$B$16,IF(기준값!$B$18>=기준값!$B$12,IF($A12>=기준값!$B$13,기준값!$B$14,기준값!$B$16),IF($A12>=기준값!$B$13,기준값!$B$16,기준값!$B$15)))))/기준값!$B$18 -> -24444.875
A13: 112 | B13: =$A13*기준값!$B$7-기준값!$B$8-(거리구간표!$D$5*(IF(기준값!$B$18<기준값!$B$11,기준값!$B$16,IF(기준값!$B$18>=기준값!$B$12,IF($A13>=기준값!$B$13,기준값!$B$14,기준값!$B$16),IF($A13>=기준값!$B$13,기준값!$B$16,기준값!$B$15)))))/기준값!$B$18 -> -5566 | C13: =$A13*기준값!$B$7-기준값!$B$8-(거리구간표!$D$6*(IF(기준값!$B$18<기준값!$B$11,기준값!$B$16,IF(기준값!$B$18>=기준값!$B$12,IF($A13>=기준값!$B$13,기준값!$B$14,기준값!$B$16),IF($A13>=기준값!$B$13,기준값!$B$16,기준값!$B$15)))))/기준값!$B$18 -> -7232.6667 | D13: =$A13*기준값!$B$7-기준값!$B$8-(거리구간표!$D$7*(IF(기준값!$B$18<기준값!$B$11,기준값!$B$16,IF(기준값!$B$18>=기준값!$B$12,IF($A13>=기준값!$B$13,기준값!$B$14,기준값!$B$16),IF($A13>=기준값!$B$13,기준값!$B$16,기준값!$B$15)))))/기준값!$B$18 -> -8899.3333 | E13: =$A13*기준값!$B$7-기준값!$B$8-(거리구간표!$D$8*(IF(기준값!$B$18<기준값!$B$11,기준값!$B$16,IF(기준값!$B$18>=기준값!$B$12,IF($A13>=기준값!$B$13,기준값!$B$14,기준값!$B$16),IF($A13>=기준값!$B$13,기준값!$B$16,기준값!$B$15)))))/기준값!$B$18 -> -12232.667 | F13: =$A13*기준값!$B$7-기준값!$B$8-(거리구간표!$D$9*(IF(기준값!$B$18<기준값!$B$11,기준값!$B$16,IF(기준값!$B$18>=기준값!$B$12,IF($A13>=기준값!$B$13,기준값!$B$14,기준값!$B$16),IF($A13>=기준값!$B$13,기준값!$B$16,기준값!$B$15)))))/기준값!$B$18 -> -13899.333 | G13: =$A13*기준값!$B$7-기준값!$B$8-(거리구간표!$D$10*(IF(기준값!$B$18<기준값!$B$11,기준값!$B$16,IF(기준값!$B$18>=기준값!$B$12,IF($A13>=기준값!$B$13,기준값!$B$14,기준값!$B$16),IF($A13>=기준값!$B$13,기준값!$B$16,기준값!$B$15)))))/기준값!$B$18 -> -15566 | H13: =$A13*기준값!$B$7-기준값!$B$8-(거리구간표!$D$11*(IF(기준값!$B$18<기준값!$B$11,기준값!$B$16,IF(기준값!$B$18>=기준값!$B$12,IF($A13>=기준값!$B$13,기준값!$B$14,기준값!$B$16),IF($A13>=기준값!$B$13,기준값!$B$16,기준값!$B$15)))))/기준값!$B$18 -> -17232.667 | I13: =$A13*기준값!$B$7-기준값!$B$8-(거리구간표!$D$12*(IF(기준값!$B$18<기준값!$B$11,기준값!$B$16,IF(기준값!$B$18>=기준값!$B$12,IF($A13>=기준값!$B$13,기준값!$B$14,기준값!$B$16),IF($A13>=기준값!$B$13,기준값!$B$16,기준값!$B$15)))))/기준값!$B$18 -> -18899.333 | J13: =$A13*기준값!$B$7-기준값!$B$8-(거리구간표!$D$13*(IF(기준값!$B$18<기준값!$B$11,기준값!$B$16,IF(기준값!$B$18>=기준값!$B$12,IF($A13>=기준값!$B$13,기준값!$B$14,기준값!$B$16),IF($A13>=기준값!$B$13,기준값!$B$16,기준값!$B$15)))))/기준값!$B$18 -> -20566
A14: 113 | B14: =$A14*기준값!$B$7-기준값!$B$8-(거리구간표!$D$5*(IF(기준값!$B$18<기준값!$B$11,기준값!$B$16,IF(기준값!$B$18>=기준값!$B$12,IF($A14>=기준값!$B$13,기준값!$B$14,기준값!$B$16),IF($A14>=기준값!$B$13,기준값!$B$16,기준값!$B$15)))))/기준값!$B$18 -> -1687.125 | C14: =$A14*기준값!$B$7-기준값!$B$8-(거리구간표!$D$6*(IF(기준값!$B$18<기준값!$B$11,기준값!$B$16,IF(기준값!$B$18>=기준값!$B$12,IF($A14>=기준값!$B$13,기준값!$B$14,기준값!$B$16),IF($A14>=기준값!$B$13,기준값!$B$16,기준값!$B$15)))))/기준값!$B$18 -> -3353.7917 | D14: =$A14*기준값!$B$7-기준값!$B$8-(거리구간표!$D$7*(IF(기준값!$B$18<기준값!$B$11,기준값!$B$16,IF(기준값!$B$18>=기준값!$B$12,IF($A14>=기준값!$B$13,기준값!$B$14,기준값!$B$16),IF($A14>=기준값!$B$13,기준값!$B$16,기준값!$B$15)))))/기준값!$B$18 -> -5020.4583 | E14: =$A14*기준값!$B$7-기준값!$B$8-(거리구간표!$D$8*(IF(기준값!$B$18<기준값!$B$11,기준값!$B$16,IF(기준값!$B$18>=기준값!$B$12,IF($A14>=기준값!$B$13,기준값!$B$14,기준값!$B$16),IF($A14>=기준값!$B$13,기준값!$B$16,기준값!$B$15)))))/기준값!$B$18 -> -8353.7917 | F14: =$A14*기준값!$B$7-기준값!$B$8-(거리구간표!$D$9*(IF(기준값!$B$18<기준값!$B$11,기준값!$B$16,IF(기준값!$B$18>=기준값!$B$12,IF($A14>=기준값!$B$13,기준값!$B$14,기준값!$B$16),IF($A14>=기준값!$B$13,기준값!$B$16,기준값!$B$15)))))/기준값!$B$18 -> -10020.458 | G14: =$A14*기준값!$B$7-기준값!$B$8-(거리구간표!$D$10*(IF(기준값!$B$18<기준값!$B$11,기준값!$B$16,IF(기준값!$B$18>=기준값!$B$12,IF($A14>=기준값!$B$13,기준값!$B$14,기준값!$B$16),IF($A14>=기준값!$B$13,기준값!$B$16,기준값!$B$15)))))/기준값!$B$18 -> -11687.125 | H14: =$A14*기준값!$B$7-기준값!$B$8-(거리구간표!$D$11*(IF(기준값!$B$18<기준값!$B$11,기준값!$B$16,IF(기준값!$B$18>=기준값!$B$12,IF($A14>=기준값!$B$13,기준값!$B$14,기준값!$B$16),IF($A14>=기준값!$B$13,기준값!$B$16,기준값!$B$15)))))/기준값!$B$18 -> -13353.792 | I14: =$A14*기준값!$B$7-기준값!$B$8-(거리구간표!$D$12*(IF(기준값!$B$18<기준값!$B$11,기준값!$B$16,IF(기준값!$B$18>=기준값!$B$12,IF($A14>=기준값!$B$13,기준값!$B$14,기준값!$B$16),IF($A14>=기준값!$B$13,기준값!$B$16,기준값!$B$15)))))/기준값!$B$18 -> -15020.458 | J14: =$A14*기준값!$B$7-기준값!$B$8-(거리구간표!$D$13*(IF(기준값!$B$18<기준값!$B$11,기준값!$B$16,IF(기준값!$B$18>=기준값!$B$12,IF($A14>=기준값!$B$13,기준값!$B$14,기준값!$B$16),IF($A14>=기준값!$B$13,기준값!$B$16,기준값!$B$15)))))/기준값!$B$18 -> -16687.125
A15: 114 | B15: =$A15*기준값!$B$7-기준값!$B$8-(거리구간표!$D$5*(IF(기준값!$B$18<기준값!$B$11,기준값!$B$16,IF(기준값!$B$18>=기준값!$B$12,IF($A15>=기준값!$B$13,기준값!$B$14,기준값!$B$16),IF($A15>=기준값!$B$13,기준값!$B$16,기준값!$B$15)))))/기준값!$B$18 -> 2191.75 | C15: =$A15*기준값!$B$7-기준값!$B$8-(거리구간표!$D$6*(IF(기준값!$B$18<기준값!$B$11,기준값!$B$16,IF(기준값!$B$18>=기준값!$B$12,IF($A15>=기준값!$B$13,기준값!$B$14,기준값!$B$16),IF($A15>=기준값!$B$13,기준값!$B$16,기준값!$B$15)))))/기준값!$B$18 -> 525.08333 | D15: =$A15*기준값!$B$7-기준값!$B$8-(거리구간표!$D$7*(IF(기준값!$B$18<기준값!$B$11,기준값!$B$16,IF(기준값!$B$18>=기준값!$B$12,IF($A15>=기준값!$B$13,기준값!$B$14,기준값!$B$16),IF($A15>=기준값!$B$13,기준값!$B$16,기준값!$B$15)))))/기준값!$B$18 -> -1141.5833 | E15: =$A15*기준값!$B$7-기준값!$B$8-(거리구간표!$D$8*(IF(기준값!$B$18<기준값!$B$11,기준값!$B$16,IF(기준값!$B$18>=기준값!$B$12,IF($A15>=기준값!$B$13,기준값!$B$14,기준값!$B$16),IF($A15>=기준값!$B$13,기준값!$B$16,기준값!$B$15)))))/기준값!$B$18 -> -4474.9167 | F15: =$A15*기준값!$B$7-기준값!$B$8-(거리구간표!$D$9*(IF(기준값!$B$18<기준값!$B$11,기준값!$B$16,IF(기준값!$B$18>=기준값!$B$12,IF($A15>=기준값!$B$13,기준값!$B$14,기준값!$B$16),IF($A15>=기준값!$B$13,기준값!$B$16,기준값!$B$15)))))/기준값!$B$18 -> -6141.5833 | G15: =$A15*기준값!$B$7-기준값!$B$8-(거리구간표!$D$10*(IF(기준값!$B$18<기준값!$B$11,기준값!$B$16,IF(기준값!$B$18>=기준값!$B$12,IF($A15>=기준값!$B$13,기준값!$B$14,기준값!$B$16),IF($A15>=기준값!$B$13,기준값!$B$16,기준값!$B$15)))))/기준값!$B$18 -> -7808.25 | H15: =$A15*기준값!$B$7-기준값!$B$8-(거리구간표!$D$11*(IF(기준값!$B$18<기준값!$B$11,기준값!$B$16,IF(기준값!$B$18>=기준값!$B$12,IF($A15>=기준값!$B$13,기준값!$B$14,기준값!$B$16),IF($A15>=기준값!$B$13,기준값!$B$16,기준값!$B$15)))))/기준값!$B$18 -> -9474.9167 | I15: =$A15*기준값!$B$7-기준값!$B$8-(거리구간표!$D$12*(IF(기준값!$B$18<기준값!$B$11,기준값!$B$16,IF(기준값!$B$18>=기준값!$B$12,IF($A15>=기준값!$B$13,기준값!$B$14,기준값!$B$16),IF($A15>=기준값!$B$13,기준값!$B$16,기준값!$B$15)))))/기준값!$B$18 -> -11141.583 | J15: =$A15*기준값!$B$7-기준값!$B$8-(거리구간표!$D$13*(IF(기준값!$B$18<기준값!$B$11,기준값!$B$16,IF(기준값!$B$18>=기준값!$B$12,IF($A15>=기준값!$B$13,기준값!$B$14,기준값!$B$16),IF($A15>=기준값!$B$13,기준값!$B$16,기준값!$B$15)))))/기준값!$B$18 -> -12808.25
A16: 115 | B16: =$A16*기준값!$B$7-기준값!$B$8-(거리구간표!$D$5*(IF(기준값!$B$18<기준값!$B$11,기준값!$B$16,IF(기준값!$B$18>=기준값!$B$12,IF($A16>=기준값!$B$13,기준값!$B$14,기준값!$B$16),IF($A16>=기준값!$B$13,기준값!$B$16,기준값!$B$15)))))/기준값!$B$18 -> 6070.625 | C16: =$A16*기준값!$B$7-기준값!$B$8-(거리구간표!$D$6*(IF(기준값!$B$18<기준값!$B$11,기준값!$B$16,IF(기준값!$B$18>=기준값!$B$12,IF($A16>=기준값!$B$13,기준값!$B$14,기준값!$B$16),IF($A16>=기준값!$B$13,기준값!$B$16,기준값!$B$15)))))/기준값!$B$18 -> 4403.9583 | D16: =$A16*기준값!$B$7-기준값!$B$8-(거리구간표!$D$7*(IF(기준값!$B$18<기준값!$B$11,기준값!$B$16,IF(기준값!$B$18>=기준값!$B$12,IF($A16>=기준값!$B$13,기준값!$B$14,기준값!$B$16),IF($A16>=기준값!$B$13,기준값!$B$16,기준값!$B$15)))))/기준값!$B$18 -> 2737.2917 | E16: =$A16*기준값!$B$7-기준값!$B$8-(거리구간표!$D$8*(IF(기준값!$B$18<기준값!$B$11,기준값!$B$16,IF(기준값!$B$18>=기준값!$B$12,IF($A16>=기준값!$B$13,기준값!$B$14,기준값!$B$16),IF($A16>=기준값!$B$13,기준값!$B$16,기준값!$B$15)))))/기준값!$B$18 -> -596.04167 | F16: =$A16*기준값!$B$7-기준값!$B$8-(거리구간표!$D$9*(IF(기준값!$B$18<기준값!$B$11,기준값!$B$16,IF(기준값!$B$18>=기준값!$B$12,IF($A16>=기준값!$B$13,기준값!$B$14,기준값!$B$16),IF($A16>=기준값!$B$13,기준값!$B$16,기준값!$B$15)))))/기준값!$B$18 -> -2262.7083 | G16: =$A16*기준값!$B$7-기준값!$B$8-(거리구간표!$D$10*(IF(기준값!$B$18<기준값!$B$11,기준값!$B$16,IF(기준값!$B$18>=기준값!$B$12,IF($A16>=기준값!$B$13,기준값!$B$14,기준값!$B$16),IF($A16>=기준값!$B$13,기준값!$B$16,기준값!$B$15)))))/기준값!$B$18 -> -3929.375 | H16: =$A16*기준값!$B$7-기준값!$B$8-(거리구간표!$D$11*(IF(기준값!$B$18<기준값!$B$11,기준값!$B$16,IF(기준값!$B$18>=기준값!$B$12,IF($A16>=기준값!$B$13,기준값!$B$14,기준값!$B$16),IF($A16>=기준값!$B$13,기준값!$B$16,기준값!$B$15)))))/기준값!$B$18 -> -5596.0417 | I16: =$A16*기준값!$B$7-기준값!$B$8-(거리구간표!$D$12*(IF(기준값!$B$18<기준값!$B$11,기준값!$B$16,IF(기준값!$B$18>=기준값!$B$12,IF($A16>=기준값!$B$13,기준값!$B$14,기준값!$B$16),IF($A16>=기준값!$B$13,기준값!$B$16,기준값!$B$15)))))/기준값!$B$18 -> -7262.7083 | J16: =$A16*기준값!$B$7-기준값!$B$8-(거리구간표!$D$13*(IF(기준값!$B$18<기준값!$B$11,기준값!$B$16,IF(기준값!$B$18>=기준값!$B$12,IF($A16>=기준값!$B$13,기준값!$B$14,기준값!$B$16),IF($A16>=기준값!$B$13,기준값!$B$16,기준값!$B$15)))))/기준값!$B$18 -> -8929.375
A17: 116 | B17: =$A17*기준값!$B$7-기준값!$B$8-(거리구간표!$D$5*(IF(기준값!$B$18<기준값!$B$11,기준값!$B$16,IF(기준값!$B$18>=기준값!$B$12,IF($A17>=기준값!$B$13,기준값!$B$14,기준값!$B$16),IF($A17>=기준값!$B$13,기준값!$B$16,기준값!$B$15)))))/기준값!$B$18 -> 9949.5 | C17: =$A17*기준값!$B$7-기준값!$B$8-(거리구간표!$D$6*(IF(기준값!$B$18<기준값!$B$11,기준값!$B$16,IF(기준값!$B$18>=기준값!$B$12,IF($A17>=기준값!$B$13,기준값!$B$14,기준값!$B$16),IF($A17>=기준값!$B$13,기준값!$B$16,기준값!$B$15)))))/기준값!$B$18 -> 8282.8333 | D17: =$A17*기준값!$B$7-기준값!$B$8-(거리구간표!$D$7*(IF(기준값!$B$18<기준값!$B$11,기준값!$B$16,IF(기준값!$B$18>=기준값!$B$12,IF($A17>=기준값!$B$13,기준값!$B$14,기준값!$B$16),IF($A17>=기준값!$B$13,기준값!$B$16,기준값!$B$15)))))/기준값!$B$18 -> 6616.1667 | E17: =$A17*기준값!$B$7-기준값!$B$8-(거리구간표!$D$8*(IF(기준값!$B$18<기준값!$B$11,기준값!$B$16,IF(기준값!$B$18>=기준값!$B$12,IF($A17>=기준값!$B$13,기준값!$B$14,기준값!$B$16),IF($A17>=기준값!$B$13,기준값!$B$16,기준값!$B$15)))))/기준값!$B$18 -> 3282.8333 | F17: =$A17*기준값!$B$7-기준값!$B$8-(거리구간표!$D$9*(IF(기준값!$B$18<기준값!$B$11,기준값!$B$16,IF(기준값!$B$18>=기준값!$B$12,IF($A17>=기준값!$B$13,기준값!$B$14,기준값!$B$16),IF($A17>=기준값!$B$13,기준값!$B$16,기준값!$B$15)))))/기준값!$B$18 -> 1616.1667 | G17: =$A17*기준값!$B$7-기준값!$B$8-(거리구간표!$D$10*(IF(기준값!$B$18<기준값!$B$11,기준값!$B$16,IF(기준값!$B$18>=기준값!$B$12,IF($A17>=기준값!$B$13,기준값!$B$14,기준값!$B$16),IF($A17>=기준값!$B$13,기준값!$B$16,기준값!$B$15)))))/기준값!$B$18 -> -50.5 | H17: =$A17*기준값!$B$7-기준값!$B$8-(거리구간표!$D$11*(IF(기준값!$B$18<기준값!$B$11,기준값!$B$16,IF(기준값!$B$18>=기준값!$B$12,IF($A17>=기준값!$B$13,기준값!$B$14,기준값!$B$16),IF($A17>=기준값!$B$13,기준값!$B$16,기준값!$B$15)))))/기준값!$B$18 -> -1717.1667 | I17: =$A17*기준값!$B$7-기준값!$B$8-(거리구간표!$D$12*(IF(기준값!$B$18<기준값!$B$11,기준값!$B$16,IF(기준값!$B$18>=기준값!$B$12,IF($A17>=기준값!$B$13,기준값!$B$14,기준값!$B$16),IF($A17>=기준값!$B$13,기준값!$B$16,기준값!$B$15)))))/기준값!$B$18 -> -3383.8333 | J17: =$A17*기준값!$B$7-기준값!$B$8-(거리구간표!$D$13*(IF(기준값!$B$18<기준값!$B$11,기준값!$B$16,IF(기준값!$B$18>=기준값!$B$12,IF($A17>=기준값!$B$13,기준값!$B$14,기준값!$B$16),IF($A17>=기준값!$B$13,기준값!$B$16,기준값!$B$15)))))/기준값!$B$18 -> -5050.5
... A26: 125 | B26: =$A26*기준값!$B$7-기준값!$B$8-(거리구간표!$D$5*(IF(기준값!$B$18<기준값!$B$11,기준값!$B$16,IF(기준값!$B$18>=기준값!$B$12,IF($A26>=기준값!$B$13,기준값!$B$14,기준값!$B$16),IF($A26>=기준값!$B$13,기준값!$B$16,기준값!$B$15)))))/기준값!$B$18 -> 44859.375 | C26: =$A26*기준값!$B$7-기준값!$B$8-(거리구간표!$D$6*(IF(기준값!$B$18<기준값!$B$11,기준값!$B$16,IF(기준값!$B$18>=기준값!$B$12,IF($A26>=기준값!$B$13,기준값!$B$14,기준값!$B$16),IF($A26>=기준값!$B$13,기준값!$B$16,기준값!$B$15)))))/기준값!$B$18 -> 43192.708 | D26: =$A26*기준값!$B$7-기준값!$B$8-(거리구간표!$D$7*(IF(기준값!$B$18<기준값!$B$11,기준값!$B$16,IF(기준값!$B$18>=기준값!$B$12,IF($A26>=기준값!$B$13,기준값!$B$14,기준값!$B$16),IF($A26>=기준값!$B$13,기준값!$B$16,기준값!$B$15)))))/기준값!$B$18 -> 41526.042 | E26: =$A26*기준값!$B$7-기준값!$B$8-(거리구간표!$D$8*(IF(기준값!$B$18<기준값!$B$11,기준값!$B$16,IF(기준값!$B$18>=기준값!$B$12,IF($A26>=기준값!$B$13,기준값!$B$14,기준값!$B$16),IF($A26>=기준값!$B$13,기준값!$B$16,기준값!$B$15)))))/기준값!$B$18 -> 38192.708 | F26: =$A26*기준값!$B$7-기준값!$B$8-(거리구간표!$D$9*(IF(기준값!$B$18<기준값!$B$11,기준값!$B$16,IF(기준값!$B$18>=기준값!$B$12,IF($A26>=기준값!$B$13,기준값!$B$14,기준값!$B$16),IF($A26>=기준값!$B$13,기준값!$B$16,기준값!$B$15)))))/기준값!$B$18 -> 36526.042 | G26: =$A26*기준값!$B$7-기준값!$B$8-(거리구간표!$D$10*(IF(기준값!$B$18<기준값!$B$11,기준값!$B$16,IF(기준값!$B$18>=기준값!$B$12,IF($A26>=기준값!$B$13,기준값!$B$14,기준값!$B$16),IF($A26>=기준값!$B$13,기준값!$B$16,기준값!$B$15)))))/기준값!$B$18 -> 34859.375 | H26: =$A26*기준값!$B$7-기준값!$B$8-(거리구간표!$D$11*(IF(기준값!$B$18<기준값!$B$11,기준값!$B$16,IF(기준값!$B$18>=기준값!$B$12,IF($A26>=기준값!$B$13,기준값!$B$14,기준값!$B$16),IF($A26>=기준값!$B$13,기준값!$B$16,기준값!$B$15)))))/기준값!$B$18 -> 33192.708 | I26: =$A26*기준값!$B$7-기준값!$B$8-(거리구간표!$D$12*(IF(기준값!$B$18<기준값!$B$11,기준값!$B$16,IF(기준값!$B$18>=기준값!$B$12,IF($A26>=기준값!$B$13,기준값!$B$14,기준값!$B$16),IF($A26>=기준값!$B$13,기준값!$B$16,기준값!$B$15)))))/기준값!$B$18 -> 31526.042 | J26: =$A26*기준값!$B$7-기준값!$B$8-(거리구간표!$D$13*(IF(기준값!$B$18<기준값!$B$11,기준값!$B$16,IF(기준값!$B$18>=기준값!$B$12,IF($A26>=기준값!$B$13,기준값!$B$14,기준값!$B$16),IF($A26>=기준값!$B$13,기준값!$B$16,기준값!$B$15)))))/기준값!$B$18 -> 29859.375
A29: ="시나리오 B · 두수 "&기준값!$B$19&"두" -> 시나리오 B · 두수 65두
A30: 평균체중\거리구간 | B30: =거리구간표!$A$5 -> ~40km | C30: =거리구간표!$A$6 -> 41~80km | D30: =거리구간표!$A$7 -> 81~120km | E30: =거리구간표!$A$8 -> 121~150km | F30: =거리구간표!$A$9 -> 151~180km | G30: =거리구간표!$A$10 -> 181~220km | H30: =거리구간표!$A$11 -> 221~260km | I30: =거리구간표!$A$12 -> 261~300km | J30: =거리구간표!$A$13 -> 301~340km
A31: 105 | B31: =$A31*기준값!$B$7-기준값!$B$8-(거리구간표!$D$5*(IF(기준값!$B$19<기준값!$B$11,기준값!$B$16,IF(기준값!$B$19>=기준값!$B$12,IF($A31>=기준값!$B$13,기준값!$B$14,기준값!$B$16),IF($A31>=기준값!$B$13,기준값!$B$16,기준값!$B$15)))))/기준값!$B$19 -> -27333.51 | C31: =$A31*기준값!$B$7-기준값!$B$8-(거리구간표!$D$6*(IF(기준값!$B$19<기준값!$B$11,기준값!$B$16,IF(기준값!$B$19>=기준값!$B$12,IF($A31>=기준값!$B$13,기준값!$B$14,기준값!$B$16),IF($A31>=기준값!$B$13,기준값!$B$16,기준값!$B$15)))))/기준값!$B$19 -> -28102.74 | D31: =$A31*기준값!$B$7-기준값!$B$8-(거리구간표!$D$7*(IF(기준값!$B$19<기준값!$B$11,기준값!$B$16,IF(기준값!$B$19>=기준값!$B$12,IF($A31>=기준값!$B$13,기준값!$B$14,기준값!$B$16),IF($A31>=기준값!$B$13,기준값!$B$16,기준값!$B$15)))))/기준값!$B$19 -> -28871.971 | E31: =$A31*기준값!$B$7-기준값!$B$8-(거리구간표!$D$8*(IF(기준값!$B$19<기준값!$B$11,기준값!$B$16,IF(기준값!$B$19>=기준값!$B$12,IF($A31>=기준값!$B$13,기준값!$B$14,기준값!$B$16),IF($A31>=기준값!$B$13,기준값!$B$16,기준값!$B$15)))))/기준값!$B$19 -> -30410.433 | F31: =$A31*기준값!$B$7-기준값!$B$8-(거리구간표!$D$9*(IF(기준값!$B$19<기준값!$B$11,기준값!$B$16,IF(기준값!$B$19>=기준값!$B$12,IF($A31>=기준값!$B$13,기준값!$B$14,기준값!$B$16),IF($A31>=기준값!$B$13,기준값!$B$16,기준값!$B$15)))))/기준값!$B$19 -> -31179.663 | G31: =$A31*기준값!$B$7-기준값!$B$8-(거리구간표!$D$10*(IF(기준값!$B$19<기준값!$B$11,기준값!$B$16,IF(기준값!$B$19>=기준값!$B$12,IF($A31>=기준값!$B$13,기준값!$B$14,기준값!$B$16),IF($A31>=기준값!$B$13,기준값!$B$16,기준값!$B$15)))))/기준값!$B$19 -> -31948.894 | H31: =$A31*기준값!$B$7-기준값!$B$8-(거리구간표!$D$11*(IF(기준값!$B$19<기준값!$B$11,기준값!$B$16,IF(기준값!$B$19>=기준값!$B$12,IF($A31>=기준값!$B$13,기준값!$B$14,기준값!$B$16),IF($A31>=기준값!$B$13,기준값!$B$16,기준값!$B$15)))))/기준값!$B$19 -> -32718.125 | I31: =$A31*기준값!$B$7-기준값!$B$8-(거리구간표!$D$12*(IF(기준값!$B$19<기준값!$B$11,기준값!$B$16,IF(기준값!$B$19>=기준값!$B$12,IF($A31>=기준값!$B$13,기준값!$B$14,기준값!$B$16),IF($A31>=기준값!$B$13,기준값!$B$16,기준값!$B$15)))))/기준값!$B$19 -> -33487.356 | J31: =$A31*기준값!$B$7-기준값!$B$8-(거리구간표!$D$13*(IF(기준값!$B$19<기준값!$B$11,기준값!$B$16,IF(기준값!$B$19>=기준값!$B$12,IF($A31>=기준값!$B$13,기준값!$B$14,기준값!$B$16),IF($A31>=기준값!$B$13,기준값!$B$16,기준값!$B$15)))))/기준값!$B$19 -> -34256.587
A32: 106 | B32: =$A32*기준값!$B$7-기준값!$B$8-(거리구간표!$D$5*(IF(기준값!$B$19<기준값!$B$11,기준값!$B$16,IF(기준값!$B$19>=기준값!$B$12,IF($A32>=기준값!$B$13,기준값!$B$14,기준값!$B$16),IF($A32>=기준값!$B$13,기준값!$B$16,기준값!$B$15)))))/기준값!$B$19 -> -23454.635 | C32: =$A32*기준값!$B$7-기준값!$B$8-(거리구간표!$D$6*(IF(기준값!$B$19<기준값!$B$11,기준값!$B$16,IF(기준값!$B$19>=기준값!$B$12,IF($A32>=기준값!$B$13,기준값!$B$14,기준값!$B$16),IF($A32>=기준값!$B$13,기준값!$B$16,기준값!$B$15)))))/기준값!$B$19 -> -24223.865 | D32: =$A32*기준값!$B$7-기준값!$B$8-(거리구간표!$D$7*(IF(기준값!$B$19<기준값!$B$11,기준값!$B$16,IF(기준값!$B$19>=기준값!$B$12,IF($A32>=기준값!$B$13,기준값!$B$14,기준값!$B$16),IF($A32>=기준값!$B$13,기준값!$B$16,기준값!$B$15)))))/기준값!$B$19 -> -24993.096 | E32: =$A32*기준값!$B$7-기준값!$B$8-(거리구간표!$D$8*(IF(기준값!$B$19<기준값!$B$11,기준값!$B$16,IF(기준값!$B$19>=기준값!$B$12,IF($A32>=기준값!$B$13,기준값!$B$14,기준값!$B$16),IF($A32>=기준값!$B$13,기준값!$B$16,기준값!$B$15)))))/기준값!$B$19 -> -26531.558 | F32: =$A32*기준값!$B$7-기준값!$B$8-(거리구간표!$D$9*(IF(기준값!$B$19<기준값!$B$11,기준값!$B$16,IF(기준값!$B$19>=기준값!$B$12,IF($A32>=기준값!$B$13,기준값!$B$14,기준값!$B$16),IF($A32>=기준값!$B$13,기준값!$B$16,기준값!$B$15)))))/기준값!$B$19 -> -27300.788 | G32: =$A32*기준값!$B$7-기준값!$B$8-(거리구간표!$D$10*(IF(기준값!$B$19<기준값!$B$11,기준값!$B$16,IF(기준값!$B$19>=기준값!$B$12,IF($A32>=기준값!$B$13,기준값!$B$14,기준값!$B$16),IF($A32>=기준값!$B$13,기준값!$B$16,기준값!$B$15)))))/기준값!$B$19 -> -28070.019 | H32: =$A32*기준값!$B$7-기준값!$B$8-(거리구간표!$D$11*(IF(기준값!$B$19<기준값!$B$11,기준값!$B$16,IF(기준값!$B$19>=기준값!$B$12,IF($A32>=기준값!$B$13,기준값!$B$14,기준값!$B$16),IF($A32>=기준값!$B$13,기준값!$B$16,기준값!$B$15)))))/기준값!$B$19 -> -28839.25 | I32: =$A32*기준값!$B$7-기준값!$B$8-(거리구간표!$D$12*(IF(기준값!$B$19<기준값!$B$11,기준값!$B$16,IF(기준값!$B$19>=기준값!$B$12,IF($A32>=기준값!$B$13,기준값!$B$14,기준값!$B$16),IF($A32>=기준값!$B$13,기준값!$B$16,기준값!$B$15)))))/기준값!$B$19 -> -29608.481 | J32: =$A32*기준값!$B$7-기준값!$B$8-(거리구간표!$D$13*(IF(기준값!$B$19<기준값!$B$11,기준값!$B$16,IF(기준값!$B$19>=기준값!$B$12,IF($A32>=기준값!$B$13,기준값!$B$14,기준값!$B$16),IF($A32>=기준값!$B$13,기준값!$B$16,기준값!$B$15)))))/기준값!$B$19 -> -30377.712
A33: 107 | B33: =$A33*기준값!$B$7-기준값!$B$8-(거리구간표!$D$5*(IF(기준값!$B$19<기준값!$B$11,기준값!$B$16,IF(기준값!$B$19>=기준값!$B$12,IF($A33>=기준값!$B$13,기준값!$B$14,기준값!$B$16),IF($A33>=기준값!$B$13,기준값!$B$16,기준값!$B$15)))))/기준값!$B$19 -> -19575.76 | C33: =$A33*기준값!$B$7-기준값!$B$8-(거리구간표!$D$6*(IF(기준값!$B$19<기준값!$B$11,기준값!$B$16,IF(기준값!$B$19>=기준값!$B$12,IF($A33>=기준값!$B$13,기준값!$B$14,기준값!$B$16),IF($A33>=기준값!$B$13,기준값!$B$16,기준값!$B$15)))))/기준값!$B$19 -> -20344.99 | D33: =$A33*기준값!$B$7-기준값!$B$8-(거리구간표!$D$7*(IF(기준값!$B$19<기준값!$B$11,기준값!$B$16,IF(기준값!$B$19>=기준값!$B$12,IF($A33>=기준값!$B$13,기준값!$B$14,기준값!$B$16),IF($A33>=기준값!$B$13,기준값!$B$16,기준값!$B$15)))))/기준값!$B$19 -> -21114.221 | E33: =$A33*기준값!$B$7-기준값!$B$8-(거리구간표!$D$8*(IF(기준값!$B$19<기준값!$B$11,기준값!$B$16,IF(기준값!$B$19>=기준값!$B$12,IF($A33>=기준값!$B$13,기준값!$B$14,기준값!$B$16),IF($A33>=기준값!$B$13,기준값!$B$16,기준값!$B$15)))))/기준값!$B$19 -> -22652.683 | F33: =$A33*기준값!$B$7-기준값!$B$8-(거리구간표!$D$9*(IF(기준값!$B$19<기준값!$B$11,기준값!$B$16,IF(기준값!$B$19>=기준값!$B$12,IF($A33>=기준값!$B$13,기준값!$B$14,기준값!$B$16),IF($A33>=기준값!$B$13,기준값!$B$16,기준값!$B$15)))))/기준값!$B$19 -> -23421.913 | G33: =$A33*기준값!$B$7-기준값!$B$8-(거리구간표!$D$10*(IF(기준값!$B$19<기준값!$B$11,기준값!$B$16,IF(기준값!$B$19>=기준값!$B$12,IF($A33>=기준값!$B$13,기준값!$B$14,기준값!$B$16),IF($A33>=기준값!$B$13,기준값!$B$16,기준값!$B$15)))))/기준값!$B$19 -> -24191.144 | H33: =$A33*기준값!$B$7-기준값!$B$8-(거리구간표!$D$11*(IF(기준값!$B$19<기준값!$B$11,기준값!$B$16,IF(기준값!$B$19>=기준값!$B$12,IF($A33>=기준값!$B$13,기준값!$B$14,기준값!$B$16),IF($A33>=기준값!$B$13,기준값!$B$16,기준값!$B$15)))))/기준값!$B$19 -> -24960.375 | I33: =$A33*기준값!$B$7-기준값!$B$8-(거리구간표!$D$12*(IF(기준값!$B$19<기준값!$B$11,기준값!$B$16,IF(기준값!$B$19>=기준값!$B$12,IF($A33>=기준값!$B$13,기준값!$B$14,기준값!$B$16),IF($A33>=기준값!$B$13,기준값!$B$16,기준값!$B$15)))))/기준값!$B$19 -> -25729.606 | J33: =$A33*기준값!$B$7-기준값!$B$8-(거리구간표!$D$13*(IF(기준값!$B$19<기준값!$B$11,기준값!$B$16,IF(기준값!$B$19>=기준값!$B$12,IF($A33>=기준값!$B$13,기준값!$B$14,기준값!$B$16),IF($A33>=기준값!$B$13,기준값!$B$16,기준값!$B$15)))))/기준값!$B$19 -> -26498.837
A34: 108 | B34: =$A34*기준값!$B$7-기준값!$B$8-(거리구간표!$D$5*(IF(기준값!$B$19<기준값!$B$11,기준값!$B$16,IF(기준값!$B$19>=기준값!$B$12,IF($A34>=기준값!$B$13,기준값!$B$14,기준값!$B$16),IF($A34>=기준값!$B$13,기준값!$B$16,기준값!$B$15)))))/기준값!$B$19 -> -15696.885 | C34: =$A34*기준값!$B$7-기준값!$B$8-(거리구간표!$D$6*(IF(기준값!$B$19<기준값!$B$11,기준값!$B$16,IF(기준값!$B$19>=기준값!$B$12,IF($A34>=기준값!$B$13,기준값!$B$14,기준값!$B$16),IF($A34>=기준값!$B$13,기준값!$B$16,기준값!$B$15)))))/기준값!$B$19 -> -16466.115 | D34: =$A34*기준값!$B$7-기준값!$B$8-(거리구간표!$D$7*(IF(기준값!$B$19<기준값!$B$11,기준값!$B$16,IF(기준값!$B$19>=기준값!$B$12,IF($A34>=기준값!$B$13,기준값!$B$14,기준값!$B$16),IF($A34>=기준값!$B$13,기준값!$B$16,기준값!$B$15)))))/기준값!$B$19 -> -17235.346 | E34: =$A34*기준값!$B$7-기준값!$B$8-(거리구간표!$D$8*(IF(기준값!$B$19<기준값!$B$11,기준값!$B$16,IF(기준값!$B$19>=기준값!$B$12,IF($A34>=기준값!$B$13,기준값!$B$14,기준값!$B$16),IF($A34>=기준값!$B$13,기준값!$B$16,기준값!$B$15)))))/기준값!$B$19 -> -18773.808 | F34: =$A34*기준값!$B$7-기준값!$B$8-(거리구간표!$D$9*(IF(기준값!$B$19<기준값!$B$11,기준값!$B$16,IF(기준값!$B$19>=기준값!$B$12,IF($A34>=기준값!$B$13,기준값!$B$14,기준값!$B$16),IF($A34>=기준값!$B$13,기준값!$B$16,기준값!$B$15)))))/기준값!$B$19 -> -19543.038 | G34: =$A34*기준값!$B$7-기준값!$B$8-(거리구간표!$D$10*(IF(기준값!$B$19<기준값!$B$11,기준값!$B$16,IF(기준값!$B$19>=기준값!$B$12,IF($A34>=기준값!$B$13,기준값!$B$14,기준값!$B$16),IF($A34>=기준값!$B$13,기준값!$B$16,기준값!$B$15)))))/기준값!$B$19 -> -20312.269 | H34: =$A34*기준값!$B$7-기준값!$B$8-(거리구간표!$D$11*(IF(기준값!$B$19<기준값!$B$11,기준값!$B$16,IF(기준값!$B$19>=기준값!$B$12,IF($A34>=기준값!$B$13,기준값!$B$14,기준값!$B$16),IF($A34>=기준값!$B$13,기준값!$B$16,기준값!$B$15)))))/기준값!$B$19 -> -21081.5 | I34: =$A34*기준값!$B$7-기준값!$B$8-(거리구간표!$D$12*(IF(기준값!$B$19<기준값!$B$11,기준값!$B$16,IF(기준값!$B$19>=기준값!$B$12,IF($A34>=기준값!$B$13,기준값!$B$14,기준값!$B$16),IF($A34>=기준값!$B$13,기준값!$B$16,기준값!$B$15)))))/기준값!$B$19 -> -21850.731 | J34: =$A34*기준값!$B$7-기준값!$B$8-(거리구간표!$D$13*(IF(기준값!$B$19<기준값!$B$11,기준값!$B$16,IF(기준값!$B$19>=기준값!$B$12,IF($A34>=기준값!$B$13,기준값!$B$14,기준값!$B$16),IF($A34>=기준값!$B$13,기준값!$B$16,기준값!$B$15)))))/기준값!$B$19 -> -22619.962
A35: 109 | B35: =$A35*기준값!$B$7-기준값!$B$8-(거리구간표!$D$5*(IF(기준값!$B$19<기준값!$B$11,기준값!$B$16,IF(기준값!$B$19>=기준값!$B$12,IF($A35>=기준값!$B$13,기준값!$B$14,기준값!$B$16),IF($A35>=기준값!$B$13,기준값!$B$16,기준값!$B$15)))))/기준값!$B$19 -> -11818.01 | C35: =$A35*기준값!$B$7-기준값!$B$8-(거리구간표!$D$6*(IF(기준값!$B$19<기준값!$B$11,기준값!$B$16,IF(기준값!$B$19>=기준값!$B$12,IF($A35>=기준값!$B$13,기준값!$B$14,기준값!$B$16),IF($A35>=기준값!$B$13,기준값!$B$16,기준값!$B$15)))))/기준값!$B$19 -> -12587.24 | D35: =$A35*기준값!$B$7-기준값!$B$8-(거리구간표!$D$7*(IF(기준값!$B$19<기준값!$B$11,기준값!$B$16,IF(기준값!$B$19>=기준값!$B$12,IF($A35>=기준값!$B$13,기준값!$B$14,기준값!$B$16),IF($A35>=기준값!$B$13,기준값!$B$16,기준값!$B$15)))))/기준값!$B$19 -> -13356.471 | E35: =$A35*기준값!$B$7-기준값!$B$8-(거리구간표!$D$8*(IF(기준값!$B$19<기준값!$B$11,기준값!$B$16,IF(기준값!$B$19>=기준값!$B$12,IF($A35>=기준값!$B$13,기준값!$B$14,기준값!$B$16),IF($A35>=기준값!$B$13,기준값!$B$16,기준값!$B$15)))))/기준값!$B$19 -> -14894.933 | F35: =$A35*기준값!$B$7-기준값!$B$8-(거리구간표!$D$9*(IF(기준값!$B$19<기준값!$B$11,기준값!$B$16,IF(기준값!$B$19>=기준값!$B$12,IF($A35>=기준값!$B$13,기준값!$B$14,기준값!$B$16),IF($A35>=기준값!$B$13,기준값!$B$16,기준값!$B$15)))))/기준값!$B$19 -> -15664.163 | G35: =$A35*기준값!$B$7-기준값!$B$8-(거리구간표!$D$10*(IF(기준값!$B$19<기준값!$B$11,기준값!$B$16,IF(기준값!$B$19>=기준값!$B$12,IF($A35>=기준값!$B$13,기준값!$B$14,기준값!$B$16),IF($A35>=기준값!$B$13,기준값!$B$16,기준값!$B$15)))))/기준값!$B$19 -> -16433.394 | H35: =$A35*기준값!$B$7-기준값!$B$8-(거리구간표!$D$11*(IF(기준값!$B$19<기준값!$B$11,기준값!$B$16,IF(기준값!$B$19>=기준값!$B$12,IF($A35>=기준값!$B$13,기준값!$B$14,기준값!$B$16),IF($A35>=기준값!$B$13,기준값!$B$16,기준값!$B$15)))))/기준값!$B$19 -> -17202.625 | I35: =$A35*기준값!$B$7-기준값!$B$8-(거리구간표!$D$12*(IF(기준값!$B$19<기준값!$B$11,기준값!$B$16,IF(기준값!$B$19>=기준값!$B$12,IF($A35>=기준값!$B$13,기준값!$B$14,기준값!$B$16),IF($A35>=기준값!$B$13,기준값!$B$16,기준값!$B$15)))))/기준값!$B$19 -> -17971.856 | J35: =$A35*기준값!$B$7-기준값!$B$8-(거리구간표!$D$13*(IF(기준값!$B$19<기준값!$B$11,기준값!$B$16,IF(기준값!$B$19>=기준값!$B$12,IF($A35>=기준값!$B$13,기준값!$B$14,기준값!$B$16),IF($A35>=기준값!$B$13,기준값!$B$16,기준값!$B$15)))))/기준값!$B$19 -> -18741.087
A36: 110 | B36: =$A36*기준값!$B$7-기준값!$B$8-(거리구간표!$D$5*(IF(기준값!$B$19<기준값!$B$11,기준값!$B$16,IF(기준값!$B$19>=기준값!$B$12,IF($A36>=기준값!$B$13,기준값!$B$14,기준값!$B$16),IF($A36>=기준값!$B$13,기준값!$B$16,기준값!$B$15)))))/기준값!$B$19 -> -7939.1346 | C36: =$A36*기준값!$B$7-기준값!$B$8-(거리구간표!$D$6*(IF(기준값!$B$19<기준값!$B$11,기준값!$B$16,IF(기준값!$B$19>=기준값!$B$12,IF($A36>=기준값!$B$13,기준값!$B$14,기준값!$B$16),IF($A36>=기준값!$B$13,기준값!$B$16,기준값!$B$15)))))/기준값!$B$19 -> -8708.3654 | D36: =$A36*기준값!$B$7-기준값!$B$8-(거리구간표!$D$7*(IF(기준값!$B$19<기준값!$B$11,기준값!$B$16,IF(기준값!$B$19>=기준값!$B$12,IF($A36>=기준값!$B$13,기준값!$B$14,기준값!$B$16),IF($A36>=기준값!$B$13,기준값!$B$16,기준값!$B$15)))))/기준값!$B$19 -> -9477.5962 | E36: =$A36*기준값!$B$7-기준값!$B$8-(거리구간표!$D$8*(IF(기준값!$B$19<기준값!$B$11,기준값!$B$16,IF(기준값!$B$19>=기준값!$B$12,IF($A36>=기준값!$B$13,기준값!$B$14,기준값!$B$16),IF($A36>=기준값!$B$13,기준값!$B$16,기준값!$B$15)))))/기준값!$B$19 -> -11016.058 | F36: =$A36*기준값!$B$7-기준값!$B$8-(거리구간표!$D$9*(IF(기준값!$B$19<기준값!$B$11,기준값!$B$16,IF(기준값!$B$19>=기준값!$B$12,IF($A36>=기준값!$B$13,기준값!$B$14,기준값!$B$16),IF($A36>=기준값!$B$13,기준값!$B$16,기준값!$B$15)))))/기준값!$B$19 -> -11785.288 | G36: =$A36*기준값!$B$7-기준값!$B$8-(거리구간표!$D$10*(IF(기준값!$B$19<기준값!$B$11,기준값!$B$16,IF(기준값!$B$19>=기준값!$B$12,IF($A36>=기준값!$B$13,기준값!$B$14,기준값!$B$16),IF($A36>=기준값!$B$13,기준값!$B$16,기준값!$B$15)))))/기준값!$B$19 -> -12554.519 | H36: =$A36*기준값!$B$7-기준값!$B$8-(거리구간표!$D$11*(IF(기준값!$B$19<기준값!$B$11,기준값!$B$16,IF(기준값!$B$19>=기준값!$B$12,IF($A36>=기준값!$B$13,기준값!$B$14,기준값!$B$16),IF($A36>=기준값!$B$13,기준값!$B$16,기준값!$B$15)))))/기준값!$B$19 -> -13323.75 | I36: =$A36*기준값!$B$7-기준값!$B$8-(거리구간표!$D$12*(IF(기준값!$B$19<기준값!$B$11,기준값!$B$16,IF(기준값!$B$19>=기준값!$B$12,IF($A36>=기준값!$B$13,기준값!$B$14,기준값!$B$16),IF($A36>=기준값!$B$13,기준값!$B$16,기준값!$B$15)))))/기준값!$B$19 -> -14092.981 | J36: =$A36*기준값!$B$7-기준값!$B$8-(거리구간표!$D$13*(IF(기준값!$B$19<기준값!$B$11,기준값!$B$16,IF(기준값!$B$19>=기준값!$B$12,IF($A36>=기준값!$B$13,기준값!$B$14,기준값!$B$16),IF($A36>=기준값!$B$13,기준값!$B$16,기준값!$B$15)))))/기준값!$B$19 -> -14862.212
A37: 111 | B37: =$A37*기준값!$B$7-기준값!$B$8-(거리구간표!$D$5*(IF(기준값!$B$19<기준값!$B$11,기준값!$B$16,IF(기준값!$B$19>=기준값!$B$12,IF($A37>=기준값!$B$13,기준값!$B$14,기준값!$B$16),IF($A37>=기준값!$B$13,기준값!$B$16,기준값!$B$15)))))/기준값!$B$19 -> -4060.2596 | C37: =$A37*기준값!$B$7-기준값!$B$8-(거리구간표!$D$6*(IF(기준값!$B$19<기준값!$B$11,기준값!$B$16,IF(기준값!$B$19>=기준값!$B$12,IF($A37>=기준값!$B$13,기준값!$B$14,기준값!$B$16),IF($A37>=기준값!$B$13,기준값!$B$16,기준값!$B$15)))))/기준값!$B$19 -> -4829.4904 | D37: =$A37*기준값!$B$7-기준값!$B$8-(거리구간표!$D$7*(IF(기준값!$B$19<기준값!$B$11,기준값!$B$16,IF(기준값!$B$19>=기준값!$B$12,IF($A37>=기준값!$B$13,기준값!$B$14,기준값!$B$16),IF($A37>=기준값!$B$13,기준값!$B$16,기준값!$B$15)))))/기준값!$B$19 -> -5598.7212 | E37: =$A37*기준값!$B$7-기준값!$B$8-(거리구간표!$D$8*(IF(기준값!$B$19<기준값!$B$11,기준값!$B$16,IF(기준값!$B$19>=기준값!$B$12,IF($A37>=기준값!$B$13,기준값!$B$14,기준값!$B$16),IF($A37>=기준값!$B$13,기준값!$B$16,기준값!$B$15)))))/기준값!$B$19 -> -7137.1827 | F37: =$A37*기준값!$B$7-기준값!$B$8-(거리구간표!$D$9*(IF(기준값!$B$19<기준값!$B$11,기준값!$B$16,IF(기준값!$B$19>=기준값!$B$12,IF($A37>=기준값!$B$13,기준값!$B$14,기준값!$B$16),IF($A37>=기준값!$B$13,기준값!$B$16,기준값!$B$15)))))/기준값!$B$19 -> -7906.4135 | G37: =$A37*기준값!$B$7-기준값!$B$8-(거리구간표!$D$10*(IF(기준값!$B$19<기준값!$B$11,기준값!$B$16,IF(기준값!$B$19>=기준값!$B$12,IF($A37>=기준값!$B$13,기준값!$B$14,기준값!$B$16),IF($A37>=기준값!$B$13,기준값!$B$16,기준값!$B$15)))))/기준값!$B$19 -> -8675.6442 | H37: =$A37*기준값!$B$7-기준값!$B$8-(거리구간표!$D$11*(IF(기준값!$B$19<기준값!$B$11,기준값!$B$16,IF(기준값!$B$19>=기준값!$B$12,IF($A37>=기준값!$B$13,기준값!$B$14,기준값!$B$16),IF($A37>=기준값!$B$13,기준값!$B$16,기준값!$B$15)))))/기준값!$B$19 -> -9444.875 | I37: =$A37*기준값!$B$7-기준값!$B$8-(거리구간표!$D$12*(IF(기준값!$B$19<기준값!$B$11,기준값!$B$16,IF(기준값!$B$19>=기준값!$B$12,IF($A37>=기준값!$B$13,기준값!$B$14,기준값!$B$16),IF($A37>=기준값!$B$13,기준값!$B$16,기준값!$B$15)))))/기준값!$B$19 -> -10214.106 | J37: =$A37*기준값!$B$7-기준값!$B$8-(거리구간표!$D$13*(IF(기준값!$B$19<기준값!$B$11,기준값!$B$16,IF(기준값!$B$19>=기준값!$B$12,IF($A37>=기준값!$B$13,기준값!$B$14,기준값!$B$16),IF($A37>=기준값!$B$13,기준값!$B$16,기준값!$B$15)))))/기준값!$B$19 -> -10983.337
A38: 112 | B38: =$A38*기준값!$B$7-기준값!$B$8-(거리구간표!$D$5*(IF(기준값!$B$19<기준값!$B$11,기준값!$B$16,IF(기준값!$B$19>=기준값!$B$12,IF($A38>=기준값!$B$13,기준값!$B$14,기준값!$B$16),IF($A38>=기준값!$B$13,기준값!$B$16,기준값!$B$15)))))/기준값!$B$19 -> -181.38462 | C38: =$A38*기준값!$B$7-기준값!$B$8-(거리구간표!$D$6*(IF(기준값!$B$19<기준값!$B$11,기준값!$B$16,IF(기준값!$B$19>=기준값!$B$12,IF($A38>=기준값!$B$13,기준값!$B$14,기준값!$B$16),IF($A38>=기준값!$B$13,기준값!$B$16,기준값!$B$15)))))/기준값!$B$19 -> -950.61538 | D38: =$A38*기준값!$B$7-기준값!$B$8-(거리구간표!$D$7*(IF(기준값!$B$19<기준값!$B$11,기준값!$B$16,IF(기준값!$B$19>=기준값!$B$12,IF($A38>=기준값!$B$13,기준값!$B$14,기준값!$B$16),IF($A38>=기준값!$B$13,기준값!$B$16,기준값!$B$15)))))/기준값!$B$19 -> -1719.8462 | E38: =$A38*기준값!$B$7-기준값!$B$8-(거리구간표!$D$8*(IF(기준값!$B$19<기준값!$B$11,기준값!$B$16,IF(기준값!$B$19>=기준값!$B$12,IF($A38>=기준값!$B$13,기준값!$B$14,기준값!$B$16),IF($A38>=기준값!$B$13,기준값!$B$16,기준값!$B$15)))))/기준값!$B$19 -> -3258.3077 | F38: =$A38*기준값!$B$7-기준값!$B$8-(거리구간표!$D$9*(IF(기준값!$B$19<기준값!$B$11,기준값!$B$16,IF(기준값!$B$19>=기준값!$B$12,IF($A38>=기준값!$B$13,기준값!$B$14,기준값!$B$16),IF($A38>=기준값!$B$13,기준값!$B$16,기준값!$B$15)))))/기준값!$B$19 -> -4027.5385 | G38: =$A38*기준값!$B$7-기준값!$B$8-(거리구간표!$D$10*(IF(기준값!$B$19<기준값!$B$11,기준값!$B$16,IF(기준값!$B$19>=기준값!$B$12,IF($A38>=기준값!$B$13,기준값!$B$14,기준값!$B$16),IF($A38>=기준값!$B$13,기준값!$B$16,기준값!$B$15)))))/기준값!$B$19 -> -4796.7692 | H38: =$A38*기준값!$B$7-기준값!$B$8-(거리구간표!$D$11*(IF(기준값!$B$19<기준값!$B$11,기준값!$B$16,IF(기준값!$B$19>=기준값!$B$12,IF($A38>=기준값!$B$13,기준값!$B$14,기준값!$B$16),IF($A38>=기준값!$B$13,기준값!$B$16,기준값!$B$15)))))/기준값!$B$19 -> -5566 | I38: =$A38*기준값!$B$7-기준값!$B$8-(거리구간표!$D$12*(IF(기준값!$B$19<기준값!$B$11,기준값!$B$16,IF(기준값!$B$19>=기준값!$B$12,IF($A38>=기준값!$B$13,기준값!$B$14,기준값!$B$16),IF($A38>=기준값!$B$13,기준값!$B$16,기준값!$B$15)))))/기준값!$B$19 -> -6335.2308 | J38: =$A38*기준값!$B$7-기준값!$B$8-(거리구간표!$D$13*(IF(기준값!$B$19<기준값!$B$11,기준값!$B$16,IF(기준값!$B$19>=기준값!$B$12,IF($A38>=기준값!$B$13,기준값!$B$14,기준값!$B$16),IF($A38>=기준값!$B$13,기준값!$B$16,기준값!$B$15)))))/기준값!$B$19 -> -7104.4615
