Workbook

Sheet 양식2
A1: 농장명 : | D1: =TODAY() -> 46325
F2: 클레임적용 | O2: 클레임
B3: 일자 | C3: 두수 | D3: 총체 | E3: 평체 | F3: 두수 | G3: 총체 | H3: 평체 | I3: 전입처 | J3: 출하예정일 | K3: 폐사두수 | L3: 총폐사율 | M3: 출하두수 | N3: 재고 | O3: 일자 | P3: 두수
E4: =D4/C4 -> #DIV/0! | F4: =C8-P8 -> 0 | G4: =D8-(D8/C8*P8) -> #DIV/0! | H4: =G4/F4 -> #DIV/0! | J4: =B4+90 -> 90 | K4: =C58 -> 0 | L4: =K8/F8 -> #DIV/0! | M4: =E58 -> 0 | N4: =F8-C58-E58 -> 0
E5: =D5/C5 -> #DIV/0! | J5: =B5+90 -> 90
E6: =D6/C6 -> #DIV/0!
E7: =D7/C7 -> #DIV/0!
B8: 계 | C8: =SUM(C4:C7) -> 0 | D8: =SUM(D4:D7) -> 0 | E8: =D8/C8 -> #DIV/0! | F8: =SUM(F4) -> 0 | G8: =SUM(G4) -> #DIV/0! | H8: =G8/F8 -> #DIV/0! | K8: =K4 -> 0 | L8: =L4 -> #DIV/0! | M8: =M4 -> 0 | N8: =N4 -> 0 | O8: =P8/C8 -> #DIV/0! | P8: =SUM(P4:P7) -> 0
I9: =F8*0.95 -> 0
B10: 폐사내역 | D10: 출하내역 | H10: 사료내역 | K10: 사료 두당 섭취량 | N10: 특이사항 | R10: 출하예상
B11: 일자 | C11: 두수 | D11: 일자 | E11: 두수 | F11: 총체 | G11: 평체 | H11: 일자 | I11: 품목 | J11: 중량 | K11: 품목 | L11: 총중량 | M11: 두당 섭취량 | N11: 일자 | O11: 내용 | R11: 주차 | S11: 두수
K12: 윈맥스S트랜스 | L12: =SUMIF($I$12:$I$123,K12,$J$12:$J$123) -> 0 | M12: =L12/$C$8 -> #DIV/0!
K13: 리더MF1호 | L13: =SUMIF($I$12:$I$123,K13,$J$12:$J$123) -> 0 | M13: =L13/$C$8 -> #DIV/0!
K14: 리더MF2호 | L14: =SUMIF($I$12:$I$123,K14,$J$12:$J$123) -> 0 | M14: =L14/$C$8 -> #DIV/0!
K15: 총량 | L15: =SUM(L12:L14) -> 0 | M15: =L15/C8 -> #DIV/0!
K18: 예상FCR | L18: =J58/((I9*G58)-(G9)) -> #DIV/0!
C58: =SUM(C12:C57) -> 0 | E58: =SUM(E12:E57) -> 0 | F58: =SUM(F12:F57) -> 0 | G58: =F58/E58 -> #DIV/0! | J58: =SUM(J12:J57) -> 0

Sheet 통합
B1: 농가명 | C1: 입식일 | D1: 전입처 | E1: 총체 | F1: 평체 | G1: 전입두수 | H1: 클레임두수 | I1: 클레임율 | J1: 폐사두수 | K1: 출하두수 | L1: 폐사율 | M1: 재고 | N1: 총사료투입량 | O1: 예상FCR | P1: 사육일령 | Q1: 평균일당사료섭취량 | R1: 비고 | U1: =TODAY() -> 46325
B2: 요셉(1106) | C2: ='요셉(1106)'!B$4 -> 0 | D2: ='요셉(1106)'!I$4 -> 태평 | E2: ='요셉(1106)'!G$8 -> #DIV/0! | F2: ='요셉(1106)'!H$8 -> #DIV/0! | G2: ='요셉(1106)'!F$8 -> 0 | H2: ='요셉(1106)'!P$8 -> 0 | I2: ='요셉(1106)'!O$8 -> #DIV/0! | J2: ='요셉(1106)'!K$8 -> 0 | K2: ='요셉(1106)'!M$8 -> 0 | L2: ='요셉(1106)'!L$8 -> #DIV/0! | M2: ='요셉(1106)'!N$8 -> 0 | N2: ='요셉(1106)'!L21 -> #DIV/0! | O2: ='요셉(1106)'!L27 -> #DIV/0! | P2: =$U$1-C2 -> 46325 | Q2: ='요셉(1106)'!L28 -> 0
B3: 신흥1-4,5 | C3: ='신흥(1-1)'!B$4 -> 46224 | D3: ='신흥(1-1)'!I$4 -> 태농 | E3: ='신흥(1-1)'!G$9 -> 13730 | F3: ='신흥(1-1)'!H$8 -> 24.705263 | G3: ='신흥(1-1)'!F$8 -> 936 | H3: ='신흥(1-1)'!P$8 -> 14 | I3: ='신흥(1-1)'!O$8 -> 0.014736842 | J3: ='신흥(1-1)'!K$8 -> 53 | K3: ='신흥(1-1)'!M$8 -> 0 | L3: ='신흥(1-1)'!L$8 -> 0.056623932 | M3: ='신흥(1-1)'!N$8 -> 883 | N3: ='신흥(1-1)'!L20 -> 0 | O3: ='신흥(1-1)'!L23 -> 0 | P3: =$U$1-C3 -> 101 | Q3: ='신흥(1-1)'!L23 -> 0
B4: 신흥1-6 | C4: ='신흥(1-6)'!B$4 -> 46275 | D4: ='신흥(1-6)'!I$4 -> 태농 | E4: ='신흥(1-6)'!G$9 -> 13730 | F4: ='신흥(1-6)'!H$8 -> 29.5 | G4: ='신흥(1-6)'!F$8 -> 475 | H4: ='신흥(1-6)'!P$8 -> 5 | I4: ='신흥(1-6)'!O$8 -> 0.010416667 | J4: ='신흥(1-6)'!K$8 -> 19 | K4: ='신흥(1-6)'!M$8 -> 0 | L4: ='신흥(1-6)'!L$8 -> 0.04 | M4: ='신흥(1-6)'!N$8 -> 456 | N4: ='신흥(1-6)'!L21 -> 0 | O4: ='신흥(1-6)'!L24 -> 0 | P4: =$U$1-C4 -> 50 | Q4: ='신흥(1-6)'!L24 -> 0
B5: 신흥2-10 | C5: ='신흥(2-10)'!B$4 -> 46282 | D5: ='신흥(2-10)'!I$4 -> 태농 | E5: ='신흥(2-10)'!G$9 -> 13730 | F5: ='신흥(2-10)'!H$8 -> 28.9 | G5: ='신흥(2-10)'!F$8 -> 396 | H5: ='신흥(2-10)'!P$8 -> 4 | I5: ='신흥(2-10)'!O$8 -> 0.01 | J5: ='신흥(2-10)'!K$8 -> 15 | K5: ='신흥(2-10)'!M$8 -> 0 | L5: ='신흥(2-10)'!L$8 -> 0.037878788 | M5: ='신흥(2-10)'!N$8 -> 381 | N5: ='신흥(2-10)'!L22 -> 0 | O5: ='신흥(2-10)'!L25 -> 0 | P5: =$U$1-C5 -> 43 | Q5: ='신흥(2-10)'!L25 -> 0
B6: 신흥2-11 | C6: ='신흥(2-11)'!B$4 -> 46294 | D6: ='신흥(2-11)'!I$4 -> 태농 | E6: ='신흥(2-11)'!G$9 -> 13730 | F6: ='신흥(2-11)'!H$8 -> 31.3 | G6: ='신흥(2-11)'!F$8 -> 396 | H6: ='신흥(2-11)'!P$8 -> 4 | I6: ='신흥(2-11)'!O$8 -> 0.01 | J6: ='신흥(2-11)'!K$8 -> 12 | K6: ='신흥(2-11)'!M$8 -> 0 | L6: ='신흥(2-11)'!L$8 -> 0.03030303 | M6: ='신흥(2-11)'!N$8 -> 384 | N6: ='신흥(2-11)'!L23 -> 0 | O6: ='신흥(2-11)'!L26 -> 0 | P6: =$U$1-C6 -> 31 | Q6: ='신흥(2-11)'!L26 -> 0
B7: 신흥2-12 | C7: ='신흥(2-12)'!B$4 -> 46303 | D7: ='신흥(2-12)'!I$4 -> 태농 | E7: ='신흥(2-12)'!G$9 -> 13730 | F7: ='신흥(2-12)'!H$8 -> 28 | G7: ='신흥(2-12)'!F$8 -> 396 | H7: ='신흥(2-12)'!P$8 -> 4 | I7: ='신흥(2-12)'!O$8 -> 0.01 | J7: ='신흥(2-12)'!K$8 -> 11 | K7: ='신흥(2-12)'!M$8 -> 0 | L7: ='신흥(2-12)'!L$8 -> 0.027777778 | M7: ='신흥(2-12)'!N$8 -> 385 | N7: ='신흥(2-12)'!L24 -> 0 | O7: ='신흥(2-12)'!L27 -> 0 | P7: =$U$1-C7 -> 22 | Q7: ='신흥(2-12)'!L27 -> 0
B8: 신흥2-13 | C8: ='신흥(2-13)'!B$4 -> 46316 | D8: ='신흥(2-13)'!I$4 -> 태농 | E8: ='신흥(2-13)'!G$9 -> 13730 | F8: ='신흥(2-13)'!H$8 -> 26.5 | G8: ='신흥(2-13)'!F$8 -> 396 | H8: ='신흥(2-13)'!P$8 -> 4 | I8: ='신흥(2-13)'!O$8 -> 0.01 | J8: ='신흥(2-13)'!K$8 -> 6 | K8: ='신흥(2-13)'!M$8 -> 0 | L8: ='신흥(2-13)'!L$8 -> 0.015151515 | M8: ='신흥(2-13)'!N$8 -> 390 | N8: ='신흥(2-13)'!L25 -> 0 | O8: ='신흥(2-13)'!L28 -> 0 | P8: =$U$1-C8 -> 9 | Q8: ='신흥(2-13)'!L28 -> 0
B9: 신흥2-14 | C9: ='신흥(2-14)'!B$4 -> 46324 | D9: ='신흥(2-14)'!I$4 -> 태농 | E9: ='신흥(2-14)'!G$9 -> 13730 | F9: ='신흥(2-14)'!H$8 -> 26.2 | G9: ='신흥(2-14)'!F$8 -> 396 | H9: ='신흥(2-14)'!P$8 -> 4 | I9: ='신흥(2-14)'!O$8 -> 0.01 | J9: ='신흥(2-14)'!K$8 -> 0 | K9: ='신흥(2-14)'!M$8 -> 0 | L9: ='신흥(2-14)'!L$8 -> 0 | M9: ='신흥(2-14)'!N$8 -> 396 | N9: ='신흥(2-14)'!L26 -> 0 | O9: ='신흥(2-14)'!L29 -> 0 | P9: =$U$1-C9 -> 1 | Q9: ='신흥(2-14)'!L29 -> 0
B10: 준석 | C10: ='준석(26-003)'!B$4 -> 46318 | D10: ='준석(26-003)'!I$4 -> 태평 | E10: ='준석(26-003)'!G$9 -> 8051 | F10: ='준석(26-003)'!H$8 -> 31.2 | G10: ='준석(26-003)'!F$8 -> 938 | H10: ='준석(26-003)'!P$8 -> 12 | I10: ='준석(26-003)'!O$8 -> 0.012631579 | J10: ='준석(26-003)'!K$8 -> 3 | K10: ='준석(26-003)'!M$8 -> 0 | L10: ='준석(26-003)'!L$8 -> 0.0031982942 | M10: ='준석(26-003)'!N$8 -> 935 | N10: ='준석(26-003)'!L22 -> 0 | O10: ='준석(26-003)'!L25 -> 0 | P10: =$U$1-C10 -> 7 | Q10: ='준석(26-003)'!L26 -> 0
J30: 526
J31: 696
J32: =J30/J31 -> 0.75574713

Sheet 대웅돈유전자1(1027)
A1: 농장명 : | B1: 대웅돈유전자1 | D1: =TODAY() -> 46325 | E1: =D1-B4 -> 1099
F2: 클레임적용 | O2: 클레임
B3: 일자 | C3: 두수 | D3: 총체 | E3: 평체 | F3: 두수 | G3: 총체 | H3: 평체 | I3: 전입처 | J3: 출하예정일 | K3: 폐사두수 | L3: 총폐사율 | M3: 출하두수 | N3: 재고 | O3: 일자 | P3: 두수
B4: 45226 | C4: 400 | D4: =3650+3920+4820 -> 12390 | E4: =D4/C4 -> 30.975 | F4: =C8-P8 -> 875 | G4: =D8-(D8/C8*P8) -> 25112.5 | H4: =G4/F4 -> 28.7 | I4: 아빠 | J4: =B4+90 -> 45316 | K4: =C59 -> 27 | L4: =K8/F8 -> 0.030857143 | M4: =E59 -> 848 | N4: =F8-C59-E59 -> 0 | O4: 45226 | P4: 12 | Q4: =3+1+1+1+2+1+1*4 -> 13 | R4: =C4-P4 -> 388
B5: 45234 | C5: 250 | D5: =3620+3660 -> 7280 | E5: =D5/C5 -> 29.12 | J5: =B5+90 -> 45324 | O5: 45234 | P5: 7 | Q5: =1+1+1+2+3+1+1+1 -> 11 | R5: =C5-P5 -> 243
B6: 45240 | C6: 250 | D6: =3090+3070 -> 6160 | E6: =D6/C6 -> 24.64 | J6: =B6+90 -> 45330 | O6: 45240 | P6: 6 | Q6: =1+2+1+1+2+2+1+2+3+1+2+1 -> 19 | R6: =C6-P6 -> 244
E7: =D7/C7 -> #DIV/0!
B8: 계 | C8: =SUM(C4:C7) -> 900 | D8: =SUM(D4:D7) -> 25830 | E8: =D8/C8 -> 28.7 | F8: =SUM(F4) -> 875 | G8: =SUM(G4) -> 25112.5 | H8: =G8/F8 -> 28.7 | K8: =K4 -> 27 | L8: =L4 -> 0.030857143 | M8: =M4 -> 848 | N8: =N4 -> 0 | O8: =P8/C8 -> 0.027777778 | P8: =SUM(P4:P7) -> 25 | Q8: =P8-Q4-Q5-Q6 -> -18
G9: =12024+7077+6016 -> 25117 | I9: =F8*0.95 -> 831.25
B10: 폐사내역 | D10: 출하내역 | H10: 사료내역 | K10: 사료 두당 섭취량 | N10: 특이사항 | R10: 출하예상
B11: 일자 | C11: 두수 | D11: 일자 | E11: 두수 | F11: 총체 | G11: 평체 | H11: 일자 | I11: 품목 | J11: 중량 | K11: 품목 | L11: 총중량 | M11: 두당 섭취량 | N11: 일자 | O11: 내용 | R11: 주차 | S11: 두수
B12: 45235 | C12: 3 | D12: 45315 | E12: 30 | F12: 3230 | G12: =F12/E12 -> 107.66667 | H12: 45226 | I12: 윈맥스S트랜스 | J12: 5040 | K12: 윈맥스S트랜스 | L12: =SUMIF($I$12:$I$124,K12,$J$12:$J$124) -> 48040 | M12: =L12/$C$8 -> 53.377778 | R12: 1월4주 | S12: 30
B13: 45237 | C13: 1 | D13: 45329 | E13: 45 | F13: 5020 | G13: =F13/E13 -> 111.55556 | H13: 45234 | I13: 윈맥스S트랜스 | J13: 5000 | K13: 리더MF1호 | L13: =SUMIF($I$12:$I$124,K13,$J$12:$J$124) -> 36980 | M13: =L13/$C$8 -> 41.088889 | R13: 2월1주
B14: 45239 | C14: 2 | D14: 45337 | E14: 60 | F14: 6560 | G14: =F14/E14 -> 109.33333 | H14: 45240 | I14: 윈맥스S트랜스 | J14: 4970 | K14: 윈맥스S배로우 | L14: =SUMIF($I$12:$I$124,K14,$J$12:$J$124) -> 132170 | M14: =L14/$C$8 -> 146.85556 | R14: 2월2주 | S14: 45
B15: 45240 | C15: 1 | D15: 45344 | E15: 60 | F15: 7190 | G15: =F15/E15 -> 119.83333 | H15: 45241 | I15: 윈맥스S트랜스 | J15: 4990 | K15: 리더MF2호 | L15: =SUMIF($I$12:$I$124,K15,$J$12:$J$124) -> 23110 | M15: =L15/$C$8 -> 25.677778 | R15: 2월3주 | S15: 60
B16: 45242 | C16: 2 | D16: 45344 | E16: 60 | F16: 7180 | G16: =F16/E16 -> 119.66667 | H16: 45247 | I16: 윈맥스S트랜스 | J16: 10040 | K16: 총량 | L16: =SUM(L12:L14) -> 217190 | M16: =L16/C8 -> 241.32222 | R16: 2월4주 | S16: 120
B17: 45245 | C17: 2 | D17: 45348 | E17: 52 | F17: 5940 | G17: =F17/E17 -> 114.23077 | H17: 45254 | I17: 윈맥스S트랜스 | J17: =2000+2020+3990 -> 8010 | R17: 2월5주 | S17: 103
B18: 45247 | C18: 1 | D18: 45348 | E18: 51 | F18: 5850 | G18: =F18/E18 -> 114.70588 | H18: 45260 | I18: 윈맥스S트랜스 | J18: =3000+4990+2000 -> 9990 | R18: 3월1주
B19: 45248 | C19: 2 | D19: 45358 | E19: 65 | F19: 8000 | G19: =F19/E19 -> 123.07692 | H19: 45268 | I19: 리더MF1호 | J19: =3010+4010+5010 -> 12030 | K19: 예상FCR | L19: =J59/((I9*G59)-(G9)) -> 3.3795515 | R19: 3월2주 | S19: 129
B20: 45252 | C20: 3 | D20: 45358 | E20: 64 | F20: 8020 | G20: =F20/E20 -> 125.3125 | H20: 45274 | I20: 리더MF1호 | J20: =2000+6060+4000 -> 12060 | R20: 3월3주 | S20: 243
B21: 45253 | C21: 2 | D21: 45362 | E21: 61 | F21: 7260 | G21: =F21/E21 -> 119.01639 | H21: 45647 | I21: 리더MF1호 | J21: =5940+3990+2960 -> 12890 | R21: 3월4주 | S21: 93
B22: 45254 | C22: 3 | D22: 45362 | E22: 62 | F22: 7390 | G22: =F22/E22 -> 119.19355 | H22: 45656 | I22: 윈맥스S배로우 | J22: =4010+6050+3050 -> 13110 | R22: 3월5주
B23: 45256 | C23: 4 | D23: 45364 | E23: 60 | F23: 7290 | G23: =F23/E23 -> 121.5 | H23: 45295 | I23: 윈맥스S배로우 | J23: =3000+3000+5960 -> 11960 | L23: =108+90+46 -> 244
B24: 45260 | C24: 1 | D24: 45364 | E24: 60 | F24: 6980 | G24: =F24/E24 -> 116.33333 | H24: 45300 | I24: 윈맥스S배로우 | J24: =2990+5040+4030 -> 12060
D25: 45365 | E25: 20 | F25: 1500 | G25: =F25/E25 -> 75 | H25: 45306 | I25: 윈맥스S배로우 | J25: =5010+5000+5000 -> 15010 | L25: 238
D26: 45372 | E26: 51 | F26: 5600 | G26: =F26/E26 -> 109.80392 | H26: 45311 | I26: 윈맥스S배로우 | J26: =4010+2030+4050 -> 10090
D27: 45372 | E27: 47 | F27: 5150 | G27: =F27/E27 -> 109.57447 | H27: 45316 | I27: 윈맥스S배로우 | J27: 10010
G28: =F28/E28 -> #DIV/0! | H28: 45320 | I28: 윈맥스S배로우 | J28: =5020+3000+3020 -> 11040
G29: =F29/E29 -> #DIV/0! | H29: 45324 | I29: 윈맥스S배로우 | J29: 9920
G30: =F30/E30 -> #DIV/0! | H30: 45328 | I30: 윈맥스S배로우 | J30: 8010
G31: =F31/E31 -> #DIV/0! | H31: 45334 | I31: 윈맥스S배로우 | J31: 14970
G32: =F32/E32 -> #DIV/0! | H32: 45337 | I32: 윈맥스S배로우 | J32: 10970
G33: =F33/E33 -> #DIV/0! | H33: 45342 | I33: 윈맥스S배로우 | J33: 5020
G34: =F34/E34 -> #DIV/0! | H34: 45345 | I34: 리더MF2호 | J34: 9060
G35: =F35/E35 -> #DIV/0! | H35: 45350 | I35: 리더MF2호 | J35: =4960+1990 -> 6950
G36: =F36/E36 -> #DIV/0! | H36: 45355 | I36: 리더MF2호 | J36: 7100
G37: =F37/E37 -> #DIV/0!
G38: =F38/E38 -> #DIV/0!
G39: =F39/E39 -> #DIV/0!
G40: =F40/E40 -> #DIV/0!
...

Sheet 진일농장(1004)
A1: 농장명 : | B1: 진일농장(0901) | E1: =TODAY() -> 46325 | F1: =E1-B4 -> 1122
F2: 클레임적용 | O2: 클레임 | R2: 902
B3: 일자 | C3: 두수 | D3: 총체 | E3: 평체 | F3: 두수 | G3: 총체 | H3: 평체 | I3: 전입처 | J3: 출하예정일 | K3: 폐사두수 | L3: 총폐사율 | M3: 출하두수 | N3: 재고 | O3: 일자 | P3: 두수 | R3: =R2-Q4 -> 863
B4: 45203 | C4: 900 | D4: =5410+4520+5270+5300+4740 -> 25240 | E4: =D4/C4 -> 28.044444 | F4: =C8-P8 -> 880 | G4: =D8-(D8/C8*P8) -> 24679.111 | H4: =G4/F4 -> 28.044444 | I4: 익산 | J4: =B4+90 -> 45293 | K4: =C62 -> 100 | L4: =K8/F8 -> 0.11363636 | M4: =E62 -> 780 | N4: =F8-C62-E62 -> 0 | O4: 45203 | P4: 20 | Q4: =1+1+1+1+2+1+3+1+2+1+3+2+2+1+4+12+1 -> 39
J5: =B5+90 -> 90
B8: 계 | C8: =SUM(C4:C7) -> 900 | D8: =SUM(D4:D7) -> 25240 | E8: =D8/C8 -> 28.044444 | F8: =SUM(F4) -> 880 | G8: =SUM(G4) -> 24679.111 | H8: =G8/F8 -> 28.044444 | K8: =K4 -> 100 | L8: =L4 -> 0.11363636 | M8: =M4 -> 780 | N8: =N4 -> 0 | O8: =P8/C8 -> 0.022222222 | P8: =SUM(P4:P7) -> 20 | Q8: =P8-Q4 -> -19
G9: 25740 | I9: =F8*0.886 -> 779.68
B10: 폐사내역 | D10: 출하내역 | H10: 사료내역 | K10: 사료 두당 섭취량 | N10: 특이사항 | R10: 출하예상 | U10: =82-13 -> 69
B11: 일자 | C11: 두수 | D11: 일자 | E11: 두수 | F11: 총체 | G11: 평체 | H11: 일자 | I11: 품목 | J11: 중량 | K11: 품목 | L11: 총중량 | M11: 두당 섭취량 | N11: 일자 | O11: 내용 | R11: 주차 | S11: 두수
B12: 45206 | C12: 1 | D12: 45303 | E12: 61 | F12: 7290 | G12: =F12/E12 -> 119.5082 | H12: 45203 | I12: 윈맥스S트랜스 | J12: 9880 | K12: 윈맥스S트랜스 | L12: =SUMIF($I$12:$I$127,K12,$J$12:$J$127) -> 39930 | M12: =L12/$C$8 -> 44.366667 | R12: 1월2주 | S12: 61
B13: 45210 | C13: 1 | D13: 45307 | E13: 61 | F13: 7110 | G13: =F13/E13 -> 116.55738 | H13: 45211 | I13: 윈맥스S트랜스 | J13: 10050 | K13: 리더MF1호 | L13: =SUMIF($I$12:$I$127,K13,$J$12:$J$127) -> 84960 | M13: =L13/$C$8 -> 94.4 | R13: 1월3주 | S13: 220
B14: 45211 | C14: 1 | D14: 45307 | E14: 62 | F14: 7120 | G14: =F14/E14 -> 114.83871 | H14: 45218 | I14: 윈맥스S트랜스 | J14: 9990 | K14: 리더MF2호 | L14: =SUMIF($I$12:$I$127,K14,$J$12:$J$127) -> 87040 | M14: =L14/$C$8 -> 96.711111 | R14: 1월4주 | S14: 234
B15: 45212 | C15: 1 | D15: 45310 | E15: 60 | F15: 6920 | G15: =F15/E15 -> 115.33333 | H15: 45227 | I15: 리더MF1호 | J15: 9990 | K15: 총량 | L15: =SUM(L12:L14) -> 211930 | M15: =L15/C8 -> 235.47778 | R15: 1월5주
B16: 45213 | C16: 2 | D16: 45310 | E16: 37 | F16: =6280/55*37 -> 4224.7273 | G16: =F16/E16 -> 114.18182 | H16: 45237 | I16: 윈맥스S트랜스 | J16: 10010 | R16: 2월1주
B17: 45216 | C17: 1 | D17: 45316 | E17: 71 | F17: 7960 | G17: =F17/E17 -> 112.11268 | H17: 45239 | I17: 리더MF1호 | J17: 7000 | R17: 2월2주 | S17: 61
B18: 45219 | C18: 3 | D18: 45316 | E18: 53 | F18: =7850/71*E18 -> 5859.8592 | G18: =F18/E18 -> 110.56338 | H18: 45248 | I18: 리더MF1호 | J18: 8050 | K18: 예상FCR | L18: =J62/((I9*G62)-(G9)) -> 3.4663509 | R18: 2월3주 | S18: 50
B19: 45220 | C19: 1 | D19: 45323 | E19: 55 | F19: 5970 | G19: =F19/E19 -> 108.54545 | H19: 45618 | I19: 리더MF1호 | J19: 6050 | R19: 2월4주 | S19: 71
B20: 45222 | C20: 2 | D20: 45323 | E20: 55 | F20: 5980 | G20: =F20/E20 -> 108.72727 | H20: 45257 | I20: 리더MF1호 | J20: 9970 | R20: 2월5주 | S20: 68
B21: 45225 | C21: 1 | D21: 45329 | E21: 61 | F21: 7110 | G21: =F21/E21 -> 116.55738 | H21: 45257 | I21: 리더MF2호 | J21: 5010
B22: 45226 | C22: 3 | D22: 45337 | E22: 50 | F22: 5780 | G22: =F22/E22 -> 115.6 | H22: 45262 | I22: 리더MF1호 | J22: 12820
B23: 45227 | C23: 2 | D23: 45343 | E23: 71 | F23: 8050 | G23: =F23/E23 -> 113.38028 | H23: 45266 | I23: 리더MF1호 | J23: 10140
B24: 45231 | C24: 2 | D24: 45348 | E24: 55 | F24: =7060/68*E24 -> 5710.2941 | G24: =F24/E24 -> 103.82353 | H24: 45273 | I24: 리더MF1호 | J24: 13170
A25: 0 | B25: 45232 | C25: 1 | D25: 45344 | E25: 28 | F25: 1830 | G25: =F25/E25 -> 65.357143 | H25: 45280 | I25: 리더MF2호 | J25: 5030
B26: 45233 | C26: 4 | G26: =F26/E26 -> #DIV/0! | H26: 45281 | I26: 리더MF2호 | J26: 15190
B27: 45234 | C27: 1 | H27: 45287 | I27: 리더MF1호 | J27: 7770
B28: 45235 | C28: 2 | H28: 45290 | I28: 리더MF2호 | J28: 5050
B29: 45238 | C29: 2 | H29: 45293 | I29: 리더MF2호 | J29: 10620
B30: 45239 | C30: 5 | H30: 45297 | I30: 리더MF2호 | J30: 12220
B31: 45240 | C31: 4 | H31: 45304 | I31: 리더MF2호 | J31: 12150
B32: 45241 | C32: 1 | H32: 45311 | I32: 리더MF2호 | J32: 5070
B33: 45243 | C33: 2 | H33: 45318 | I33: 리더MF2호 | J33: 6640
B34: 45247 | C34: 1 | H34: 45318 | I34: 리더MF2호 | J34: 5060
B35: 45248 | C35: 3 | H35: 45327 | I35: 리더MF2호 | J35: 5000
B36: 45250 | C36: 1
B37: 45254 | C37: 1
B38: 45269 | C38: 2
B39: 45283 | C39: 4
B40: 45284 | C40: 1
B41: 45286 | C41: 3
B42: 45287 | C42: 3
...

Sheet 대웅돈유전자1(0401)
A1: 농장명 : | B1: 대웅돈유전자1 | D1: =TODAY() -> 46325 | E1: =D1-B4 -> 942
F2: 클레임적용 | O2: 클레임
B3: 일자 | C3: 두수 | D3: 총체 | E3: 평체 | F3: 두수 | G3: 총체 | H3: 평체 | I3: 전입처 | J3: 출하예정일 | K3: 폐사두수 | L3: 총폐사율 | M3: 출하두수 | N3: 재고 | O3: 일자 | P3: 두수
B4: 45383 | C4: 450 | D4: =3420+3300+3280 -> 10000 | E4: =D4/C4 -> 22.222222 | F4: =C8-P8 -> 878 | G4: =D8-(D8/C8*P8) -> 19667.2 | H4: =G4/F4 -> 22.4 | I4: 돈앤돈 | J4: =B4+90 -> 45473 | K4: =C59 -> 44 | L4: =K8/F8 -> 0.050113895 | M4: =E59 -> 834 | N4: =F8-C59-E59 -> 0 | O4: 45383 | P4: 13 | Q4: 18 | R4: =C4-P4 -> 437
B5: 45397 | C5: 450 | D5: 10160 | E5: =D5/C5 -> 22.577778 | J5: =B5+90 -> 45487 | O5: 45397 | P5: 9 | Q5: 2 | R5: =C5-P5 -> 441
E6: =D6/C6 -> #DIV/0! | J6: =B6+90 -> 90 | R6: =C6-P6 -> 0
E7: =D7/C7 -> #DIV/0!
B8: 계 | C8: =SUM(C4:C7) -> 900 | D8: =SUM(D4:D7) -> 20160 | E8: =D8/C8 -> 22.4 | F8: =SUM(F4) -> 878 | G8: =SUM(G4) -> 19667.2 | H8: =G8/F8 -> 22.4 | K8: =K4 -> 44 | L8: =L4 -> 0.050113895 | M8: =M4 -> 834 | N8: =N4 -> 0 | O8: =P8/C8 -> 0.024444444 | P8: =SUM(P4:P7) -> 22 | Q8: =P8-Q4-Q5-Q6 -> 2
G9: =9714+9962 -> 19676 | I9: =F8*0.95 -> 834.1 | R9: 대웅돈
B10: 폐사내역 | D10: 출하내역 | H10: 사료내역 | K10: 사료 두당 섭취량 | N10: 특이사항 | R10: 출하예상 | U10: 실출하
B11: 일자 | C11: 두수 | D11: 일자 | E11: 두수 | F11: 총체 | G11: 평체 | H11: 일자 | I11: 품목 | J11: 중량 | K11: 품목 | L11: 총중량 | M11: 두당 섭취량 | N11: 일자 | O11: 내용 | R11: 주차 | S11: 두수 | U11: 주차 | V11: 두수
B12: 45439 | C12: 2 | D12: 45497 | E12: 61 | F12: 6610 | G12: =F12/E12 -> 108.36066 | H12: 45370 | I12: 윈맥스S트랜스 | J12: 960 | K12: 윈맥스S트랜스 | L12: =SUMIF($I$12:$I$124,K12,$J$12:$J$124) -> 64620 | M12: =L12/$C$8 -> 71.8 | R12: 7월1주 | U12: 7월1주
B13: 45446 | C13: 1 | D13: 45503 | E13: 60 | F13: 6470 | G13: =F13/E13 -> 107.83333 | H13: 45383 | I13: 윈맥스S트랜스 | J13: 4780 | K13: 리더MF1호 | L13: =SUMIF($I$12:$I$124,K13,$J$12:$J$124) -> 50140 | M13: =L13/$C$8 -> 55.711111 | R13: 7월2주 | U13: 7월2주
B14: 45453 | C14: 1 | D14: 45511 | E14: 58 | F14: 6550 | G14: =F14/E14 -> 112.93103 | H14: 45394 | I14: 윈맥스S트랜스 | J14: 4900 | K14: 프레쉬맥스제로육성돈 | L14: =SUMIF($I$12:$I$124,K14,$J$12:$J$124) -> 84210 | M14: =L14/$C$8 -> 93.566667 | R14: 7월3주 | U14: 7월3주
B15: 45461 | C15: 3 | D15: 45516 | E15: 60 | F15: 6640 | G15: =F15/E15 -> 110.66667 | H15: 45399 | I15: 윈맥스S트랜스 | J15: =4880+5190 -> 10070 | K15: 리더MF2호 | L15: =SUMIF($I$12:$I$124,K15,$J$12:$J$124) -> 33240 | M15: =L15/$C$8 -> 36.933333 | R15: 7월4주 | S15: 61 | U15: 7월4주 | V15: 61
B16: 45475 | C16: 2 | D16: 45516 | E16: 58 | F16: 6650 | G16: =F16/E16 -> 114.65517 | H16: 45402 | I16: 윈맥스S트랜스 | J16: 5340 | K16: 총량 | L16: =SUM(L12:L15) -> 232210 | M16: =L16/C8 -> 258.01111 | R16: 7월5주 | S16: 70 | U16: 7월5주 | V16: 60
B17: 45489 | C17: 2 | D17: 45520 | E17: 24 | F17: 2790 | G17: =F17/E17 -> 116.25 | H17: 45411 | I17: 프레쉬맥스제로육성돈 | J17: 7850 | R17: 8월1주 | U17: 8월1주
B18: 45490 | C18: 3 | D18: 45524 | E18: 52 | F18: 5710 | G18: =F18/E18 -> 109.80769 | H18: 45418 | I18: 프레쉬맥스제로육성돈 | J18: 11470 | R18: 8월2주 | S18: 100 | U18: 8월2주 | V18: 58
B19: 45517 | C19: 2 | D19: 45526 | E19: 64 | F19: 7050 | G19: =F19/E19 -> 110.15625 | H19: 45425 | I19: 프레쉬맥스제로육성돈 | J19: =3960+2800+6000 -> 12760 | K19: 예상FCR | L19: =(J59/I9)/(113-H8) -> 3.0728022 | R19: 8월3주 | S19: 60 | U19: 8월3주 | V19: 143
B20: 45524 | C20: 3 | D20: 45531 | E20: 44 | F20: 4730 | G20: =F20/E20 -> 107.5 | H20: 45432 | I20: 프레쉬맥스제로육성돈 | J20: 6000 | K20: 평균일당사료섭취량 | L20: =(J45+J46+J47)/N8/6 -> #DIV/0! | R20: 8월4주 | S20: 70 | U20: 8월4주 | V20: 116
B21: 45526 | C21: 3 | D21: 45531 | E21: 20 | F21: 1200 | G21: =F21/E21 -> 60 | H21: 45436 | I21: 프레쉬맥스제로육성돈 | J21: =3940+3970 -> 7910 | R21: 8월5주 | S21: 120 | U21: 8월5주 | V21: 150
B22: 45531 | C22: 4 | D22: 45534 | E22: 36 | F22: 4030 | G22: =F22/E22 -> 111.94444 | H22: 45440 | I22: 리더MF1호 | J22: 4990 | R22: 9월1주 | S22: 120 | U22: 9월1주 | V22: 120
B23: 45538 | C23: 4 | D23: 45534 | E23: 35 | F23: 3920 | G23: =F23/E23 -> 112 | H23: 45443 | I23: 리더MF1호 | J23: =3030+5040 -> 8070 | R23: 9월2주 | S23: 90 | U23: 9월2주 | V23: 100
C24: 14 | G24: =F24/E24 -> #DIV/0! | H24: 45446 | I24: 리더MF1호 | J24: 3900 | R24: 9월3주 | S24: 100 | U24: 9월3주
D25: 45541 | E25: 62 | F25: 6970 | G25: =F25/E25 -> 112.41935 | H25: 45450 | I25: 리더MF1호 | J25: 12120 | R25: 9월4주 | S25: 50 | U25: 9월4주
D26: 45545 | E26: 78 | F26: 8070 | G26: =F26/E26 -> 103.46154 | H26: 45456 | I26: 리더MF1호 | J26: 5010
D27: 45545 | E27: 73 | F27: 7560 | G27: =F27/E27 -> 103.56164 | H27: 45460 | I27: 리더MF1호 | J27: =5040+5040+2010 -> 12090 | L27: =M8-E21 -> 814
D28: 45554 | E28: 49 | F28: 5520 | G28: =F28/E28 -> 112.65306 | H28: 45464 | I28: 프레쉬맥스제로육성돈 | J28: 5010
G29: =F29/E29 -> #DIV/0! | H29: 45468 | I29: 프레쉬맥스제로육성돈 | J29: =4020+6090 -> 10110
G30: =F30/E30 -> #DIV/0! | H30: 45470 | I30: 프레쉬맥스제로육성돈 | J30: =6050+2010 -> 8060
G31: =F31/E31 -> #DIV/0! | H31: 45474 | I31: 리더MF1호 | J31: 1980
G32: =F32/E32 -> #DIV/0! | H32: 45474 | I32: 리더MF2호 | J32: 5030
G33: =F33/E33 -> #DIV/0! | H33: 45474 | I33: 리더MF1호 | J33: 1980
G34: =F34/E34 -> #DIV/0! | H34: 45478 | I34: 리더MF2호 | J34: 5030
G35: =F35/E35 -> #DIV/0! | H35: 45478 | I35: 리더MF2호 | J35: 3040
G36: =F36/E36 -> #DIV/0! | H36: 45478 | I36: 리더MF2호 | J36: 5020
G37: =F37/E37 -> #DIV/0! | H37: 45484 | I37: 리더MF2호 | J37: 5030
G38: =F38/E38 -> #DIV/0! | H38: 45485 | I38: 프레쉬맥스제로육성돈 | J38: 5000
G39: =F39/E39 -> #DIV/0! | H39: 45485 | I39: 프레쉬맥스제로육성돈 | J39: 10040
G40: =F40/E40 -> #DIV/0! | H40: 45490 | I40: 윈맥스S트랜스 | J40: 5930
...

Sheet 진일농장4(1101)
A1: 농장명 : | B1: 진일농장(0901) | E1: =TODAY() -> 46325 | F1: =E1-B4 -> 1094
F2: 클레임적용 | O2: 클레임 | R2: 903
B3: 일자 | C3: 두수 | D3: 총체 | E3: 평체 | F3: 두수 | G3: 총체 | H3: 평체 | I3: 전입처 | J3: 출하예정일 | K3: 폐사두수 | L3: 총폐사율 | M3: 출하두수 | N3: 재고 | O3: 일자 | P3: 두수 | R3: =R2-Q4 -> 835
B4: 45231 | C4: 903 | D4: 21080 | E4: =D4/C4 -> 23.344408 | F4: =C8-P8 -> 876 | G4: =D8-(D8/C8*P8) -> 20449.701 | H4: =G4/F4 -> 23.344408 | I4: 익산 | J4: =B4+90 -> 45321 | K4: =C58 -> 265 | L4: =K8/F8 -> 0.30251142 | M4: =E58 -> 779 | N4: =F8-C58-E58 -> -168 | O4: 45231 | P4: 27 | Q4: =2+1+1+1+1+3+1+4+1+3+2+2+2+1+3+4+3+5+2+2+1+2+3+1+2+2+9+4 -> 68
J5: =B5+90 -> 90
B8: 계 | C8: =SUM(C4:C7) -> 903 | D8: =SUM(D4:D7) -> 21080 | E8: =D8/C8 -> 23.344408 | F8: =SUM(F4) -> 876 | G8: =SUM(G4) -> 20449.701 | H8: =G8/F8 -> 23.344408 | K8: =K4 -> 265 | L8: =L4 -> 0.30251142 | M8: =M4 -> 779 | N8: =N4 -> -168 | O8: =P8/C8 -> 0.029900332 | P8: =SUM(P4:P7) -> 27 | Q8: =P8-Q4 -> -41
G9: 20459 | I9: =F8*0.95 -> 832.2 | U9: =3600 -> 3600
B10: 폐사내역 | D10: 출하내역 | H10: 사료내역 | K10: 사료 두당 섭취량 | N10: 특이사항 | R10: 출하예상 | U10: 168
B11: 일자 | C11: 두수 | D11: 일자 | E11: 두수 | F11: 총체 | G11: 평체 | H11: 일자 | I11: 품목 | J11: 중량 | K11: 품목 | L11: 총중량 | M11: 두당 섭취량 | N11: 일자 | O11: 내용 | R11: 주차 | S11: 두수 | U11: =U10/U9 -> 0.046666667
B12: 45234 | C12: 7 | D12: 45337 | E12: 53 | F12: 5960 | G12: =F12/E12 -> 112.45283 | H12: 45231 | I12: 윈맥스S트랜스 | J12: 5040 | K12: 윈맥스S트랜스 | L12: =SUMIF($I$12:$I$123,K12,$J$12:$J$123) -> 48080 | M12: =L12/$C$8 -> 53.24474 | R12: 2월3주 | S12: 53
B13: 45236 | C13: 3 | D13: 45343 | E13: 40 | F13: 4490 | G13: =F13/E13 -> 112.25 | H13: 45234 | I13: 윈맥스S트랜스 | J13: 10050 | K13: 리더MF1호 | L13: =SUMIF($I$12:$I$123,K13,$J$12:$J$123) -> 79470 | M13: =L13/$C$8 -> 88.006645 | R13: 2월4주 | S13: 40
B14: 45240 | C14: 4 | D14: 45348 | E14: 13 | F14: =7060/68*E14 -> 1349.7059 | G14: =F14/E14 -> 103.82353 | H14: 45245 | I14: 윈맥스S트랜스 | J14: 10010 | K14: 리더MF2호 | L14: =SUMIF($I$12:$I$123,K14,$J$12:$J$123) -> 69970 | M14: =L14/$C$8 -> 77.486157 | R14: 2월5주 | S14: 13
B15: 45242 | C15: 5 | D15: 45358 | E15: 60 | F15: 6720 | G15: =F15/E15 -> 112 | H15: 45255 | I15: 윈맥스S트랜스 | J15: 10030 | K15: 총량 | L15: =SUM(L12:L14) -> 197520 | M15: =L15/C8 -> 218.73754 | R15: 3월1주
B16: 45251 | C16: 5 | D16: 45358 | E16: 61 | F16: =3460+3440 -> 6900 | G16: =F16/E16 -> 113.11475 | H16: 45259 | I16: 윈맥스S트랜스 | J16: 5040 | R16: 3월2주 | S16: 121
B17: 45254 | C17: 5 | D17: 45364 | E17: 75 | F17: =4030+4700 -> 8730 | G17: =F17/E17 -> 116.4 | H17: 45266 | I17: 리더MF1호 | J17: 5060 | R17: 3월3주 | S17: 150
B18: 45258 | C18: 2 | D18: 45364 | E18: 75 | F18: =4520+3990 -> 8510 | G18: =F18/E18 -> 113.46667 | H18: 45268 | I18: 윈맥스S트랜스 | J18: 7910 | K18: 예상FCR | L18: =J58/((I9*G58)-(G9)) -> 3.1928294 | R18: 3월4주 | S18: 120
B19: 45260 | C19: 2 | D19: 45369 | E19: 62 | F19: 6880 | G19: =F19/E19 -> 110.96774 | H19: 45648 | I19: 리더MF1호 | J19: 7950 | R19: 3월5주
B20: 45261 | C20: 1 | D20: 45369 | E20: =32+31 -> 63 | F20: =3590+3530 -> 7120 | G20: =F20/E20 -> 113.01587 | H20: 45653 | I20: 리더MF1호 | J20: 1990 | R20: 4월1주 | S20: 60
B21: 45262 | C21: 2 | D21: 45383 | E21: 54 | F21: 6010 | G21: =F21/E21 -> 111.2963 | H21: 45656 | I21: 리더MF1호 | J21: 8140 | R21: 4월2주 | S21: 40
B22: 45266 | C22: 1 | D22: 45397 | E22: 34 | F22: =7680/70*E22 -> 3730.2857 | G22: =F22/E22 -> 109.71429 | H22: 45297 | I22: 리더MF1호 | J22: 12210
B23: 45267 | C23: 2 | D23: 45399 | E23: 21 | F23: 1420 | G23: =F23/E23 -> 67.619048 | H23: 45300 | I23: 리더MF2호 | J23: 5040
B24: 45269 | C24: 3 | G24: =F24/E24 -> #DIV/0! | H24: 45304 | I24: 리더MF1호 | J24: 1610 | L24: =876 -> 876
B25: 45272 | C25: 1 | G25: =F25/E25 -> #DIV/0! | H25: 45306 | I25: 리더MF1호 | J25: 12200 | L25: =21/L24 -> 0.023972603
B26: 45274 | C26: 2 | E26: 168 | F26: =E26*55 -> 9240 | G26: =F26/E26 -> 55 | H26: 45311 | I26: 리더MF1호 | J26: 10210
B27: 45275 | C27: 168 | G27: =F27/E27 -> #DIV/0! | H27: 45318 | I27: 리더MF1호 | J27: 4990
B28: 45281 | C28: 2 | G28: =F28/E28 -> #DIV/0! | H28: 45322 | I28: 리더MF2호 | J28: 12200
B29: 45282 | C29: 2 | G29: =F29/E29 -> #DIV/0! | H29: 45325 | I29: 리더MF2호 | J29: 8100
B30: 45285 | C30: 4 | G30: =F30/E30 -> #DIV/0! | H30: 45330 | I30: 리더MF2호 | J30: 7140
B31: 45287 | C31: 1 | H31: 45336 | I31: 리더MF2호 | J31: 6100
B32: 45299 | C32: 1 | H32: 45336 | I32: 리더MF2호 | J32: 5050
B33: 45300 | C33: 2 | H33: 45341 | I33: 리더MF2호 | J33: 6100
B34: 45301 | C34: 2 | H34: 45345 | I34: 리더MF2호 | J34: 5030
B35: 45303 | C35: 1 | H35: 45345 | I35: 리더MF2호 | J35: 5070
B36: 45304 | C36: 1 | H36: 45350 | I36: 리더MF1호 | J36: 5070
B37: 45308 | C37: 2 | H37: 45352 | I37: 리더MF2호 | J37: 5060
B38: 45310 | C38: 1 | H38: 45352 | I38: 리더MF1호 | J38: 5010
B39: 45311 | C39: 3 | H39: 45369 | I39: 리더MF2호 | J39: 5080
B40: 45320 | C40: 1 | H40: 45376 | I40: 리더MF1호 | J40: 5030
B41: 45324 | C41: 2
B42: 45326 | C42: 2
...

Sheet 진일농장3(1220)
A1: 농장명 : | B1: 진일농장 | E1: =TODAY() -> 46325 | F1: =E1-B4 -> 1045
F2: 클레임적용 | O2: 클레임 | R2: 901
B3: 일자 | C3: 두수 | D3: 총체 | E3: 평체 | F3: 두수 | G3: 총체 | H3: 평체 | I3: 전입처 | J3: 출하예정일 | K3: 폐사두수 | L3: 총폐사율 | M3: 출하두수 | N3: 재고 | O3: 일자 | P3: 두수 | R3: =R2-Q4 -> 862
B4: 45280 | C4: 900 | D4: 22110 | E4: =D4/C4 -> 24.566667 | F4: =C8-P8 -> 873 | G4: =D8-(D8/C8*P8) -> 21446.7 | H4: =G4/F4 -> 24.566667 | I4: 익산 | J4: =B4+90 -> 45370 | K4: =C59 -> 69 | L4: =K8/F8 -> 0.079037801 | M4: =E59 -> 804 | N4: =F8-C59-E59 -> 0 | O4: 45280 | P4: 27 | Q4: =2+2+1+1+2+4+2+4+1+1+3+2+3+2+1+4+1+2+1 -> 39
J5: =B5+90 -> 90
B8: 계 | C8: =SUM(C4:C7) -> 900 | D8: =SUM(D4:D7) -> 22110 | E8: =D8/C8 -> 24.566667 | F8: =SUM(F4) -> 873 | G8: =SUM(G4) -> 21446.7 | H8: =G8/F8 -> 24.566667 | K8: =K4 -> 69 | L8: =L4 -> 0.079037801 | M8: =M4 -> 804 | N8: =N4 -> 0 | O8: =P8/C8 -> 0.03 | P8: =SUM(P4:P7) -> 27 | Q8: =P8-Q4 -> -12
G9: =18362+3100 -> 21462 | I9: =F8*0.95 -> 829.35
B10: 폐사내역 | D10: 출하내역 | H10: 사료내역 | K10: 사료 두당 섭취량 | N10: 특이사항 | R10: 출하예상
B11: 일자 | C11: 두수 | D11: 일자 | E11: 두수 | F11: 총체 | G11: 평체 | H11: 일자 | I11: 품목 | J11: 중량 | K11: 품목 | L11: 총중량 | M11: 두당 섭취량 | N11: 일자 | O11: 내용 | R11: 주차 | S11: 두수
B12: 45300 | C12: 2 | D12: 45372 | E12: 38 | F12: 4310 | G12: =F12/E12 -> 113.42105 | H12: 45647 | I12: 윈맥스S트랜스 | J12: =7100+2990 -> 10090 | K12: 윈맥스S트랜스 | L12: =SUMIF($I$12:$I$124,K12,$J$12:$J$124) -> 39190 | M12: =L12/$C$8 -> 43.544444 | N12: 45646 | O12: 써코전체접종 | R12: 3월4주 | S12: 38
B13: 45302 | C13: 3 | D13: 45378 | E13: 79 | F13: 8790 | G13: =F13/E13 -> 111.26582 | H13: 45655 | I13: 윈맥스S트랜스 | J13: 10070 | K13: 리더MF1호 | L13: =SUMIF($I$12:$I$124,K13,$J$12:$J$124) -> 49610 | M13: =L13/$C$8 -> 55.122222 | N13: 45321 | O13: 구제역접종 | R13: 3월5주 | S13: 79
B14: 45303 | C14: 2 | D14: 45385 | E14: 82 | F14: 9250 | G14: =F14/E14 -> 112.80488 | H14: 45300 | I14: 윈맥스S트랜스 | J14: 10000 | K14: 리더MF2호 | L14: 119330 | M14: 132.58889
B15: 45305 | C15: 1 | D15: 45390 | E15: 70 | F15: 8260 | G15: =F15/E15 -> 118 | H15: 45308 | I15: 윈맥스S트랜스 | J15: 9030 | K15: 프레쉬맥스제로육성돈 | L15: =SUMIF($I$12:$I$124,K15,$J$12:$J$124) -> 8680 | M15: =L15/$C$8 -> 9.6444444 | R15: 4월1주 | S15: 70
B16: 45307 | C16: 2 | D16: 45393 | E16: 60 | F16: 6920 | G16: =F16/E16 -> 115.33333 | H16: 45314 | I16: 리더MF1호 | J16: 10180 | K16: 총량 | L16: =SUM(L12:L15) -> 216810 | M16: =L16/C8 -> 240.9 | R16: 4월2주 | S16: 251
B17: 45308 | C17: 3 | D17: 45394 | E17: 60 | F17: 6930 | G17: =F17/E17 -> 115.5 | H17: 45321 | I17: 리더MF1호 | J17: 10130 | R17: 4월3주 | S17: 182
B18: 45309 | C18: 2 | D18: 45394 | E18: 61 | F18: 7050 | G18: =F18/E18 -> 115.57377 | H18: 45327 | I18: 리더MF1호 | J18: 10080 | R18: 4월4주 | S18: 82
B19: 45310 | C19: 1 | D19: 45397 | E19: 36 | F19: =7680/70*E19 -> 3949.7143 | G19: =F19/E19 -> 109.71429 | H19: 45330 | I19: 리더MF1호 | J19: 8110 | K19: 예상FCR | L19: =J59/((M8*G59)-(G9)) -> 3.1801725 | R19: 4월5주
B20: 45311 | C20: 4 | D20: 45399 | E20: 70 | F20: 7870 | G20: =F20/E20 -> 112.42857 | H20: 45336 | I20: 리더MF1호 | J20: 6150 | R20: 5월1주 | S20: 41
B21: 45314 | C21: 1 | D21: 45399 | E21: 76 | F21: =4160+4140 -> 8300 | G21: =F21/E21 -> 109.21053 | H21: 45341 | I21: 리더MF2호 | J21: 8120 | R21: 5월2주
B22: 45315 | C22: 2 | D22: 45405 | E22: 50 | F22: 5500 | G22: =F22/E22 -> 110 | H22: 45345 | I22: 리더MF2호 | J22: 10140 | R22: 5월3주 | S22: 28
B23: 45320 | C23: 1 | D23: 45407 | E23: 21 | F23: 1300 | G23: =F23/E23 -> 61.904762 | H23: 45349 | I23: 리더MF2호 | J23: 11240 | R23: 5월4주
B24: 45321 | C24: 1 | D24: 45407 | E24: 32 | F24: =6050/56*E24 -> 3457.1429 | G24: =F24/E24 -> 108.03571 | H24: 45353 | I24: 리더MF2호 | J24: 7660 | R24: 5월5주
B25: 45324 | C25: 2 | D25: 45414 | E25: 41 | F25: =4550/41*E25 -> 4550 | G25: =F25/E25 -> 110.97561 | H25: 45357 | I25: 리더MF2호 | J25: 10190
B26: 45326 | C26: 4 | D26: 45428 | E26: 28 | F26: =6630/58*E26 -> 3200.6897 | G26: =F26/E26 -> 114.31034 | H26: 45362 | I26: 리더MF2호 | J26: 10190
B27: 45328 | C27: 1 | G27: =F27/E27 -> #DIV/0! | H27: 45366 | I27: 리더MF2호 | J27: 12210
B28: 45329 | C28: 1 | G28: =F28/E28 -> #DIV/0! | H28: 45370 | I28: 리더MF2호 | J28: 15140
B29: 45332 | C29: 2 | G29: =F29/E29 -> #DIV/0! | H29: 45376 | I29: 리더MF2호 | J29: 12200
B30: 45334 | C30: 2 | G30: =F30/E30 -> #DIV/0! | H30: 45384 | I30: 리더MF1호 | J30: 4960
B31: 45335 | C31: 1 | H31: 45385 | I31: 리더MF2호 | J31: 5140
B32: 45338 | C32: 2 | H32: 45390 | I32: 프레쉬맥스제로육성돈 | J32: 5030
B33: 45342 | C33: 2 | H33: 45391 | I33: 리더MF2호 | J33: 10090
B34: 45343 | C34: 1 | H34: 45400 | I34: 프레쉬맥스제로육성돈 | J34: 3650
B35: 45344 | C35: 1 | H35: 45407 | I35: 리더MF2호 | J35: 2020
B36: 45346 | C36: 4 | H36: 45412 | I36: 리더MF2호 | J36: 4990
B37: 45350 | C37: 4
B38: 45353 | C38: 2
B39: 45356 | C39: 1
B40: 45375 | C40: 2
B41: 45380 | C41: 2
B42: 45383 | C42: 1
...

Sheet 진일농장2(0124)
A1: 농장명 : | B1: 진일농장(0124) | E1: =TODAY() -> 46325 | F1: =E1-B4 -> 1010
F2: 클레임적용 | O2: 클레임 | R2: 901
B3: 일자 | C3: 두수 | D3: 총체 | E3: 평체 | F3: 두수 | G3: 총체 | H3: 평체 | I3: 전입처 | J3: 출하예정일 | K3: 폐사두수 | L3: 총폐사율 | M3: 출하두수 | N3: 재고 | O3: 일자 | P3: 두수 | R3: =R2-Q4 -> 827
B4: 45315 | C4: 900 | D4: =4420+4750+4930+4220+4000 -> 22320 | E4: =D4/C4 -> 24.8 | F4: =C8-P8 -> 866 | G4: =D8-(D8/C8*P8) -> 21476.8 | H4: =G4/F4 -> 24.8 | I4: 익산 | J4: =B4+90 -> 45405 | K4: =C62 -> 147 | L4: =K8/F8 -> 0.16974596 | M4: =E62 -> 719 | N4: =F8-C62-E62 -> 0 | O4: 45315 | P4: 34 | Q4: =3+2+2+5+8+9+1+9+2+4+4+5+5+2+4+1+2+6 -> 74
J5: =B5+90 -> 90
B8: 계 | C8: =SUM(C4:C7) -> 900 | D8: =SUM(D4:D7) -> 22320 | E8: =D8/C8 -> 24.8 | F8: =SUM(F4) -> 866 | G8: =SUM(G4) -> 21476.8 | H8: =G8/F8 -> 24.8 | K8: =K4 -> 147 | L8: =L4 -> 0.16974596 | M8: =M4 -> 719 | N8: =N4 -> 0 | O8: =P8/C8 -> 0.037777778 | P8: =SUM(P4:P7) -> 34 | Q8: =P8-Q4 -> -40
G9: 21484 | I9: =F8*0.834 -> 722.244
B10: 폐사내역 | D10: 출하내역 | H10: 사료내역 | K10: 사료 두당 섭취량 | N10: 특이사항 | R10: 출하예상
B11: 일자 | C11: 두수 | D11: 일자 | E11: 두수 | F11: 총체 | G11: 평체 | H11: 일자 | I11: 품목 | J11: 중량 | K11: 품목 | L11: 총중량 | M11: 두당 섭취량 | N11: 일자 | O11: 내용 | R11: 주차 | S11: 두수
B12: 45322 | C12: 5 | D12: 45405 | E12: 51 | F12: 5500 | G12: =F12/E12 -> 107.84314 | H12: 45323 | I12: 윈맥스S트랜스 | J12: 10130 | K12: 윈맥스S트랜스 | L12: =SUMIF($I$12:$I$127,K12,$J$12:$J$127) -> 29970 | M12: =L12/$C$8 -> 33.3 | N12: 45315 | O12: 써코전체접종 | R12: 4월4주 | S12: 75
B13: 45323 | C13: 5 | D13: 45407 | E13: 24 | F13: =6050/56*E13 -> 2592.8571 | G13: =F13/E13 -> 108.03571 | H13: 45336 | I13: 리더MF1호 | J13: 5480 | K13: 리더MF1호 | L13: =SUMIF($I$12:$I$127,K13,$J$12:$J$127) -> 109310 | M13: =L13/$C$8 -> 121.45556 | N13: 45385 | O13: 구제역접종 | R13: 4월5주
B14: 45324 | C14: 1 | D14: 45421 | E14: 61 | F14: 6810 | G14: =F14/E14 -> 111.63934 | H14: 45342 | I14: 리더MF1호 | J14: 15130 | K14: 리더MF2호 | L14: =SUMIF($I$12:$I$127,K14,$J$12:$J$127) -> 30170 | M14: =L14/$C$8 -> 33.522222 | R14: 5월1주
B15: 45326 | C15: 9 | D15: 45428 | E15: 70 | F15: 7920 | G15: =F15/E15 -> 113.14286 | H15: 45350 | I15: 리더MF1호 | J15: 10170 | K15: 프레쉬맥스제로육성돈 | L15: =SUMIF($I$12:$I$127,K15,$J$12:$J$127) -> 60940 | M15: =L15/$C$8 -> 67.711111 | R15: 5월2주 | S15: 61
B16: 45328 | C16: 4 | D16: 45435 | E16: 72 | F16: 8090 | G16: =F16/E16 -> 112.36111 | H16: 45357 | I16: 리더MF1호 | J16: 15240 | K16: 총량 | L16: =SUM(L12:L15) -> 230390 | M16: =L16/C8 -> 255.98889 | R16: 5월3주 | S16: 70
B17: 45329 | C17: 5 | D17: 45435 | E17: 31 | F17: 3650 | G17: =F17/E17 -> 117.74194 | H17: 45363 | I17: 리더MF1호 | J17: 8120 | R17: 5월4주 | S17: 173
B18: 45331 | C18: 6 | D18: 45435 | E18: 70 | F18: 8130 | G18: =F18/E18 -> 116.14286 | H18: 45363 | I18: 윈맥스S트랜스 | J18: 5990 | R18: 5월5주 | S18: 125
B19: 45334 | C19: 2 | D19: 45440 | E19: 60 | F19: 6610 | G19: =F19/E19 -> 110.16667 | H19: 45369 | I19: 리더MF1호 | J19: 10190 | K19: 예상FCR | L19: =(J62/I9)/(G62-H8) -> 3.6958668 | R19: 6월1주
B20: 45335 | C20: 7 | D20: 45440 | E20: 60 | F20: 6560 | G20: =F20/E20 -> 109.33333 | H20: 45374 | I20: 리더MF1호 | J20: 12100 | R20: 6월2주 | S20: 70
B21: 45337 | C21: 2 | D21: 45450 | E21: 61 | F21: 6740 | G21: =F21/E21 -> 110.4918 | H21: 45383 | I21: 프레쉬맥스제로육성돈 | J21: 9150 | R21: 6월3주 | S21: 70
B22: 45338 | C22: 4 | D22: 45450 | E22: 60 | F22: 6490 | G22: =F22/E22 -> 108.16667 | H22: 45388 | I22: 리더MF1호 | J22: 10080 | R22: 6월4주 | S22: 70
B23: 45340 | C23: 2 | D23: 45456 | E23: 41 | F23: 4470 | G23: =F23/E23 -> 109.02439 | H23: 45391 | I23: 리더MF1호 | J23: 5030 | R23: 7월1주 | S23: 35
B24: 45341 | C24: 4 | D24: 45457 | E24: 29 | F24: 3180 | G24: =F24/E24 -> 109.65517 | H24: 45397 | I24: 프레쉬맥스제로육성돈 | J24: 7980
B25: 45344 | C25: 1 | D25: 45474 | E25: 21 | F25: 2260 | G25: =F25/E25 -> 107.61905 | H25: 45400 | I25: 프레쉬맥스제로육성돈 | J25: 6990
B26: 45346 | C26: 6 | D26: 45495 | E26: 8 | F26: =7970/72*E26 -> 885.55556 | G26: =F26/E26 -> 110.69444 | H26: 45404 | I26: 리더MF2호 | J26: 10050
B27: 45348 | C27: 3 | H27: 45411 | I27: 리더MF2호 | J27: 10080
B28: 45349 | C28: 2 | H28: 45416 | I28: 리더MF2호 | J28: 10040
B29: 45350 | C29: 4 | H29: 45421 | I29: 프레쉬맥스제로육성돈 | J29: 12360
B30: 45351 | C30: 1 | H30: 45427 | I30: 프레쉬맥스제로육성돈 | J30: 15050
B31: 45353 | C31: 7 | H31: 45432 | I31: 프레쉬맥스제로육성돈 | J31: 4430
B32: 45356 | C32: 1 | H32: 45439 | I32: 프레쉬맥스제로육성돈 | J32: 4980
B33: 45361 | C33: 4 | H33: 45446 | I33: 리더MF1호 | J33: 2650
B34: 45362 | C34: 3 | H34: 45447 | I34: 윈맥스S트랜스 | J34: 3010
B35: 45364 | C35: 1 | H35: 45450 | I35: 윈맥스S트랜스 | J35: 10000
B36: 45369 | C36: 2 | H36: 45370 | I36: 윈맥스S트랜스 | J36: 840
B37: 45375 | C37: 3 | H37: 45469 | I37: 리더MF1호 | J37: 5040
B38: 45383 | C38: 1 | H38: 45475 | I38: 리더MF1호 | J38: 5060
B39: 45392 | C39: 1 | H39: 45490 | I39: 리더MF1호 | J39: 5020
B40: 45394 | C40: 1
B41: 45398 | C41: 2
B42: 45399 | C42: 6
...

Sheet 진일농장4(0215)
A1: 농장명 : | E1: =TODAY() -> 46325 | F1: =E1-B4 -> 988
F2: 클레임적용 | O2: 클레임 | R2: 910
B3: 일자 | C3: 두수 | D3: 총체 | E3: 평체 | F3: 두수 | G3: 총체 | H3: 평체 | I3: 전입처 | J3: 출하예정일 | K3: 폐사두수 | L3: 총폐사율 | M3: 출하두수 | N3: 재고 | O3: 일자 | P3: 두수 | R3: =R2-Q4 -> 901
B4: 45337 | C4: 910 | D4: =6670+7370+7080+6940+7280 -> 35340 | E4: =D4/C4 -> 38.835165 | F4: =C8-P8 -> 906 | G4: =D8-(D8/C8*P8) -> 35184.659 | H4: =G4/F4 -> 38.835165 | I4: 외부 | J4: =B4+90 -> 45427 | K4: =C63 -> 165 | L4: =K8/F8 -> 0.18211921 | M4: =E63 -> 741 | N4: =F8-C63-E63 -> 0 | O4: 45337 | P4: 4 | Q4: =2+3+2+2 -> 9
J5: =B5+90 -> 90
B8: 계 | C8: =SUM(C4:C7) -> 910 | D8: =SUM(D4:D7) -> 35340 | E8: =D8/C8 -> 38.835165 | F8: =SUM(F4) -> 906 | G8: =SUM(G4) -> 35184.659 | H8: =G8/F8 -> 38.835165 | K8: =K4 -> 165 | L8: =L4 -> 0.18211921 | M8: =M4 -> 741 | N8: =N4 -> 0 | O8: =P8/C8 -> 0.0043956044 | P8: =SUM(P4:P7) -> 4 | Q8: =P8-Q4 -> -5
G9: 35188 | I9: =F8*0.818 -> 741.108
B10: 폐사내역 | D10: 출하내역 | H10: 사료내역 | K10: 사료 두당 섭취량 | N10: 특이사항 | R10: 출하예상
B11: 일자 | C11: 두수 | D11: 일자 | E11: 두수 | F11: 총체 | G11: 평체 | H11: 일자 | I11: 품목 | J11: 중량 | K11: 품목 | L11: 총중량 | M11: 두당 섭취량 | N11: 일자 | O11: 내용 | R11: 주차 | S11: 두수
B12: 45347 | C12: 5 | D12: 45421 | E12: 36 | F12: 4010 | G12: =F12/E12 -> 111.38889 | H12: 45337 | I12: 윈맥스S트랜스 | J12: 9850 | K12: 윈맥스S트랜스 | L12: =SUMIF($I$12:$I$128,K12,$J$12:$J$128) -> 77130 | M12: =L12/$C$8 -> 84.758242 | R12: 5월2주 | S12: 36
B13: 45348 | C13: 1 | D13: 45428 | E13: 30 | F13: =6630/58*E13 -> 3429.3103 | G13: =F13/E13 -> 114.31034 | H13: 45345 | I13: 윈맥스S트랜스 | J13: 9830 | K13: 리더MF1호 | L13: =SUMIF($I$12:$I$128,K13,$J$12:$J$128) -> 0 | M13: =L13/$C$8 -> 0 | R13: 5월3주 | S13: 30
B14: 45351 | C14: 1 | D14: 45434 | E14: 60 | F14: 6920 | G14: =F14/E14 -> 115.33333 | H14: 45351 | I14: 윈맥스S트랜스 | J14: 9820 | K14: 리더MF2호 | L14: =SUMIF($I$12:$I$128,K14,$J$12:$J$128) -> 32210 | M14: =L14/$C$8 -> 35.395604 | R14: 5월4주 | S14: 60
B15: 45354 | C15: 2 | D15: 45441 | E15: 65 | F15: 7390 | G15: =F15/E15 -> 113.69231 | H15: 45357 | I15: 윈맥스S트랜스 | J15: 4960 | K15: 프레쉬맥스제로육성돈 | L15: =SUMIF($I$12:$I$128,K15,$J$12:$J$128) -> 72240 | M15: =L15/$C$8 -> 79.384615 | R15: 5월5주 | S15: 131
B16: 45355 | C16: 1 | D16: 45441 | E16: 66 | F16: 7550 | G16: =F16/E16 -> 114.39394 | H16: 45362 | I16: 윈맥스S트랜스 | J16: 5040 | K16: 총량 | L16: =SUM(L12:L15) -> 181580 | M16: =L16/C8 -> 199.53846 | R16: 6월1주 | S16: 121
B17: 45361 | C17: 3 | D17: 45446 | E17: 61 | F17: 7010 | G17: =F17/E17 -> 114.91803 | H17: 45366 | I17: 윈맥스S트랜스 | J17: 2850 | R17: 6월2주 | S17: 70
B18: 45362 | C18: 4 | D18: 45446 | E18: 60 | F18: 6840 | G18: =F18/E18 -> 114 | H18: 45370 | I18: 윈맥스S트랜스 | J18: 9840 | R18: 6월3주 | S18: 120
B19: 45363 | C19: 2 | D19: 45453 | E19: 60 | F19: 7050 | G19: =F19/E19 -> 117.5 | H19: 45376 | I19: 윈맥스S트랜스 | J19: 9900 | K19: 예상FCR | L19: =(J63/I9)/(G63-H8) -> 3.27877 | R19: 6월4주 | S19: 60
B20: 45364 | C20: 6 | D20: 45453 | E20: 60 | F20: 6950 | G20: =F20/E20 -> 115.83333 | H20: 45384 | I20: 프레쉬맥스제로육성돈 | J20: 9970 | R20: 7월1주 | S20: 40
B21: 45365 | C21: 5 | D21: 45455 | E21: 53 | F21: 6220 | G21: =F21/E21 -> 117.35849 | H21: 45388 | I21: 프레쉬맥스제로육성돈 | J21: 5330 | R21: 7월2주
B22: 45367 | C22: 2 | D22: 45456 | E22: 40 | F22: 4690 | G22: =F22/E22 -> 117.25 | H22: 45391 | I22: 프레쉬맥스제로육성돈 | J22: 4990
B23: 45369 | C23: 2 | D23: 45460 | E23: 50 | F23: 5660 | G23: =F23/E23 -> 113.2 | H23: 45397 | I23: 프레쉬맥스제로육성돈 | J23: 10420
B24: 45371 | C24: 6 | D24: 45460 | E24: 47 | F24: 5140 | G24: =F24/E24 -> 109.3617 | H24: 45402 | I24: 프레쉬맥스제로육성돈 | J24: 10060
B25: 45372 | C25: 4 | D25: 45463 | E25: 36 | F25: 4040 | G25: =F25/E25 -> 112.22222 | H25: 45407 | I25: 리더MF2호 | J25: 5020
B26: 45375 | C26: 7 | D26: 45484 | E26: 17 | F26: 1250 | G26: =F26/E26 -> 73.529412 | H26: 45409 | I26: 리더MF2호 | J26: 10060
B27: 45376 | C27: 6 | G27: =F27/E27 -> #DIV/0! | H27: 45413 | I27: 리더MF2호 | J27: 10070
B28: 45377 | C28: 7 | G28: =F28/E28 -> #DIV/0! | H28: 45416 | I28: 프레쉬맥스제로육성돈 | J28: 4610
B29: 45380 | C29: 4 | G29: =F29/E29 -> #DIV/0! | H29: 45418 | I29: 프레쉬맥스제로육성돈 | J29: 6430
B30: 45383 | C30: 4 | G30: =F30/E30 -> #DIV/0! | H30: 45425 | I30: 리더MF2호 | J30: 7060
B31: 45384 | C31: 4 | H31: 45430 | I31: 프레쉬맥스제로육성돈 | J31: 10380
B32: 45385 | C32: 2 | H32: 45436 | I32: 프레쉬맥스제로육성돈 | J32: 10050
B33: 45386 | C33: 2 | H33: 45441 | I33: 윈맥스S트랜스 | J33: 10010
B34: 45389 | C34: 2 | H34: 45450 | I34: 윈맥스S트랜스 | J34: 5030
B35: 45390 | C35: 1
B36: 45392 | C36: 4
B37: 45393 | C37: 1
B38: 45394 | C38: 1
B39: 45398 | C39: 2
B40: 45399 | C40: 7
B41: 45400 | C41: 1
B42: 45403 | C42: 2
...

Sheet 진일농장3(0327)
A1: 농장명 : | E1: =TODAY() -> 46325 | F1: =E1-B4 -> 947
F2: 클레임적용 | O2: 클레임 | R2: 901
B3: 일자 | C3: 두수 | D3: 총체 | E3: 평체 | F3: 두수 | G3: 총체 | H3: 평체 | I3: 전입처 | J3: 출하예정일 | K3: 폐사두수 | L3: 총폐사율 | M3: 출하두수 | N3: 재고 | O3: 일자 | P3: 두수 | R3: =R2-Q4 -> 874
B4: 45378 | C4: 901 | D4: 34030 | E4: =D4/C4 -> 37.769145 | F4: =C8-P8 -> 879 | G4: =D8-(D8/C8*P8) -> 33199.079 | H4: =G4/F4 -> 37.769145 | I4: 익산 | J4: =B4+90 -> 45468 | K4: =C59 -> 42 | L4: =K8/F8 -> 0.04778157 | M4: =E59 -> 837 | N4: =F8-C59-E59 -> 0 | O4: 45378 | P4: 22 | Q4: 27
J5: =B5+90 -> 90
B8: 계 | C8: =SUM(C4:C7) -> 901 | D8: =SUM(D4:D7) -> 34030 | E8: =D8/C8 -> 37.769145 | F8: =SUM(F4) -> 879 | G8: =SUM(G4) -> 33199.079 | H8: =G8/F8 -> 37.769145 | K8: =K4 -> 42 | L8: =L4 -> 0.04778157 | M8: =M4 -> 837 | N8: =N4 -> 0 | O8: =P8/C8 -> 0.024417314 | P8: =SUM(P4:P7) -> 22 | Q8: =P8-Q4 -> -5
G9: 33216 | I9: =F8*0.95 -> 835.05
B10: 폐사내역 | D10: 출하내역 | H10: 사료내역 | K10: 사료 두당 섭취량 | N10: 특이사항 | R10: 출하예상 | U10: 실출하
B11: 일자 | C11: 두수 | D11: 일자 | E11: 두수 | F11: 총체 | G11: 평체 | H11: 일자 | I11: 품목 | J11: 중량 | K11: 품목 | L11: 총중량 | M11: 두당 섭취량 | N11: 일자 | O11: 내용 | R11: 주차 | S11: 두수 | U11: 주차 | V11: 두수
B12: 45409 | C12: 3 | D12: 45455 | E12: 24 | F12: 2700 | G12: =F12/E12 -> 112.5 | H12: 45379 | I12: 윈맥스S트랜스 | J12: 7820 | K12: 윈맥스S트랜스 | L12: =SUMIF($I$12:$I$124,K12,$J$12:$J$124) -> 88330 | M12: =L12/$C$8 -> 98.035516 | N12: 45400 | O12: 플로르페니콜 전체주사 | R12: 6월2주 | S12: 24 | U12: 6월2주 | V12: 24
B13: 45418 | C13: 2 | D13: 45463 | E13: 45 | F13: 5030 | G13: =F13/E13 -> 111.77778 | H13: 45385 | I13: 윈맥스S트랜스 | J13: 9860 | K13: 리더MF1호 | L13: =SUMIF($I$12:$I$124,K13,$J$12:$J$124) -> 36330 | M13: =L13/$C$8 -> 40.321865 | R13: 6월3주 | S13: 45 | U13: 6월3주 | V13: 45
B14: 45421 | C14: 1 | D14: 45470 | E14: 44 | F14: 5050 | G14: =F14/E14 -> 114.77273 | H14: 45391 | I14: 윈맥스S트랜스 | J14: 8030 | K14: 리더MF2호 | L14: =SUMIF($I$12:$I$124,K14,$J$12:$J$124) -> 29160 | M14: =L14/$C$8 -> 32.36404 | R14: 6월4주 | S14: 100 | U14: 6월4주 | V14: 107
B15: 45424 | C15: 3 | D15: 45470 | E15: 63 | F15: 7000 | G15: =F15/E15 -> 111.11111 | H15: 45397 | I15: 윈맥스S트랜스 | J15: 4900 | K15: 프레쉬맥스제로육성돈 | L15: =SUMIF($I$12:$I$124,K15,$J$12:$J$124) -> 40130 | M15: =L15/$C$8 -> 44.539401 | R15: 7월1주 | S15: 120 | U15: 7월1주 | V15: 116
B16: 45432 | C16: 1 | D16: 45474 | E16: 70 | F16: 7740 | G16: =F16/E16 -> 110.57143 | H16: 45400 | I16: 윈맥스S트랜스 | J16: 4890 | K16: 총량 | L16: =SUM(L12:L15) -> 193950 | M16: =L16/C8 -> 215.26082 | R16: 7월2주 | S16: 100 | U16: 7월2주 | V16: 128
B17: 45434 | C17: 2 | D17: 45477 | E17: 46 | F17: 5090 | G17: =F17/E17 -> 110.65217 | H17: 45405 | I17: 프레쉬맥스제로육성돈 | J17: 11040 | R17: 7월3주 | S17: 120 | U17: 7월3주 | V17: 106
B18: 45440 | C18: 1 | D18: 45483 | E18: 56 | F18: 6240 | G18: =F18/E18 -> 111.42857 | H18: 45411 | I18: 리더MF1호 | J18: 5010 | R18: 7월4주 | S18: 50 | U18: 7월4주 | V18: 194
B19: 45442 | C19: 1 | D19: 45483 | E19: 72 | F19: 8010 | G19: =F19/E19 -> 111.25 | H19: 45412 | I19: 리더MF1호 | J19: 5040 | K19: 예상FCR | L19: =(J59/I9)/(G59-H8) -> 3.1579179 | R19: 7월5주 | U19: 7월5주 | V19: 70
B20: 45443 | C20: 1 | D20: 45490 | E20: 52 | F20: 5990 | G20: =F20/E20 -> 115.19231 | H20: 45415 | I20: 프레쉬맥스제로육성돈 | J20: 8020 | K20: 평균일당사료섭취량 | L20: =J35/419/7 -> 2.7378111 | R20: 8월1주 | S20: 120 | U20: 8월1주
B21: 45445 | C21: 2 | D21: 45490 | E21: 54 | F21: 6130 | G21: =F21/E21 -> 113.51852 | H21: 45420 | I21: 리더MF1호 | J21: 12110 | R21: 8월2주 | S21: 60 | U21: 8월2주
B22: 45446 | C22: 1 | D22: 45495 | E22: 64 | F22: =7970/72*E22 -> 7084.4444 | G22: =F22/E22 -> 110.69444 | H22: 45370 | I22: 윈맥스S트랜스 | J22: 840 | R22: 8월3주 | S22: 20 | U22: 8월3주 | V22: 40
B23: 45448 | C23: 1 | D23: 45495 | E23: 70 | F23: 7840 | G23: =F23/E23 -> 112 | H23: 45429 | I23: 프레쉬맥스제로육성돈 | J23: 7990 | R23: 8월4주 | U23: 8월4주
B24: 45450 | C24: 2 | D24: 45499 | E24: 61 | F24: 6860 | G24: =F24/E24 -> 112.45902 | H24: 45433 | I24: 리더MF1호 | J24: 6080 | R24: 8월5주 | U24: 8월5주
B25: 45452 | C25: 3 | D25: 45503 | E25: 51 | F25: 5480 | G25: =F25/E25 -> 107.45098 | H25: 45433 | I25: 리더MF2호 | J25: 6050
B26: 45455 | C26: 1 | D26: 45511 | E26: 40 | F26: 4290 | G26: =F26/E26 -> 107.25 | H26: 45439 | I26: 리더MF2호 | J26: 12080 | L26: =L16-185860 -> 8090
B27: 45457 | C27: 1 | D27: 45518 | E27: 22 | F27: 2310 | G27: =F27/E27 -> 105
B28: 45460 | C28: 3 | D28: 45525 | E28: 3 | F28: =2740/25*E28 -> 328.8 | G28: =F28/E28 -> 109.6 | H28: 45444 | I28: 리더MF2호 | J28: 3000
B29: 45461 | C29: 1 | H29: 45447 | I29: 윈맥스S트랜스 | J29: 10060
B30: 45463 | C30: 2 | H30: 45453 | I30: 윈맥스S트랜스 | J30: 14940
B31: 45466 | C31: 1 | H31: 45460 | I31: 윈맥스S트랜스 | J31: 12000
B32: 45467 | C32: 2 | H32: 45465 | I32: 윈맥스S트랜스 | J32: 14990
B33: 45470 | C33: 1 | H33: 45474 | I33: 프레쉬맥스제로육성돈 | J33: 7030
B34: 45475 | C34: 1 | H34: 45476 | I34: 프레쉬맥스제로육성돈 | J34: 6050
B35: 45489 | C35: 2 | H35: 45484 | I35: 리더MF2호 | J35: 8030
B36: 45494 | C36: 1 | H36: 45502 | I36: 리더MF1호 | J36: 5020
B37: 45515 | C37: 2 | H37: 45521 | I37: 리더MF1호 | J37: 3070
C59: =SUM(C12:C58) -> 42 | E59: =SUM(E12:E58) -> 837 | F59: =SUM(F12:F58) -> 93173.244 | G59: =F59/E59 -> 111.31809 | J59: =SUM(J12:J58) -> 193950
D65: 1월1주 | E65: 60
D66: 1월2주 | E66: 120
D67: 1월3주 | E67: 180
D68: 1월4주 | E68: 180
...

Sheet 진일농장2(0424)
A1: 농장명 : | E1: =TODAY() -> 46325 | F1: =E1-B4 -> 919
F2: 클레임적용 | O2: 클레임 | R2: 901
B3: 일자 | C3: 두수 | D3: 총체 | E3: 평체 | F3: 두수 | G3: 총체 | H3: 평체 | I3: 전입처 | J3: 출하예정일 | K3: 폐사두수 | L3: 총폐사율 | M3: 출하두수 | N3: 재고 | O3: 일자 | P3: 두수 | R3: =R2-Q4 -> 887
B4: 45406 | C4: 900 | D4: =4090+4380+3610+3650+4070 -> 19800 | E4: =D4/C4 -> 22 | F4: =C8-P8 -> 889 | G4: =D8-(D8/C8*P8) -> 19558 | H4: =G4/F4 -> 22 | I4: 오케이 | J4: =B4+90 -> 45496 | K4: =C59 -> 56 | L4: =K8/F8 -> 0.062992126 | M4: =E59 -> 833 | N4: =F8-C59-E59 -> 0 | O4: 45406 | P4: 11 | Q4: 14
J5: =B5+90 -> 90
B8: 계 | C8: =SUM(C4:C7) -> 900 | D8: =SUM(D4:D7) -> 19800 | E8: =D8/C8 -> 22 | F8: =SUM(F4) -> 889 | G8: =SUM(G4) -> 19558 | H8: =G8/F8 -> 22 | K8: =K4 -> 56 | L8: =L4 -> 0.062992126 | M8: =M4 -> 833 | N8: =N4 -> 0 | O8: =P8/C8 -> 0.012222222 | P8: =SUM(P4:P7) -> 11 | Q8: =P8-Q4 -> -3
G9: 19558 | I9: =F8*0.95 -> 844.55
B10: 폐사내역 | D10: 출하내역 | H10: 사료내역 | K10: 사료 두당 섭취량 | N10: 특이사항 | R10: 출하예상 | U10: 출하예상
B11: 일자 | C11: 두수 | D11: 일자 | E11: 두수 | F11: 총체 | G11: 평체 | H11: 일자 | I11: 품목 | J11: 중량 | K11: 품목 | L11: 총중량 | M11: 두당 섭취량 | N11: 일자 | O11: 내용 | R11: 주차 | S11: 두수 | U11: 주차 | V11: 두수
B12: 45412 | C12: 1 | D12: 45511 | E12: 22 | F12: 2330 | G12: =F12/E12 -> 105.90909 | H12: 45407 | I12: 윈맥스S트랜스 | J12: 8050 | K12: 윈맥스S트랜스 | L12: =SUMIF($I$12:$I$124,K12,$J$12:$J$124) -> 120680 | M12: =L12/$C$8 -> 134.08889 | N12: 45461 | O12: 구제역 | R12: 7월5주 | S12: 50 | U12: 7월5주
B13: 45436 | C13: 1 | D13: 45518 | E13: 21 | F13: 2250 | G13: =F13/E13 -> 107.14286 | H13: 45415 | I13: 윈맥스S트랜스 | J13: 6870 | K13: 리더MF1호 | L13: =SUMIF($I$12:$I$124,K13,$J$12:$J$124) -> 17100 | M13: =L13/$C$8 -> 19 | R13: 8월1주 | U13: 8월1주
B14: 45438 | C14: 2 | D14: 45524 | E14: 19 | F14: 1430 | G14: =F14/E14 -> 75.263158 | H14: 45421 | I14: 윈맥스S트랜스 | J14: 10000 | K14: 리더MF2호 | L14: =SUMIF($I$12:$I$124,K14,$J$12:$J$124) -> 15480 | M14: =L14/$C$8 -> 17.2 | R14: 8월2주 | S14: 80 | U14: 8월2주 | V14: 22
B15: 45440 | C15: 2 | D15: 45525 | E15: 22 | F15: =2740/25*E15 -> 2411.2 | G15: =F15/E15 -> 109.6 | H15: 45429 | I15: 윈맥스S트랜스 | J15: 7000 | K15: 프레쉬맥스제로육성돈 | L15: =SUMIF($I$12:$I$124,K15,$J$12:$J$124) -> 66430 | M15: =L15/$C$8 -> 73.811111 | R15: 8월3주 | S15: 130 | U15: 8월3주 | V15: 21
B16: 45441 | C16: 3 | D16: 45531 | E16: 32 | F16: 3460 | G16: =F16/E16 -> 108.125 | H16: 45436 | I16: 윈맥스S트랜스 | J16: 4080 | K16: 총량 | L16: =SUM(L12:L15) -> 219690 | M16: =L16/F8 -> 247.12036 | R16: 8월4주 | S16: 130 | U16: 8월4주 | V16: 41
B17: 45442 | C17: 1 | D17: 45531 | E17: 31 | F17: 3470 | G17: =F17/E17 -> 111.93548 | H17: 45439 | I17: 윈맥스S트랜스 | J17: 3050 | R17: 8월5주 | S17: 120 | U17: 8월5주 | V17: 280
B18: 45445 | C18: 3 | D18: 45533 | E18: 61 | F18: 6170 | G18: =F18/E18 -> 101.14754 | H18: 45442 | I18: 프레쉬맥스제로육성돈 | J18: 10040 | R18: 9월1주 | S18: 80 | U18: 9월1주 | V18: 300
B19: 45446 | C19: 1 | D19: 45533 | E19: 59 | F19: 6150 | G19: =F19/E19 -> 104.23729 | H19: 45450 | I19: 프레쉬맥스제로육성돈 | J19: 9040 | K19: 예상FCR | L19: =(J59/I9)/(105.5-H8) -> 3.1152898 | R19: 9월2주 | S19: 120 | U19: 9월2주
B20: 45447 | C20: 2 | D20: 45534 | E20: 60 | F20: 6370 | G20: =F20/E20 -> 106.16667 | H20: 45457 | I20: 프레쉬맥스제로육성돈 | J20: 10090 | K20: 평균일당사료섭취량 | L20: =J40/(H40-H39)/N8 -> #DIV/0! | R20: 9월3주 | S20: 80 | U20: 9월3주 | V20: 50
B21: 45457 | C21: 1 | D21: 45534 | E21: 60 | F21: 6370 | G21: =F21/E21 -> 106.16667 | H21: 45463 | I21: 프레쉬맥스제로육성돈 | J21: 15110 | R21: 9월4주 | S21: 20 | U21: 9월4주
B22: 45460 | C22: 1 | D22: 45537 | E22: 45 | F22: 4850 | G22: =F22/E22 -> 107.77778 | H22: 45470 | I22: 프레쉬맥스제로육성돈 | J22: 8040 | R22: 9월5주 | U22: 9월5주
B23: 45461 | C23: 1 | D23: 45537 | E23: 44 | F23: 4960 | G23: =F23/E23 -> 112.72727 | H23: 45474 | I23: 프레쉬맥스제로육성돈 | J23: 8060 | R23: 10월1주 | S23: 20 | U23: 10월1주 | V23: 30
B24: 45462 | C24: 1 | D24: 45539 | E24: 63 | F24: 6390 | G24: =F24/E24 -> 101.42857 | H24: 45476 | I24: 프레쉬맥스제로육성돈 | J24: 6050 | R24: 10월1주 | U24: 10월1주
B25: 45463 | C25: 1 | D25: 45539 | E25: 28 | F25: 2800 | G25: =F25/E25 -> 100 | H25: 45482 | I25: 리더MF2호 | J25: 9420
B26: 45467 | C26: 1 | D26: 45539 | E26: 22 | F26: 2230 | G26: =F26/E26 -> 101.36364 | H26: 45490 | I26: 윈맥스S트랜스 | J26: 5000
B27: 45469 | C27: 1 | D27: 45545 | E27: 51 | F27: 5210 | G27: =F27/E27 -> 102.15686 | H27: 45493 | I27: 윈맥스S트랜스 | J27: 5930
B28: 45476 | C28: 1 | D28: 45561 | E28: 82 | F28: 8880 | G28: =F28/E28 -> 108.29268 | H28: 45497 | I28: 윈맥스S트랜스 | J28: 5930
B29: 45478 | C29: 2 | D29: 45575 | E29: 58 | F29: 6370 | G29: =F29/E29 -> 109.82759 | H29: 45500 | I29: 윈맥스S트랜스 | J29: 5900
B30: 45480 | C30: 1 | D30: 45579 | E30: 46 | F30: 5330 | G30: =F30/E30 -> 115.86957 | H30: 45505 | I30: 윈맥스S트랜스 | J30: 4930
B31: 45483 | C31: 2 | D31: 45587 | E31: 7 | F31: =5700/50*E31 -> 798 | G31: =F31/E31 -> 114 | H31: 45507 | I31: 리더MF2호 | J31: 6060
B32: 45490 | C32: 5 | H32: 45509 | I32: 윈맥스S트랜스 | J32: 5900
B33: 45491 | C33: 3 | H33: 45510 | I33: 윈맥스S트랜스 | J33: 9960
A34: 폭염 | B34: 45496 | C34: 7 | H34: 45517 | I34: 윈맥스S트랜스 | J34: 4900
B35: 45540 | C35: 4 | H35: 45520 | I35: 윈맥스S트랜스 | J35: 7900
B36: 45552 | C36: 3 | H36: 45527 | I36: 윈맥스S트랜스 | J36: 9870
B37: 45564 | C37: 1 | H37: 45531 | I37: 윈맥스S트랜스 | J37: 10210
B38: 45571 | C38: 3 | H38: 45534 | I38: 윈맥스S트랜스 | J38: 5200
C39: 1 | H39: 45545 | I39: 리더MF1호 | J39: 5000
H40: 45549 | I40: 리더MF1호 | J40: 3060
H41: 45554 | I41: 리더MF1호 | J41: 3040
H42: 45567 | I42: 리더MF1호 | J42: 3980
...

Sheet 진일농장4(0602)
A1: 농장명 : | E1: =TODAY() -> 46325 | F1: =E1-B4 -> 880 | J1: =M16/F1 -> 0.26296306
F2: 클레임적용 | O2: 클레임 | R2: 900
B3: 일자 | C3: 두수 | D3: 총체 | E3: 평체 | F3: 두수 | G3: 총체 | H3: 평체 | I3: 전입처 | J3: 출하예정일 | K3: 폐사두수 | L3: 총폐사율 | M3: 출하두수 | N3: 재고 | O3: 일자 | P3: 두수 | R3: =R2-Q4 -> 882
B4: 45445 | C4: 900 | D4: =4510+4330+4190+3990+4070 -> 21090 | E4: =D4/C4 -> 23.433333 | F4: =C8-P8 -> 881 | G4: =D8-(D8/C8*P8) -> 20644.767 | H4: =G4/F4 -> 23.433333 | I4: 돈앤돈 | J4: =B4+90 -> 45535 | K4: =C59 -> 85 | L4: =K8/F8 -> 0.096481271 | M4: =E59 -> 796 | N4: =F8-C59-E59 -> 0 | O4: 45445 | P4: 19 | Q4: 18
J5: =B5+90 -> 90
B8: 계 | C8: =SUM(C4:C7) -> 900 | D8: =SUM(D4:D7) -> 21090 | E8: =D8/C8 -> 23.433333 | F8: =SUM(F4) -> 881 | G8: =SUM(G4) -> 20644.767 | H8: =G8/F8 -> 23.433333 | K8: =K4 -> 85 | L8: =L4 -> 0.096481271 | M8: =M4 -> 796 | N8: =N4 -> 0 | O8: =P8/C8 -> 0.021111111 | P8: =SUM(P4:P7) -> 19 | Q8: =P8-Q4 -> 1
G9: 20653 | I9: =F8*0.95 -> 836.95 | K9: =796+41 -> 837
B10: 폐사내역 | D10: 출하내역 | H10: 사료내역 | K10: 사료 두당 섭취량 | N10: 특이사항 | R10: 출하예상 | U10: 출하예상
B11: 일자 | C11: 두수 | D11: 일자 | E11: 두수 | F11: 총체 | G11: 평체 | H11: 일자 | I11: 품목 | J11: 중량 | K11: 품목 | L11: 총중량 | M11: 두당 섭취량 | N11: 일자 | O11: 내용 | R11: 주차 | S11: 두수 | U11: 주차 | V11: 두수
B12: 45464 | C12: 4 | D12: 45540 | E12: 25 | F12: 2680 | G12: =F12/E12 -> 107.2 | H12: 45444 | I12: 윈맥스S트랜스 | J12: 6050 | K12: 윈맥스S트랜스 | L12: =SUMIF($I$12:$I$124,K12,$J$12:$J$124) -> 40930 | M12: =L12/$C$8 -> 45.477778 | N12: 45469 | O12: 호흡기 | R12: 11월2주 | S12: 50
B13: 45466 | C13: 1 | D13: 45540 | E13: 25 | F13: 2700 | G13: =F13/E13 -> 108 | H13: 45451 | I13: 윈맥스S트랜스 | J13: 5020 | K13: 리더MF1호 | L13: =SUMIF($I$12:$I$124,K13,$J$12:$J$124) -> 26990 | M13: =L13/$C$8 -> 29.988889 | N13: 45496 | O13: 구제역 | R13: 11월3주
B14: 45471 | C14: 1 | D14: 45541 | E14: 35 | F14: 2110 | G14: =F14/E14 -> 60.285714 | H14: 45457 | I14: 윈맥스S트랜스 | J14: 5040 | K14: 리더MF2호 | L14: =SUMIF($I$12:$I$124,K14,$J$12:$J$124) -> 111850 | M14: =L14/$C$8 -> 124.27778 | R14: 11월4주
B15: 45474 | C15: 3 | D15: 45556 | E15: 32 | F15: 3460 | G15: =F15/E15 -> 108.125 | H15: 45461 | I15: 윈맥스S트랜스 | J15: 2960 | K15: 프레쉬맥스제로육성돈 | L15: =SUMIF($I$12:$I$124,K15,$J$12:$J$124) -> 24100 | M15: =L15/$C$8 -> 26.777778 | R15: 11월5주
B16: 45475 | C16: 1 | D16: 45566 | E16: 60 | F16: 6440 | G16: =F16/E16 -> 107.33333 | H16: 45469 | I16: 윈맥스S트랜스 | J16: 9960 | K16: 총량 | L16: =SUM(L12:L15) -> 203870 | M16: =L16/F8 -> 231.40749
B17: 45476 | C17: 1 | D17: 45566 | E17: 66 | F17: 7200 | G17: =F17/E17 -> 109.09091 | H17: 45475 | I17: 윈맥스S트랜스 | J17: 8850
B18: 45480 | C18: 3 | D18: 45572 | E18: 77 | F18: 8310 | G18: =F18/E18 -> 107.92208 | H18: 45484 | I18: 프레쉬맥스제로육성돈 | J18: 7050
B19: 45481 | C19: 3 | D19: 45572 | E19: 75 | F19: 7960 | G19: =F19/E19 -> 106.13333 | H19: 45489 | I19: 프레쉬맥스제로육성돈 | J19: 7970 | K19: 예상FCR | L19: =(J59/(M8+N8))/(G59-H8) -> 3.0678543
B20: 45487 | C20: 2 | D20: 45579 | E20: 43 | F20: 4800 | G20: =F20/E20 -> 111.62791 | H20: 45495 | I20: 리더MF2호 | J20: 8040 | K20: 평균일당사료섭취량 | L20: =J31/(H31-H30)/N8 -> #DIV/0!
B21: 45489 | C21: 2 | D21: 45581 | E21: 63 | F21: 6950 | G21: =F21/E21 -> 110.31746 | H21: 45502 | I21: 리더MF2호 | J21: 14120
B22: 45490 | C22: 2 | D22: 45587 | E22: 43 | F22: =5700/50*E22 -> 4902 | G22: =F22/E22 -> 114 | H22: 45507 | I22: 프레쉬맥스제로육성돈 | J22: 9080
B23: 45494 | C23: 3 | D23: 45587 | E23: 51 | F23: 5640 | G23: =F23/E23 -> 110.58824 | H23: 45512 | I23: 리더MF2호 | J23: 10060 | L23: 2.95
B24: 45496 | C24: 3 | D24: 45590 | E24: 51 | F24: 5530 | G24: =F24/E24 -> 108.43137 | H24: 45517 | I24: 리더MF2호 | J24: 8080
B25: 45504 | C25: 2 | D25: 45590 | E25: 38 | F25: 4030 | G25: =F25/E25 -> 106.05263
B26: 45509 | C26: 1 | D26: 45593 | E26: 54 | F26: 6090 | G26: =F26/E26 -> 112.77778 | H26: 45525 | I26: 리더MF2호 | J26: 10070
B27: 45510 | C27: 6 | D27: 45596 | E27: 40 | F27: 4330 | G27: =F27/E27 -> 108.25 | H27: 45531 | I27: 리더MF1호 | J27: 5030
B28: 45512 | C28: 1 | D28: 45602 | E28: 18 | F28: =3620/33*E28 -> 1974.5455 | G28: =F28/E28 -> 109.69697 | H28: 45534 | I28: 리더MF1호 | J28: 9950
B29: 45515 | C29: 1 | G29: =F29/E29 -> #DIV/0! | H29: 45540 | I29: 리더MF2호 | J29: 9960
B30: 45516 | C30: 2 | G30: =F30/E30 -> #DIV/0! | H30: 45545 | I30: 리더MF2호 | J30: 10030
B31: 45517 | C31: 1 | G31: =F31/E31 -> #DIV/0! | H31: 45549 | I31: 리더MF2호 | J31: 6960
B32: 45536 | C32: 4 | G32: =F32/E32 -> #DIV/0! | H32: 45554 | I32: 리더MF2호 | J32: 7060
B33: 45540 | C33: 2 | G33: =F33/E33 -> #DIV/0! | H33: 45562 | I33: 윈맥스S트랜스 | J33: 3050
B34: 45541 | C34: 1 | G34: =F34/E34 -> #DIV/0! | H34: 45562 | I34: 리더MF2호 | J34: 4050
B35: 45548 | C35: 1 | G35: =F35/E35 -> #DIV/0! | H35: 45566 | I35: 리더MF2호 | J35: 4020
B36: 45553 | C36: 1 | G36: =F36/E36 -> #DIV/0! | H36: 45570 | I36: 리더MF1호 | J36: 2020
B37: 45554 | C37: 1 | G37: =F37/E37 -> #DIV/0! | H37: 45570 | I37: 리더MF2호 | J37: 4010
B38: 45556 | C38: 1 | H38: 45573 | I38: 리더MF1호 | J38: 5020
B39: 45558 | C39: 1 | H39: 45582 | I39: 리더MF2호 | J39: 4940
B40: 45566 | C40: 5 | H40: 45586 | I40: 리더MF2호 | J40: 5470
B41: 45567 | C41: 5 | H41: 45588 | I41: 리더MF2호 | J41: 4980
B42: 45568 | C42: 3 | H42: 45607 | I42: 리더MF1호 | J42: 4970
...

Sheet 진일농장3(0704)
A1: 농장명 : | E1: =TODAY() -> 46325 | F1: =E1-B4 -> 848
F2: 클레임적용 | O2: 클레임 | R2: 903
B3: 일자 | C3: 두수 | D3: 총체 | E3: 평체 | F3: 두수 | G3: 총체 | H3: 평체 | I3: 전입처 | J3: 출하예정일 | K3: 폐사두수 | L3: 총폐사율 | M3: 출하두수 | N3: 재고 | O3: 일자 | P3: 두수 | R3: =R2-Q4 -> 852
B4: 45477 | C4: 903 | D4: =5450+5490+5390+5160+5080 -> 26570 | E4: =D4/C4 -> 29.424142 | F4: =C8-P8 -> 844 | G4: =D8-(D8/C8*P8) -> 24833.976 | H4: =G4/F4 -> 29.424142 | I4: 익산 | J4: =B4+90 -> 45567 | K4: =C59 -> 102 | L4: =K8/F8 -> 0.12085308 | M4: =E59 -> 742 | N4: =F8-C59-E59 -> 0 | O4: 45477 | P4: 59 | Q4: 51
J5: =B5+90 -> 90
B8: 계 | C8: =SUM(C4:C7) -> 903 | D8: =SUM(D4:D7) -> 26570 | E8: =D8/C8 -> 29.424142 | F8: =SUM(F4) -> 844 | G8: =SUM(G4) -> 24833.976 | H8: =G8/F8 -> 29.424142 | K8: =K4 -> 102 | L8: =L4 -> 0.12085308 | M8: =M4 -> 742 | N8: =N4 -> 0 | O8: =P8/C8 -> 0.065337763 | P8: =SUM(P4:P7) -> 59 | Q8: =P8-Q4 -> 8
G9: 24859 | I9: =784 -> 784
B10: 폐사내역 | D10: 출하내역 | H10: 사료내역 | K10: 사료 두당 섭취량 | N10: 특이사항 | R10: 출하예상
B11: 일자 | C11: 두수 | D11: 일자 | E11: 두수 | F11: 총체 | G11: 평체 | H11: 일자 | I11: 품목 | J11: 중량 | K11: 품목 | L11: 총중량 | M11: 두당 섭취량 | N11: 일자 | O11: 내용 | R11: 주차 | S11: 두수
B12: 45499 | C12: 5 | D12: 45575 | E12: 30 | F12: 3310 | G12: =F12/E12 -> 110.33333 | H12: 45476 | I12: 윈맥스S트랜스 | J12: 8940 | K12: 윈맥스S트랜스 | L12: =SUMIF($I$12:$I$124,K12,$J$12:$J$124) -> 27980 | M12: =L12/$C$8 -> 30.985604 | N12: 45477 | O12: 툴라젝트 | R12: 11월2주 | S12: 34
B13: 45503 | C13: 1 | D13: 45581 | E13: 64 | F13: 6990 | G13: =F13/E13 -> 109.21875 | H13: 45485 | I13: 윈맥스S트랜스 | J13: 9960 | K13: 리더MF1호 | L13: =SUMIF($I$12:$I$124,K13,$J$12:$J$124) -> 60440 | M13: =L13/$C$8 -> 66.932447 | R13: 11월3주 | S13: 43
B14: 45508 | C14: 2 | D14: 45586 | E14: 52 | F14: 5620 | G14: =F14/E14 -> 108.07692 | H14: 45493 | I14: 윈맥스S트랜스 | J14: 5930 | K14: 리더MF2호 | L14: =SUMIF($I$12:$I$124,K14,$J$12:$J$124) -> 74329 | M14: =L14/$C$8 -> 82.3134 | R14: 11월4주 | S14: 110
B15: 45513 | C15: 1 | D15: 45586 | E15: 48 | F15: 5390 | G15: =F15/E15 -> 112.29167 | H15: 45497 | I15: 리더MF2호 | J15: 1510 | K15: 프레쉬맥스제로육성돈 | L15: =SUMIF($I$12:$I$124,K15,$J$12:$J$124) -> 27090 | M15: =L15/$C$8 -> 30 | R15: 11월5주 | S15: 60
B16: 45515 | C16: 5 | D16: 45587 | E16: 21 | F16: 1280 | G16: =F16/E16 -> 60.952381 | H16: 45500 | I16: 프레쉬맥스제로육성돈 | J16: 10110 | K16: 총량 | L16: =SUM(L12:L15) -> 189839 | M16: =L16/F8 -> 224.92773 | R16: 12월1주 | S16: 20
B17: 45517 | C17: 3 | D17: 45588 | E17: 57 | F17: 6090 | G17: =F17/E17 -> 106.84211 | H17: 45507 | I17: 리더MF2호 | R17: 12월2주
B18: 45522 | C18: 4 | D18: 45588 | E18: 62 | F18: 7070 | G18: =F18/E18 -> 114.03226 | H18: 45509 | I18: 프레쉬맥스제로육성돈 | J18: 10110 | R18: 12월3주
B19: 45530 | C19: 1 | D19: 45593 | E19: 45 | F19: 4970 | G19: =F19/E19 -> 110.44444 | H19: 45517 | I19: 프레쉬맥스제로육성돈 | J19: 6870 | K19: 예상FCR | L19: =(J59/I9)/(G59-H8) -> 3.0301024 | R19: 12월4주
B20: 45534 | C20: 2 | D20: 45593 | E20: 41 | F20: 4390 | G20: =F20/E20 -> 107.07317 | H20: 45521 | I20: 리더MF2호 | J20: 1209 | K20: 평균일당사료섭취량 | L20: =J24/(H24-H23)/N8 -> #DIV/0!
B21: 45536 | C21: 4 | D21: 45596 | E21: 35 | F21: 3830 | G21: =F21/E21 -> 109.42857 | H21: 45530 | I21: 리더MF2호 | J21: 10000
B22: 45541 | C22: 3 | D22: 45602 | E22: 15 | F22: =3620/33*15 -> 1645.4545 | G22: =F22/E22 -> 109.69697 | H22: 45535 | I22: 리더MF1호 | J22: 10070
B23: 45545 | C23: 1 | D23: 45603 | E23: 19 | F23: 2090 | G23: =F23/E23 -> 110 | H23: 45541 | I23: 리더MF1호 | J23: 12100
B24: 45549 | C24: 1 | D24: 45610 | E24: 43 | F24: 4840 | G24: =F24/E24 -> 112.55814 | H24: 45547 | I24: 리더MF2호 | J24: 15050
B25: 45554 | C25: 2 | D25: 45616 | E25: 49 | F25: 5590 | G25: =F25/E25 -> 114.08163 | H25: 45549 | I25: 리더MF2호 | J25: 7300
B26: 45556 | C26: 2 | D26: 45617 | E26: 30 | F26: 3290 | G26: =F26/E26 -> 109.66667 | H26: 45555 | I26: 리더MF2호 | J26: 4040 | K26: 178150 | L26: =(K26/I9)/(G59-H8) -> 2.8435292
B27: 45562 | C27: 2 | D27: 45617 | E27: 31 | F27: 3540 | G27: =F27/E27 -> 114.19355 | H27: 45560 | I27: 리더MF1호 | J27: 10030
B28: 45566 | C28: 3 | D28: 45622 | E28: 21 | F28: 2330 | G28: =F28/E28 -> 110.95238 | H28: 45566 | I28: 윈맥스S트랜스 | J28: 3150
B29: 45567 | C29: 5 | D29: 45622 | E29: 17 | F29: 1850 | G29: =F29/E29 -> 108.82353 | H29: 45566 | I29: 리더MF2호 | J29: 5940
B30: 45568 | C30: 2 | D30: 45625 | E30: 22 | F30: 2550 | G30: =F30/E30 -> 115.90909 | H30: 45570 | I30: 리더MF2호 | J30: 8150 | L30: 259
B31: 45569 | C31: 7 | D31: 45630 | E31: 40 | F31: =7920/71*E31 -> 4461.9718 | G31: =F31/E31 -> 111.5493 | H31: 45577 | I31: 리더MF2호 | J31: 9940
B32: 45571 | C32: 8 | G32: =F32/E32 -> #DIV/0! | H32: 45577 | I32: 리더MF1호 | J32: 4950 | L32: 4970
B33: 45573 | C33: 2 | G33: =F33/E33 -> #DIV/0! | H33: 45586 | I33: 리더MF2호 | J33: 5470 | L33: =L32/L30/7 -> 2.7413127
B34: 45575 | C34: 2 | G34: =F34/E34 -> #DIV/0! | H34: 45586 | I34: 리더MF1호 | J34: 2970
